[2016-11-16 15:24:55] DEBUG [django.db.backends:90] (0.000) 
            SELECT name, type FROM sqlite_master
            WHERE type in ('table', 'view') AND NOT name='sqlite_sequence'
            ORDER BY name; args=None
[2016-11-16 15:24:55] DEBUG [django.db.backends:90] (0.000) SELECT "django_migrations"."app", "django_migrations"."name" FROM "django_migrations"; args=()
[2016-11-16 15:25:24] DEBUG [django.db.backends:90] (0.042) SELECT "django_session"."session_key", "django_session"."session_data", "django_session"."expire_date" FROM "django_session" WHERE ("django_session"."expire_date" > '2016-11-16 20:25:24.319770' AND "django_session"."session_key" = '4w7mksqqsrmucukumcpvs4jbtn8vd4qw'); args=('2016-11-16 20:25:24.319770', '4w7mksqqsrmucukumcpvs4jbtn8vd4qw')
[2016-11-16 15:25:24] DEBUG [django.db.backends:90] (0.004) SELECT "auths_user"."password", "auths_user"."last_login", "auths_user"."is_superuser", "auths_user"."username", "auths_user"."first_name", "auths_user"."last_name", "auths_user"."email", "auths_user"."is_staff", "auths_user"."is_active", "auths_user"."date_joined", "auths_user"."id", "auths_user"."last_hierarchy_id", "auths_user"."last_module_id", "auths_user"."person_id", "auths_user"."updated_at", "auths_user"."registered_by" FROM "auths_user" WHERE "auths_user"."id" = '3651942c1384420da02bbf9e5eca3faa'; args=('3651942c1384420da02bbf9e5eca3faa',)
[2016-11-16 15:25:25] DEBUG [django.template:929] Exception while resolving variable 'is_popup' in template 'admin/index.html'.
Traceback (most recent call last):
  File "C:\Users\pc\AppData\Local\Programs\Python\Python35-32\lib\site-packages\django\template\base.py", line 885, in _resolve_lookup
    current = current[bit]
  File "C:\Users\pc\AppData\Local\Programs\Python\Python35-32\lib\site-packages\django\template\context.py", line 75, in __getitem__
    raise KeyError(key)
KeyError: 'is_popup'

During handling of the above exception, another exception occurred:

Traceback (most recent call last):
  File "C:\Users\pc\AppData\Local\Programs\Python\Python35-32\lib\site-packages\django\template\base.py", line 891, in _resolve_lookup
    if isinstance(current, BaseContext) and getattr(type(current), bit):
AttributeError: type object 'RequestContext' has no attribute 'is_popup'

During handling of the above exception, another exception occurred:

Traceback (most recent call last):
  File "C:\Users\pc\AppData\Local\Programs\Python\Python35-32\lib\site-packages\django\template\base.py", line 900, in _resolve_lookup
    current = current[int(bit)]
ValueError: invalid literal for int() with base 10: 'is_popup'

During handling of the above exception, another exception occurred:

Traceback (most recent call last):
  File "C:\Users\pc\AppData\Local\Programs\Python\Python35-32\lib\site-packages\django\template\base.py", line 907, in _resolve_lookup
    (bit, current))  # missing attribute
django.template.base.VariableDoesNotExist: Failed lookup for key [is_popup] in "[{'None': None, 'False': False, 'True': True}, {'request': <WSGIRequest: GET '/admin/'>, 'perms': <django.contrib.auth.context_processors.PermWrapper object at 0x04ABD5F0>, 'DEFAULT_MESSAGE_LEVELS': {'DEBUG': 10, 'ERROR': 40, 'WARNING': 30, 'INFO': 20, 'SUCCESS': 25}, 'user': <SimpleLazyObject: <User: admin>>, 'messages': <django.contrib.messages.storage.fallback.FallbackStorage object at 0x045A5B50>, 'csrf_token': <SimpleLazyObject: <function csrf.<locals>._get_val at 0x045AB930>>}, {}, {'site_header': <django.utils.functional.lazy.<locals>.__proxy__ object at 0x038529D0>, 'app_list': [{'name': <django.utils.functional.lazy.<locals>.__proxy__ object at 0x0386D610>, 'has_module_perms': True, 'app_url': '/admin/auth/', 'app_label': 'auth', 'models': [{'name': <django.utils.functional.lazy.<locals>.__proxy__ object at 0x04A22B30>, 'admin_url': '/admin/auth/group/', 'object_name': 'Group', 'perms': {'change': True, 'delete': True, 'add': True}, 'add_url': '/admin/auth/group/add/'}, {'name': <django.utils.functional.lazy.<locals>.__proxy__ object at 0x04A3F250>, 'admin_url': '/admin/auth/permission/', 'object_name': 'Permission', 'perms': {'change': True, 'delete': True, 'add': True}, 'add_url': '/admin/auth/permission/add/'}]}, {'name': 'Auths', 'has_module_perms': True, 'app_url': '/admin/auths/', 'app_label': 'auths', 'models': [{'name': <django.utils.functional.lazy.<locals>.__proxy__ object at 0x045506B0>, 'admin_url': '/admin/auths/hierarchytype/', 'object_name': 'HierarchyType', 'perms': {'change': True, 'delete': True, 'add': True}, 'add_url': '/admin/auths/hierarchytype/add/'}, {'name': <django.utils.functional.lazy.<locals>.__proxy__ object at 0x04A227D0>, 'admin_url': '/admin/auths/hierarchy/', 'object_name': 'Hierarchy', 'perms': {'change': True, 'delete': True, 'add': True}, 'add_url': '/admin/auths/hierarchy/add/'}, {'name': <django.utils.functional.lazy.<locals>.__proxy__ object at 0x04533570>, 'admin_url': '/admin/auths/menu/', 'object_name': 'Menu', 'perms': {'change': True, 'delete': True, 'add': True}, 'add_url': '/admin/auths/menu/add/'}, {'name': <django.utils.functional.lazy.<locals>.__proxy__ object at 0x04A3F5D0>, 'admin_url': '/admin/auths/person/', 'object_name': 'Person', 'perms': {'change': True, 'delete': True, 'add': True}, 'add_url': '/admin/auths/person/add/'}, {'name': <django.utils.functional.lazy.<locals>.__proxy__ object at 0x04A3F370>, 'admin_url': '/admin/auths/userhierarchygroup/', 'object_name': 'UserHierarchyGroup', 'perms': {'change': True, 'delete': True, 'add': True}, 'add_url': '/admin/auths/userhierarchygroup/add/'}, {'name': <django.utils.functional.lazy.<locals>.__proxy__ object at 0x04550750>, 'admin_url': '/admin/auths/userhierarchypermission/', 'object_name': 'UserHierarchyPermission', 'perms': {'change': True, 'delete': True, 'add': True}, 'add_url': '/admin/auths/userhierarchypermission/add/'}, {'name': <django.utils.functional.lazy.<locals>.__proxy__ object at 0x04533590>, 'admin_url': '/admin/auths/user/', 'object_name': 'User', 'perms': {'change': True, 'delete': True, 'add': True}, 'add_url': '/admin/auths/user/add/'}]}, {'name': 'Catalogo', 'has_module_perms': True, 'app_url': '/admin/catalogo/', 'app_label': 'catalogo', 'models': [{'name': 'Autores', 'admin_url': '/admin/catalogo/autor/', 'object_name': 'Autor', 'perms': {'change': True, 'delete': True, 'add': True}, 'add_url': '/admin/catalogo/autor/add/'}, {'name': 'Categorias', 'admin_url': '/admin/catalogo/categoria/', 'object_name': 'Categoria', 'perms': {'change': True, 'delete': True, 'add': True}, 'add_url': '/admin/catalogo/categoria/add/'}, {'name': 'Libros', 'admin_url': '/admin/catalogo/libro/', 'object_name': 'Libro', 'perms': {'change': True, 'delete': True, 'add': True}, 'add_url': '/admin/catalogo/libro/add/'}]}, {'name': <django.utils.functional.lazy.<locals>.__proxy__ object at 0x0386D3F0>, 'has_module_perms': True, 'app_url': '/admin/contenttypes/', 'app_label': 'contenttypes', 'models': [{'name': <django.utils.functional.lazy.<locals>.__proxy__ object at 0x04A3F110>, 'admin_url': '/admin/contenttypes/contenttype/', 'object_name': 'ContentType', 'perms': {'change': True, 'delete': True, 'add': True}, 'add_url': '/admin/contenttypes/contenttype/add/'}]}, {'name': 'Django OAuth Toolkit', 'has_module_perms': True, 'app_url': '/admin/oauth2_provider/', 'app_label': 'oauth2_provider', 'models': [{'name': <django.utils.functional.lazy.<locals>.__proxy__ object at 0x045502B0>, 'admin_url': '/admin/oauth2_provider/accesstoken/', 'object_name': 'AccessToken', 'perms': {'change': True, 'delete': True, 'add': True}, 'add_url': '/admin/oauth2_provider/accesstoken/add/'}, {'name': <django.utils.functional.lazy.<locals>.__proxy__ object at 0x04550970>, 'admin_url': '/admin/oauth2_provider/application/', 'object_name': 'Application', 'perms': {'change': True, 'delete': True, 'add': True}, 'add_url': '/admin/oauth2_provider/application/add/'}, {'name': <django.utils.functional.lazy.<locals>.__proxy__ object at 0x04550790>, 'admin_url': '/admin/oauth2_provider/grant/', 'object_name': 'Grant', 'perms': {'change': True, 'delete': True, 'add': True}, 'add_url': '/admin/oauth2_provider/grant/add/'}, {'name': <django.utils.functional.lazy.<locals>.__proxy__ object at 0x04533AB0>, 'admin_url': '/admin/oauth2_provider/refreshtoken/', 'object_name': 'RefreshToken', 'perms': {'change': True, 'delete': True, 'add': True}, 'add_url': '/admin/oauth2_provider/refreshtoken/add/'}]}], 'LANGUAGE_CODE': 'en-us', 'LANGUAGE_BIDI': False, 'title': <django.utils.functional.lazy.<locals>.__proxy__ object at 0x03852A30>, 'site_title': <django.utils.functional.lazy.<locals>.__proxy__ object at 0x03842AF0>, 'has_permission': True, 'available_apps': [{'name': <django.utils.functional.lazy.<locals>.__proxy__ object at 0x0386D610>, 'has_module_perms': True, 'app_url': '/admin/auth/', 'app_label': 'auth', 'models': [{'name': <django.utils.functional.lazy.<locals>.__proxy__ object at 0x04A3F3D0>, 'admin_url': '/admin/auth/group/', 'object_name': 'Group', 'perms': {'change': True, 'delete': True, 'add': True}, 'add_url': '/admin/auth/group/add/'}, {'name': <django.utils.functional.lazy.<locals>.__proxy__ object at 0x04A49C30>, 'admin_url': '/admin/auth/permission/', 'object_name': 'Permission', 'perms': {'change': True, 'delete': True, 'add': True}, 'add_url': '/admin/auth/permission/add/'}]}, {'name': 'Auths', 'has_module_perms': True, 'app_url': '/admin/auths/', 'app_label': 'auths', 'models': [{'name': <django.utils.functional.lazy.<locals>.__proxy__ object at 0x04A499F0>, 'admin_url': '/admin/auths/hierarchytype/', 'object_name': 'HierarchyType', 'perms': {'change': True, 'delete': True, 'add': True}, 'add_url': '/admin/auths/hierarchytype/add/'}, {'name': <django.utils.functional.lazy.<locals>.__proxy__ object at 0x04A499D0>, 'admin_url': '/admin/auths/hierarchy/', 'object_name': 'Hierarchy', 'perms': {'change': True, 'delete': True, 'add': True}, 'add_url': '/admin/auths/hierarchy/add/'}, {'name': <django.utils.functional.lazy.<locals>.__proxy__ object at 0x04A49C70>, 'admin_url': '/admin/auths/menu/', 'object_name': 'Menu', 'perms': {'change': True, 'delete': True, 'add': True}, 'add_url': '/admin/auths/menu/add/'}, {'name': <django.utils.functional.lazy.<locals>.__proxy__ object at 0x04A49F50>, 'admin_url': '/admin/auths/person/', 'object_name': 'Person', 'perms': {'change': True, 'delete': True, 'add': True}, 'add_url': '/admin/auths/person/add/'}, {'name': <django.utils.functional.lazy.<locals>.__proxy__ object at 0x04A49A10>, 'admin_url': '/admin/auths/userhierarchygroup/', 'object_name': 'UserHierarchyGroup', 'perms': {'change': True, 'delete': True, 'add': True}, 'add_url': '/admin/auths/userhierarchygroup/add/'}, {'name': <django.utils.functional.lazy.<locals>.__proxy__ object at 0x04A49E50>, 'admin_url': '/admin/auths/userhierarchypermission/', 'object_name': 'UserHierarchyPermission', 'perms': {'change': True, 'delete': True, 'add': True}, 'add_url': '/admin/auths/userhierarchypermission/add/'}, {'name': <django.utils.functional.lazy.<locals>.__proxy__ object at 0x04A49E10>, 'admin_url': '/admin/auths/user/', 'object_name': 'User', 'perms': {'change': True, 'delete': True, 'add': True}, 'add_url': '/admin/auths/user/add/'}]}, {'name': 'Catalogo', 'has_module_perms': True, 'app_url': '/admin/catalogo/', 'app_label': 'catalogo', 'models': [{'name': 'Autores', 'admin_url': '/admin/catalogo/autor/', 'object_name': 'Autor', 'perms': {'change': True, 'delete': True, 'add': True}, 'add_url': '/admin/catalogo/autor/add/'}, {'name': 'Categorias', 'admin_url': '/admin/catalogo/categoria/', 'object_name': 'Categoria', 'perms': {'change': True, 'delete': True, 'add': True}, 'add_url': '/admin/catalogo/categoria/add/'}, {'name': 'Libros', 'admin_url': '/admin/catalogo/libro/', 'object_name': 'Libro', 'perms': {'change': True, 'delete': True, 'add': True}, 'add_url': '/admin/catalogo/libro/add/'}]}, {'name': <django.utils.functional.lazy.<locals>.__proxy__ object at 0x0386D3F0>, 'has_module_perms': True, 'app_url': '/admin/contenttypes/', 'app_label': 'contenttypes', 'models': [{'name': <django.utils.functional.lazy.<locals>.__proxy__ object at 0x04A49DF0>, 'admin_url': '/admin/contenttypes/contenttype/', 'object_name': 'ContentType', 'perms': {'change': True, 'delete': True, 'add': True}, 'add_url': '/admin/contenttypes/contenttype/add/'}]}, {'name': 'Django OAuth Toolkit', 'has_module_perms': True, 'app_url': '/admin/oauth2_provider/', 'app_label': 'oauth2_provider', 'models': [{'name': <django.utils.functional.lazy.<locals>.__proxy__ object at 0x04A49F90>, 'admin_url': '/admin/oauth2_provider/accesstoken/', 'object_name': 'AccessToken', 'perms': {'change': True, 'delete': True, 'add': True}, 'add_url': '/admin/oauth2_provider/accesstoken/add/'}, {'name': <django.utils.functional.lazy.<locals>.__proxy__ object at 0x04A49FB0>, 'admin_url': '/admin/oauth2_provider/application/', 'object_name': 'Application', 'perms': {'change': True, 'delete': True, 'add': True}, 'add_url': '/admin/oauth2_provider/application/add/'}, {'name': <django.utils.functional.lazy.<locals>.__proxy__ object at 0x04A49A90>, 'admin_url': '/admin/oauth2_provider/grant/', 'object_name': 'Grant', 'perms': {'change': True, 'delete': True, 'add': True}, 'add_url': '/admin/oauth2_provider/grant/add/'}, {'name': <django.utils.functional.lazy.<locals>.__proxy__ object at 0x04A49A50>, 'admin_url': '/admin/oauth2_provider/refreshtoken/', 'object_name': 'RefreshToken', 'perms': {'change': True, 'delete': True, 'add': True}, 'add_url': '/admin/oauth2_provider/refreshtoken/add/'}]}], 'site_url': '/'}]"
[2016-11-16 15:25:25] DEBUG [django.template:929] Exception while resolving variable 'is_popup' in template 'admin/index.html'.
Traceback (most recent call last):
  File "C:\Users\pc\AppData\Local\Programs\Python\Python35-32\lib\site-packages\django\template\base.py", line 885, in _resolve_lookup
    current = current[bit]
  File "C:\Users\pc\AppData\Local\Programs\Python\Python35-32\lib\site-packages\django\template\context.py", line 75, in __getitem__
    raise KeyError(key)
KeyError: 'is_popup'

During handling of the above exception, another exception occurred:

Traceback (most recent call last):
  File "C:\Users\pc\AppData\Local\Programs\Python\Python35-32\lib\site-packages\django\template\base.py", line 891, in _resolve_lookup
    if isinstance(current, BaseContext) and getattr(type(current), bit):
AttributeError: type object 'RequestContext' has no attribute 'is_popup'

During handling of the above exception, another exception occurred:

Traceback (most recent call last):
  File "C:\Users\pc\AppData\Local\Programs\Python\Python35-32\lib\site-packages\django\template\base.py", line 900, in _resolve_lookup
    current = current[int(bit)]
ValueError: invalid literal for int() with base 10: 'is_popup'

During handling of the above exception, another exception occurred:

Traceback (most recent call last):
  File "C:\Users\pc\AppData\Local\Programs\Python\Python35-32\lib\site-packages\django\template\base.py", line 907, in _resolve_lookup
    (bit, current))  # missing attribute
django.template.base.VariableDoesNotExist: Failed lookup for key [is_popup] in "[{'None': None, 'False': False, 'True': True}, {'request': <WSGIRequest: GET '/admin/'>, 'perms': <django.contrib.auth.context_processors.PermWrapper object at 0x04ABD5F0>, 'DEFAULT_MESSAGE_LEVELS': {'DEBUG': 10, 'ERROR': 40, 'WARNING': 30, 'INFO': 20, 'SUCCESS': 25}, 'user': <SimpleLazyObject: <User: admin>>, 'messages': <django.contrib.messages.storage.fallback.FallbackStorage object at 0x045A5B50>, 'csrf_token': <SimpleLazyObject: <function csrf.<locals>._get_val at 0x045AB930>>}, {}, {'site_header': <django.utils.functional.lazy.<locals>.__proxy__ object at 0x038529D0>, 'app_list': [{'name': <django.utils.functional.lazy.<locals>.__proxy__ object at 0x0386D610>, 'has_module_perms': True, 'app_url': '/admin/auth/', 'app_label': 'auth', 'models': [{'name': <django.utils.functional.lazy.<locals>.__proxy__ object at 0x04A22B30>, 'admin_url': '/admin/auth/group/', 'object_name': 'Group', 'perms': {'change': True, 'delete': True, 'add': True}, 'add_url': '/admin/auth/group/add/'}, {'name': <django.utils.functional.lazy.<locals>.__proxy__ object at 0x04A3F250>, 'admin_url': '/admin/auth/permission/', 'object_name': 'Permission', 'perms': {'change': True, 'delete': True, 'add': True}, 'add_url': '/admin/auth/permission/add/'}]}, {'name': 'Auths', 'has_module_perms': True, 'app_url': '/admin/auths/', 'app_label': 'auths', 'models': [{'name': <django.utils.functional.lazy.<locals>.__proxy__ object at 0x045506B0>, 'admin_url': '/admin/auths/hierarchytype/', 'object_name': 'HierarchyType', 'perms': {'change': True, 'delete': True, 'add': True}, 'add_url': '/admin/auths/hierarchytype/add/'}, {'name': <django.utils.functional.lazy.<locals>.__proxy__ object at 0x04A227D0>, 'admin_url': '/admin/auths/hierarchy/', 'object_name': 'Hierarchy', 'perms': {'change': True, 'delete': True, 'add': True}, 'add_url': '/admin/auths/hierarchy/add/'}, {'name': <django.utils.functional.lazy.<locals>.__proxy__ object at 0x04533570>, 'admin_url': '/admin/auths/menu/', 'object_name': 'Menu', 'perms': {'change': True, 'delete': True, 'add': True}, 'add_url': '/admin/auths/menu/add/'}, {'name': <django.utils.functional.lazy.<locals>.__proxy__ object at 0x04A3F5D0>, 'admin_url': '/admin/auths/person/', 'object_name': 'Person', 'perms': {'change': True, 'delete': True, 'add': True}, 'add_url': '/admin/auths/person/add/'}, {'name': <django.utils.functional.lazy.<locals>.__proxy__ object at 0x04A3F370>, 'admin_url': '/admin/auths/userhierarchygroup/', 'object_name': 'UserHierarchyGroup', 'perms': {'change': True, 'delete': True, 'add': True}, 'add_url': '/admin/auths/userhierarchygroup/add/'}, {'name': <django.utils.functional.lazy.<locals>.__proxy__ object at 0x04550750>, 'admin_url': '/admin/auths/userhierarchypermission/', 'object_name': 'UserHierarchyPermission', 'perms': {'change': True, 'delete': True, 'add': True}, 'add_url': '/admin/auths/userhierarchypermission/add/'}, {'name': <django.utils.functional.lazy.<locals>.__proxy__ object at 0x04533590>, 'admin_url': '/admin/auths/user/', 'object_name': 'User', 'perms': {'change': True, 'delete': True, 'add': True}, 'add_url': '/admin/auths/user/add/'}]}, {'name': 'Catalogo', 'has_module_perms': True, 'app_url': '/admin/catalogo/', 'app_label': 'catalogo', 'models': [{'name': 'Autores', 'admin_url': '/admin/catalogo/autor/', 'object_name': 'Autor', 'perms': {'change': True, 'delete': True, 'add': True}, 'add_url': '/admin/catalogo/autor/add/'}, {'name': 'Categorias', 'admin_url': '/admin/catalogo/categoria/', 'object_name': 'Categoria', 'perms': {'change': True, 'delete': True, 'add': True}, 'add_url': '/admin/catalogo/categoria/add/'}, {'name': 'Libros', 'admin_url': '/admin/catalogo/libro/', 'object_name': 'Libro', 'perms': {'change': True, 'delete': True, 'add': True}, 'add_url': '/admin/catalogo/libro/add/'}]}, {'name': <django.utils.functional.lazy.<locals>.__proxy__ object at 0x0386D3F0>, 'has_module_perms': True, 'app_url': '/admin/contenttypes/', 'app_label': 'contenttypes', 'models': [{'name': <django.utils.functional.lazy.<locals>.__proxy__ object at 0x04A3F110>, 'admin_url': '/admin/contenttypes/contenttype/', 'object_name': 'ContentType', 'perms': {'change': True, 'delete': True, 'add': True}, 'add_url': '/admin/contenttypes/contenttype/add/'}]}, {'name': 'Django OAuth Toolkit', 'has_module_perms': True, 'app_url': '/admin/oauth2_provider/', 'app_label': 'oauth2_provider', 'models': [{'name': <django.utils.functional.lazy.<locals>.__proxy__ object at 0x045502B0>, 'admin_url': '/admin/oauth2_provider/accesstoken/', 'object_name': 'AccessToken', 'perms': {'change': True, 'delete': True, 'add': True}, 'add_url': '/admin/oauth2_provider/accesstoken/add/'}, {'name': <django.utils.functional.lazy.<locals>.__proxy__ object at 0x04550970>, 'admin_url': '/admin/oauth2_provider/application/', 'object_name': 'Application', 'perms': {'change': True, 'delete': True, 'add': True}, 'add_url': '/admin/oauth2_provider/application/add/'}, {'name': <django.utils.functional.lazy.<locals>.__proxy__ object at 0x04550790>, 'admin_url': '/admin/oauth2_provider/grant/', 'object_name': 'Grant', 'perms': {'change': True, 'delete': True, 'add': True}, 'add_url': '/admin/oauth2_provider/grant/add/'}, {'name': <django.utils.functional.lazy.<locals>.__proxy__ object at 0x04533AB0>, 'admin_url': '/admin/oauth2_provider/refreshtoken/', 'object_name': 'RefreshToken', 'perms': {'change': True, 'delete': True, 'add': True}, 'add_url': '/admin/oauth2_provider/refreshtoken/add/'}]}], 'LANGUAGE_CODE': 'en-us', 'LANGUAGE_BIDI': False, 'title': <django.utils.functional.lazy.<locals>.__proxy__ object at 0x03852A30>, 'site_title': <django.utils.functional.lazy.<locals>.__proxy__ object at 0x03842AF0>, 'has_permission': True, 'available_apps': [{'name': <django.utils.functional.lazy.<locals>.__proxy__ object at 0x0386D610>, 'has_module_perms': True, 'app_url': '/admin/auth/', 'app_label': 'auth', 'models': [{'name': <django.utils.functional.lazy.<locals>.__proxy__ object at 0x04A3F3D0>, 'admin_url': '/admin/auth/group/', 'object_name': 'Group', 'perms': {'change': True, 'delete': True, 'add': True}, 'add_url': '/admin/auth/group/add/'}, {'name': <django.utils.functional.lazy.<locals>.__proxy__ object at 0x04A49C30>, 'admin_url': '/admin/auth/permission/', 'object_name': 'Permission', 'perms': {'change': True, 'delete': True, 'add': True}, 'add_url': '/admin/auth/permission/add/'}]}, {'name': 'Auths', 'has_module_perms': True, 'app_url': '/admin/auths/', 'app_label': 'auths', 'models': [{'name': <django.utils.functional.lazy.<locals>.__proxy__ object at 0x04A499F0>, 'admin_url': '/admin/auths/hierarchytype/', 'object_name': 'HierarchyType', 'perms': {'change': True, 'delete': True, 'add': True}, 'add_url': '/admin/auths/hierarchytype/add/'}, {'name': <django.utils.functional.lazy.<locals>.__proxy__ object at 0x04A499D0>, 'admin_url': '/admin/auths/hierarchy/', 'object_name': 'Hierarchy', 'perms': {'change': True, 'delete': True, 'add': True}, 'add_url': '/admin/auths/hierarchy/add/'}, {'name': <django.utils.functional.lazy.<locals>.__proxy__ object at 0x04A49C70>, 'admin_url': '/admin/auths/menu/', 'object_name': 'Menu', 'perms': {'change': True, 'delete': True, 'add': True}, 'add_url': '/admin/auths/menu/add/'}, {'name': <django.utils.functional.lazy.<locals>.__proxy__ object at 0x04A49F50>, 'admin_url': '/admin/auths/person/', 'object_name': 'Person', 'perms': {'change': True, 'delete': True, 'add': True}, 'add_url': '/admin/auths/person/add/'}, {'name': <django.utils.functional.lazy.<locals>.__proxy__ object at 0x04A49A10>, 'admin_url': '/admin/auths/userhierarchygroup/', 'object_name': 'UserHierarchyGroup', 'perms': {'change': True, 'delete': True, 'add': True}, 'add_url': '/admin/auths/userhierarchygroup/add/'}, {'name': <django.utils.functional.lazy.<locals>.__proxy__ object at 0x04A49E50>, 'admin_url': '/admin/auths/userhierarchypermission/', 'object_name': 'UserHierarchyPermission', 'perms': {'change': True, 'delete': True, 'add': True}, 'add_url': '/admin/auths/userhierarchypermission/add/'}, {'name': <django.utils.functional.lazy.<locals>.__proxy__ object at 0x04A49E10>, 'admin_url': '/admin/auths/user/', 'object_name': 'User', 'perms': {'change': True, 'delete': True, 'add': True}, 'add_url': '/admin/auths/user/add/'}]}, {'name': 'Catalogo', 'has_module_perms': True, 'app_url': '/admin/catalogo/', 'app_label': 'catalogo', 'models': [{'name': 'Autores', 'admin_url': '/admin/catalogo/autor/', 'object_name': 'Autor', 'perms': {'change': True, 'delete': True, 'add': True}, 'add_url': '/admin/catalogo/autor/add/'}, {'name': 'Categorias', 'admin_url': '/admin/catalogo/categoria/', 'object_name': 'Categoria', 'perms': {'change': True, 'delete': True, 'add': True}, 'add_url': '/admin/catalogo/categoria/add/'}, {'name': 'Libros', 'admin_url': '/admin/catalogo/libro/', 'object_name': 'Libro', 'perms': {'change': True, 'delete': True, 'add': True}, 'add_url': '/admin/catalogo/libro/add/'}]}, {'name': <django.utils.functional.lazy.<locals>.__proxy__ object at 0x0386D3F0>, 'has_module_perms': True, 'app_url': '/admin/contenttypes/', 'app_label': 'contenttypes', 'models': [{'name': <django.utils.functional.lazy.<locals>.__proxy__ object at 0x04A49DF0>, 'admin_url': '/admin/contenttypes/contenttype/', 'object_name': 'ContentType', 'perms': {'change': True, 'delete': True, 'add': True}, 'add_url': '/admin/contenttypes/contenttype/add/'}]}, {'name': 'Django OAuth Toolkit', 'has_module_perms': True, 'app_url': '/admin/oauth2_provider/', 'app_label': 'oauth2_provider', 'models': [{'name': <django.utils.functional.lazy.<locals>.__proxy__ object at 0x04A49F90>, 'admin_url': '/admin/oauth2_provider/accesstoken/', 'object_name': 'AccessToken', 'perms': {'change': True, 'delete': True, 'add': True}, 'add_url': '/admin/oauth2_provider/accesstoken/add/'}, {'name': <django.utils.functional.lazy.<locals>.__proxy__ object at 0x04A49FB0>, 'admin_url': '/admin/oauth2_provider/application/', 'object_name': 'Application', 'perms': {'change': True, 'delete': True, 'add': True}, 'add_url': '/admin/oauth2_provider/application/add/'}, {'name': <django.utils.functional.lazy.<locals>.__proxy__ object at 0x04A49A90>, 'admin_url': '/admin/oauth2_provider/grant/', 'object_name': 'Grant', 'perms': {'change': True, 'delete': True, 'add': True}, 'add_url': '/admin/oauth2_provider/grant/add/'}, {'name': <django.utils.functional.lazy.<locals>.__proxy__ object at 0x04A49A50>, 'admin_url': '/admin/oauth2_provider/refreshtoken/', 'object_name': 'RefreshToken', 'perms': {'change': True, 'delete': True, 'add': True}, 'add_url': '/admin/oauth2_provider/refreshtoken/add/'}]}], 'site_url': '/'}]"
[2016-11-16 15:25:25] DEBUG [django.db.backends:90] (0.010) SELECT "django_admin_log"."id", "django_admin_log"."action_time", "django_admin_log"."user_id", "django_admin_log"."content_type_id", "django_admin_log"."object_id", "django_admin_log"."object_repr", "django_admin_log"."action_flag", "django_admin_log"."change_message", "auths_user"."password", "auths_user"."last_login", "auths_user"."is_superuser", "auths_user"."username", "auths_user"."first_name", "auths_user"."last_name", "auths_user"."email", "auths_user"."is_staff", "auths_user"."is_active", "auths_user"."date_joined", "auths_user"."id", "auths_user"."last_hierarchy_id", "auths_user"."last_module_id", "auths_user"."person_id", "auths_user"."updated_at", "auths_user"."registered_by", "django_content_type"."id", "django_content_type"."app_label", "django_content_type"."model" FROM "django_admin_log" INNER JOIN "auths_user" ON ("django_admin_log"."user_id" = "auths_user"."id") LEFT OUTER JOIN "django_content_type" ON ("django_admin_log"."content_type_id" = "django_content_type"."id") WHERE "django_admin_log"."user_id" = '3651942c1384420da02bbf9e5eca3faa' ORDER BY "django_admin_log"."action_time" DESC LIMIT 10; args=('3651942c1384420da02bbf9e5eca3faa',)
[2016-11-16 15:25:25] INFO [django.server:131] "GET /admin/ HTTP/1.1" 200 10333
[2016-11-16 15:25:26] DEBUG [django.template:929] Exception while resolving variable 'name' in template 'unknown'.
Traceback (most recent call last):
  File "C:\Users\pc\AppData\Local\Programs\Python\Python35-32\lib\site-packages\django\core\handlers\exception.py", line 39, in inner
    response = get_response(request)
  File "C:\Users\pc\AppData\Local\Programs\Python\Python35-32\lib\site-packages\django\core\handlers\base.py", line 172, in _get_response
    resolver_match = resolver.resolve(request.path_info)
  File "C:\Users\pc\AppData\Local\Programs\Python\Python35-32\lib\site-packages\django\urls\resolvers.py", line 300, in resolve
    raise Resolver404({'tried': tried, 'path': new_path})
django.urls.exceptions.Resolver404: {'path': 'favicon.ico', 'tried': [[<RegexURLResolver <RegexURLPattern list> (admin:admin) ^admin/>], [<RegexURLResolver <module 'django.contrib.admindocs.urls' from 'C:\\Users\\pc\\AppData\\Local\\Programs\\Python\\Python35-32\\lib\\site-packages\\django\\contrib\\admindocs\\urls.py'> (None:None) ^admin/doc/>], [<RegexURLResolver <module 'rest_framework.urls' from 'C:\\Users\\pc\\AppData\\Local\\Programs\\Python\\Python35-32\\lib\\site-packages\\rest_framework\\urls.py'> (rest_framework:rest_framework) ^api-auth/>], [<RegexURLResolver <module 'oauth2_provider.urls' from 'C:\\Users\\pc\\AppData\\Local\\Programs\\Python\\Python35-32\\lib\\site-packages\\oauth2_provider\\urls.py'> (None:oauth2_provider) ^o/>], [<RegexURLResolver <module 'vemo_service_apps.auths_api.urls' from 'D:\\Nueva carpeta (2)\\vemo\\vemo_service\\vemo_service_apps\\auths_api\\urls.py'> (None:None) ^api/auths/>], [<RegexURLResolver <module 'vemo_service_apps.catalogo_api.urls' from 'D:\\Nueva carpeta (2)\\vemo\\vemo_service\\vemo_service_apps\\catalogo_api\\urls.py'> (None:None) ^api/catalogo/>]]}

During handling of the above exception, another exception occurred:

Traceback (most recent call last):
  File "C:\Users\pc\AppData\Local\Programs\Python\Python35-32\lib\site-packages\django\template\base.py", line 885, in _resolve_lookup
    current = current[bit]
TypeError: 'RegexURLResolver' object is not subscriptable

During handling of the above exception, another exception occurred:

Traceback (most recent call last):
  File "C:\Users\pc\AppData\Local\Programs\Python\Python35-32\lib\site-packages\django\template\base.py", line 893, in _resolve_lookup
    current = getattr(current, bit)
AttributeError: 'RegexURLResolver' object has no attribute 'name'

During handling of the above exception, another exception occurred:

Traceback (most recent call last):
  File "C:\Users\pc\AppData\Local\Programs\Python\Python35-32\lib\site-packages\django\template\base.py", line 900, in _resolve_lookup
    current = current[int(bit)]
ValueError: invalid literal for int() with base 10: 'name'

During handling of the above exception, another exception occurred:

Traceback (most recent call last):
  File "C:\Users\pc\AppData\Local\Programs\Python\Python35-32\lib\site-packages\django\template\base.py", line 907, in _resolve_lookup
    (bit, current))  # missing attribute
django.template.base.VariableDoesNotExist: Failed lookup for key [name] in '<RegexURLResolver <RegexURLPattern list> (admin:admin) ^admin/>'
[2016-11-16 15:25:26] DEBUG [django.template:929] Exception while resolving variable 'name' in template 'unknown'.
Traceback (most recent call last):
  File "C:\Users\pc\AppData\Local\Programs\Python\Python35-32\lib\site-packages\django\core\handlers\exception.py", line 39, in inner
    response = get_response(request)
  File "C:\Users\pc\AppData\Local\Programs\Python\Python35-32\lib\site-packages\django\core\handlers\base.py", line 172, in _get_response
    resolver_match = resolver.resolve(request.path_info)
  File "C:\Users\pc\AppData\Local\Programs\Python\Python35-32\lib\site-packages\django\urls\resolvers.py", line 300, in resolve
    raise Resolver404({'tried': tried, 'path': new_path})
django.urls.exceptions.Resolver404: {'path': 'favicon.ico', 'tried': [[<RegexURLResolver <RegexURLPattern list> (admin:admin) ^admin/>], [<RegexURLResolver <module 'django.contrib.admindocs.urls' from 'C:\\Users\\pc\\AppData\\Local\\Programs\\Python\\Python35-32\\lib\\site-packages\\django\\contrib\\admindocs\\urls.py'> (None:None) ^admin/doc/>], [<RegexURLResolver <module 'rest_framework.urls' from 'C:\\Users\\pc\\AppData\\Local\\Programs\\Python\\Python35-32\\lib\\site-packages\\rest_framework\\urls.py'> (rest_framework:rest_framework) ^api-auth/>], [<RegexURLResolver <module 'oauth2_provider.urls' from 'C:\\Users\\pc\\AppData\\Local\\Programs\\Python\\Python35-32\\lib\\site-packages\\oauth2_provider\\urls.py'> (None:oauth2_provider) ^o/>], [<RegexURLResolver <module 'vemo_service_apps.auths_api.urls' from 'D:\\Nueva carpeta (2)\\vemo\\vemo_service\\vemo_service_apps\\auths_api\\urls.py'> (None:None) ^api/auths/>], [<RegexURLResolver <module 'vemo_service_apps.catalogo_api.urls' from 'D:\\Nueva carpeta (2)\\vemo\\vemo_service\\vemo_service_apps\\catalogo_api\\urls.py'> (None:None) ^api/catalogo/>]]}

During handling of the above exception, another exception occurred:

Traceback (most recent call last):
  File "C:\Users\pc\AppData\Local\Programs\Python\Python35-32\lib\site-packages\django\template\base.py", line 885, in _resolve_lookup
    current = current[bit]
TypeError: 'RegexURLResolver' object is not subscriptable

During handling of the above exception, another exception occurred:

Traceback (most recent call last):
  File "C:\Users\pc\AppData\Local\Programs\Python\Python35-32\lib\site-packages\django\template\base.py", line 893, in _resolve_lookup
    current = getattr(current, bit)
AttributeError: 'RegexURLResolver' object has no attribute 'name'

During handling of the above exception, another exception occurred:

Traceback (most recent call last):
  File "C:\Users\pc\AppData\Local\Programs\Python\Python35-32\lib\site-packages\django\template\base.py", line 900, in _resolve_lookup
    current = current[int(bit)]
ValueError: invalid literal for int() with base 10: 'name'

During handling of the above exception, another exception occurred:

Traceback (most recent call last):
  File "C:\Users\pc\AppData\Local\Programs\Python\Python35-32\lib\site-packages\django\template\base.py", line 907, in _resolve_lookup
    (bit, current))  # missing attribute
django.template.base.VariableDoesNotExist: Failed lookup for key [name] in "<RegexURLResolver <module 'django.contrib.admindocs.urls' from 'C:\\\\Users\\\\pc\\\\AppData\\\\Local\\\\Programs\\\\Python\\\\Python35-32\\\\lib\\\\site-packages\\\\django\\\\contrib\\\\admindocs\\\\urls.py'> (None:None) ^admin/doc/>"
[2016-11-16 15:25:26] DEBUG [django.template:929] Exception while resolving variable 'name' in template 'unknown'.
Traceback (most recent call last):
  File "C:\Users\pc\AppData\Local\Programs\Python\Python35-32\lib\site-packages\django\core\handlers\exception.py", line 39, in inner
    response = get_response(request)
  File "C:\Users\pc\AppData\Local\Programs\Python\Python35-32\lib\site-packages\django\core\handlers\base.py", line 172, in _get_response
    resolver_match = resolver.resolve(request.path_info)
  File "C:\Users\pc\AppData\Local\Programs\Python\Python35-32\lib\site-packages\django\urls\resolvers.py", line 300, in resolve
    raise Resolver404({'tried': tried, 'path': new_path})
django.urls.exceptions.Resolver404: {'path': 'favicon.ico', 'tried': [[<RegexURLResolver <RegexURLPattern list> (admin:admin) ^admin/>], [<RegexURLResolver <module 'django.contrib.admindocs.urls' from 'C:\\Users\\pc\\AppData\\Local\\Programs\\Python\\Python35-32\\lib\\site-packages\\django\\contrib\\admindocs\\urls.py'> (None:None) ^admin/doc/>], [<RegexURLResolver <module 'rest_framework.urls' from 'C:\\Users\\pc\\AppData\\Local\\Programs\\Python\\Python35-32\\lib\\site-packages\\rest_framework\\urls.py'> (rest_framework:rest_framework) ^api-auth/>], [<RegexURLResolver <module 'oauth2_provider.urls' from 'C:\\Users\\pc\\AppData\\Local\\Programs\\Python\\Python35-32\\lib\\site-packages\\oauth2_provider\\urls.py'> (None:oauth2_provider) ^o/>], [<RegexURLResolver <module 'vemo_service_apps.auths_api.urls' from 'D:\\Nueva carpeta (2)\\vemo\\vemo_service\\vemo_service_apps\\auths_api\\urls.py'> (None:None) ^api/auths/>], [<RegexURLResolver <module 'vemo_service_apps.catalogo_api.urls' from 'D:\\Nueva carpeta (2)\\vemo\\vemo_service\\vemo_service_apps\\catalogo_api\\urls.py'> (None:None) ^api/catalogo/>]]}

During handling of the above exception, another exception occurred:

Traceback (most recent call last):
  File "C:\Users\pc\AppData\Local\Programs\Python\Python35-32\lib\site-packages\django\template\base.py", line 885, in _resolve_lookup
    current = current[bit]
TypeError: 'RegexURLResolver' object is not subscriptable

During handling of the above exception, another exception occurred:

Traceback (most recent call last):
  File "C:\Users\pc\AppData\Local\Programs\Python\Python35-32\lib\site-packages\django\template\base.py", line 893, in _resolve_lookup
    current = getattr(current, bit)
AttributeError: 'RegexURLResolver' object has no attribute 'name'

During handling of the above exception, another exception occurred:

Traceback (most recent call last):
  File "C:\Users\pc\AppData\Local\Programs\Python\Python35-32\lib\site-packages\django\template\base.py", line 900, in _resolve_lookup
    current = current[int(bit)]
ValueError: invalid literal for int() with base 10: 'name'

During handling of the above exception, another exception occurred:

Traceback (most recent call last):
  File "C:\Users\pc\AppData\Local\Programs\Python\Python35-32\lib\site-packages\django\template\base.py", line 907, in _resolve_lookup
    (bit, current))  # missing attribute
django.template.base.VariableDoesNotExist: Failed lookup for key [name] in "<RegexURLResolver <module 'rest_framework.urls' from 'C:\\\\Users\\\\pc\\\\AppData\\\\Local\\\\Programs\\\\Python\\\\Python35-32\\\\lib\\\\site-packages\\\\rest_framework\\\\urls.py'> (rest_framework:rest_framework) ^api-auth/>"
[2016-11-16 15:25:26] DEBUG [django.template:929] Exception while resolving variable 'name' in template 'unknown'.
Traceback (most recent call last):
  File "C:\Users\pc\AppData\Local\Programs\Python\Python35-32\lib\site-packages\django\core\handlers\exception.py", line 39, in inner
    response = get_response(request)
  File "C:\Users\pc\AppData\Local\Programs\Python\Python35-32\lib\site-packages\django\core\handlers\base.py", line 172, in _get_response
    resolver_match = resolver.resolve(request.path_info)
  File "C:\Users\pc\AppData\Local\Programs\Python\Python35-32\lib\site-packages\django\urls\resolvers.py", line 300, in resolve
    raise Resolver404({'tried': tried, 'path': new_path})
django.urls.exceptions.Resolver404: {'path': 'favicon.ico', 'tried': [[<RegexURLResolver <RegexURLPattern list> (admin:admin) ^admin/>], [<RegexURLResolver <module 'django.contrib.admindocs.urls' from 'C:\\Users\\pc\\AppData\\Local\\Programs\\Python\\Python35-32\\lib\\site-packages\\django\\contrib\\admindocs\\urls.py'> (None:None) ^admin/doc/>], [<RegexURLResolver <module 'rest_framework.urls' from 'C:\\Users\\pc\\AppData\\Local\\Programs\\Python\\Python35-32\\lib\\site-packages\\rest_framework\\urls.py'> (rest_framework:rest_framework) ^api-auth/>], [<RegexURLResolver <module 'oauth2_provider.urls' from 'C:\\Users\\pc\\AppData\\Local\\Programs\\Python\\Python35-32\\lib\\site-packages\\oauth2_provider\\urls.py'> (None:oauth2_provider) ^o/>], [<RegexURLResolver <module 'vemo_service_apps.auths_api.urls' from 'D:\\Nueva carpeta (2)\\vemo\\vemo_service\\vemo_service_apps\\auths_api\\urls.py'> (None:None) ^api/auths/>], [<RegexURLResolver <module 'vemo_service_apps.catalogo_api.urls' from 'D:\\Nueva carpeta (2)\\vemo\\vemo_service\\vemo_service_apps\\catalogo_api\\urls.py'> (None:None) ^api/catalogo/>]]}

During handling of the above exception, another exception occurred:

Traceback (most recent call last):
  File "C:\Users\pc\AppData\Local\Programs\Python\Python35-32\lib\site-packages\django\template\base.py", line 885, in _resolve_lookup
    current = current[bit]
TypeError: 'RegexURLResolver' object is not subscriptable

During handling of the above exception, another exception occurred:

Traceback (most recent call last):
  File "C:\Users\pc\AppData\Local\Programs\Python\Python35-32\lib\site-packages\django\template\base.py", line 893, in _resolve_lookup
    current = getattr(current, bit)
AttributeError: 'RegexURLResolver' object has no attribute 'name'

During handling of the above exception, another exception occurred:

Traceback (most recent call last):
  File "C:\Users\pc\AppData\Local\Programs\Python\Python35-32\lib\site-packages\django\template\base.py", line 900, in _resolve_lookup
    current = current[int(bit)]
ValueError: invalid literal for int() with base 10: 'name'

During handling of the above exception, another exception occurred:

Traceback (most recent call last):
  File "C:\Users\pc\AppData\Local\Programs\Python\Python35-32\lib\site-packages\django\template\base.py", line 907, in _resolve_lookup
    (bit, current))  # missing attribute
django.template.base.VariableDoesNotExist: Failed lookup for key [name] in "<RegexURLResolver <module 'oauth2_provider.urls' from 'C:\\\\Users\\\\pc\\\\AppData\\\\Local\\\\Programs\\\\Python\\\\Python35-32\\\\lib\\\\site-packages\\\\oauth2_provider\\\\urls.py'> (None:oauth2_provider) ^o/>"
[2016-11-16 15:25:26] DEBUG [django.template:929] Exception while resolving variable 'name' in template 'unknown'.
Traceback (most recent call last):
  File "C:\Users\pc\AppData\Local\Programs\Python\Python35-32\lib\site-packages\django\core\handlers\exception.py", line 39, in inner
    response = get_response(request)
  File "C:\Users\pc\AppData\Local\Programs\Python\Python35-32\lib\site-packages\django\core\handlers\base.py", line 172, in _get_response
    resolver_match = resolver.resolve(request.path_info)
  File "C:\Users\pc\AppData\Local\Programs\Python\Python35-32\lib\site-packages\django\urls\resolvers.py", line 300, in resolve
    raise Resolver404({'tried': tried, 'path': new_path})
django.urls.exceptions.Resolver404: {'path': 'favicon.ico', 'tried': [[<RegexURLResolver <RegexURLPattern list> (admin:admin) ^admin/>], [<RegexURLResolver <module 'django.contrib.admindocs.urls' from 'C:\\Users\\pc\\AppData\\Local\\Programs\\Python\\Python35-32\\lib\\site-packages\\django\\contrib\\admindocs\\urls.py'> (None:None) ^admin/doc/>], [<RegexURLResolver <module 'rest_framework.urls' from 'C:\\Users\\pc\\AppData\\Local\\Programs\\Python\\Python35-32\\lib\\site-packages\\rest_framework\\urls.py'> (rest_framework:rest_framework) ^api-auth/>], [<RegexURLResolver <module 'oauth2_provider.urls' from 'C:\\Users\\pc\\AppData\\Local\\Programs\\Python\\Python35-32\\lib\\site-packages\\oauth2_provider\\urls.py'> (None:oauth2_provider) ^o/>], [<RegexURLResolver <module 'vemo_service_apps.auths_api.urls' from 'D:\\Nueva carpeta (2)\\vemo\\vemo_service\\vemo_service_apps\\auths_api\\urls.py'> (None:None) ^api/auths/>], [<RegexURLResolver <module 'vemo_service_apps.catalogo_api.urls' from 'D:\\Nueva carpeta (2)\\vemo\\vemo_service\\vemo_service_apps\\catalogo_api\\urls.py'> (None:None) ^api/catalogo/>]]}

During handling of the above exception, another exception occurred:

Traceback (most recent call last):
  File "C:\Users\pc\AppData\Local\Programs\Python\Python35-32\lib\site-packages\django\template\base.py", line 885, in _resolve_lookup
    current = current[bit]
TypeError: 'RegexURLResolver' object is not subscriptable

During handling of the above exception, another exception occurred:

Traceback (most recent call last):
  File "C:\Users\pc\AppData\Local\Programs\Python\Python35-32\lib\site-packages\django\template\base.py", line 893, in _resolve_lookup
    current = getattr(current, bit)
AttributeError: 'RegexURLResolver' object has no attribute 'name'

During handling of the above exception, another exception occurred:

Traceback (most recent call last):
  File "C:\Users\pc\AppData\Local\Programs\Python\Python35-32\lib\site-packages\django\template\base.py", line 900, in _resolve_lookup
    current = current[int(bit)]
ValueError: invalid literal for int() with base 10: 'name'

During handling of the above exception, another exception occurred:

Traceback (most recent call last):
  File "C:\Users\pc\AppData\Local\Programs\Python\Python35-32\lib\site-packages\django\template\base.py", line 907, in _resolve_lookup
    (bit, current))  # missing attribute
django.template.base.VariableDoesNotExist: Failed lookup for key [name] in "<RegexURLResolver <module 'vemo_service_apps.auths_api.urls' from 'D:\\\\Nueva carpeta (2)\\\\vemo\\\\vemo_service\\\\vemo_service_apps\\\\auths_api\\\\urls.py'> (None:None) ^api/auths/>"
[2016-11-16 15:25:26] DEBUG [django.template:929] Exception while resolving variable 'name' in template 'unknown'.
Traceback (most recent call last):
  File "C:\Users\pc\AppData\Local\Programs\Python\Python35-32\lib\site-packages\django\core\handlers\exception.py", line 39, in inner
    response = get_response(request)
  File "C:\Users\pc\AppData\Local\Programs\Python\Python35-32\lib\site-packages\django\core\handlers\base.py", line 172, in _get_response
    resolver_match = resolver.resolve(request.path_info)
  File "C:\Users\pc\AppData\Local\Programs\Python\Python35-32\lib\site-packages\django\urls\resolvers.py", line 300, in resolve
    raise Resolver404({'tried': tried, 'path': new_path})
django.urls.exceptions.Resolver404: {'path': 'favicon.ico', 'tried': [[<RegexURLResolver <RegexURLPattern list> (admin:admin) ^admin/>], [<RegexURLResolver <module 'django.contrib.admindocs.urls' from 'C:\\Users\\pc\\AppData\\Local\\Programs\\Python\\Python35-32\\lib\\site-packages\\django\\contrib\\admindocs\\urls.py'> (None:None) ^admin/doc/>], [<RegexURLResolver <module 'rest_framework.urls' from 'C:\\Users\\pc\\AppData\\Local\\Programs\\Python\\Python35-32\\lib\\site-packages\\rest_framework\\urls.py'> (rest_framework:rest_framework) ^api-auth/>], [<RegexURLResolver <module 'oauth2_provider.urls' from 'C:\\Users\\pc\\AppData\\Local\\Programs\\Python\\Python35-32\\lib\\site-packages\\oauth2_provider\\urls.py'> (None:oauth2_provider) ^o/>], [<RegexURLResolver <module 'vemo_service_apps.auths_api.urls' from 'D:\\Nueva carpeta (2)\\vemo\\vemo_service\\vemo_service_apps\\auths_api\\urls.py'> (None:None) ^api/auths/>], [<RegexURLResolver <module 'vemo_service_apps.catalogo_api.urls' from 'D:\\Nueva carpeta (2)\\vemo\\vemo_service\\vemo_service_apps\\catalogo_api\\urls.py'> (None:None) ^api/catalogo/>]]}

During handling of the above exception, another exception occurred:

Traceback (most recent call last):
  File "C:\Users\pc\AppData\Local\Programs\Python\Python35-32\lib\site-packages\django\template\base.py", line 885, in _resolve_lookup
    current = current[bit]
TypeError: 'RegexURLResolver' object is not subscriptable

During handling of the above exception, another exception occurred:

Traceback (most recent call last):
  File "C:\Users\pc\AppData\Local\Programs\Python\Python35-32\lib\site-packages\django\template\base.py", line 893, in _resolve_lookup
    current = getattr(current, bit)
AttributeError: 'RegexURLResolver' object has no attribute 'name'

During handling of the above exception, another exception occurred:

Traceback (most recent call last):
  File "C:\Users\pc\AppData\Local\Programs\Python\Python35-32\lib\site-packages\django\template\base.py", line 900, in _resolve_lookup
    current = current[int(bit)]
ValueError: invalid literal for int() with base 10: 'name'

During handling of the above exception, another exception occurred:

Traceback (most recent call last):
  File "C:\Users\pc\AppData\Local\Programs\Python\Python35-32\lib\site-packages\django\template\base.py", line 907, in _resolve_lookup
    (bit, current))  # missing attribute
django.template.base.VariableDoesNotExist: Failed lookup for key [name] in "<RegexURLResolver <module 'vemo_service_apps.catalogo_api.urls' from 'D:\\\\Nueva carpeta (2)\\\\vemo\\\\vemo_service\\\\vemo_service_apps\\\\catalogo_api\\\\urls.py'> (None:None) ^api/catalogo/>"
[2016-11-16 15:25:26] WARNING [django.request:152] Not Found: /favicon.ico
[2016-11-16 15:25:26] WARNING [django.server:131] "GET /favicon.ico HTTP/1.1" 404 2488
[2016-11-16 15:25:26] DEBUG [django.template:929] Exception while resolving variable 'name' in template 'unknown'.
Traceback (most recent call last):
  File "C:\Users\pc\AppData\Local\Programs\Python\Python35-32\lib\site-packages\django\core\handlers\exception.py", line 39, in inner
    response = get_response(request)
  File "C:\Users\pc\AppData\Local\Programs\Python\Python35-32\lib\site-packages\django\core\handlers\base.py", line 172, in _get_response
    resolver_match = resolver.resolve(request.path_info)
  File "C:\Users\pc\AppData\Local\Programs\Python\Python35-32\lib\site-packages\django\urls\resolvers.py", line 300, in resolve
    raise Resolver404({'tried': tried, 'path': new_path})
django.urls.exceptions.Resolver404: {'path': 'favicon.ico', 'tried': [[<RegexURLResolver <RegexURLPattern list> (admin:admin) ^admin/>], [<RegexURLResolver <module 'django.contrib.admindocs.urls' from 'C:\\Users\\pc\\AppData\\Local\\Programs\\Python\\Python35-32\\lib\\site-packages\\django\\contrib\\admindocs\\urls.py'> (None:None) ^admin/doc/>], [<RegexURLResolver <module 'rest_framework.urls' from 'C:\\Users\\pc\\AppData\\Local\\Programs\\Python\\Python35-32\\lib\\site-packages\\rest_framework\\urls.py'> (rest_framework:rest_framework) ^api-auth/>], [<RegexURLResolver <module 'oauth2_provider.urls' from 'C:\\Users\\pc\\AppData\\Local\\Programs\\Python\\Python35-32\\lib\\site-packages\\oauth2_provider\\urls.py'> (None:oauth2_provider) ^o/>], [<RegexURLResolver <module 'vemo_service_apps.auths_api.urls' from 'D:\\Nueva carpeta (2)\\vemo\\vemo_service\\vemo_service_apps\\auths_api\\urls.py'> (None:None) ^api/auths/>], [<RegexURLResolver <module 'vemo_service_apps.catalogo_api.urls' from 'D:\\Nueva carpeta (2)\\vemo\\vemo_service\\vemo_service_apps\\catalogo_api\\urls.py'> (None:None) ^api/catalogo/>]]}

During handling of the above exception, another exception occurred:

Traceback (most recent call last):
  File "C:\Users\pc\AppData\Local\Programs\Python\Python35-32\lib\site-packages\django\template\base.py", line 885, in _resolve_lookup
    current = current[bit]
TypeError: 'RegexURLResolver' object is not subscriptable

During handling of the above exception, another exception occurred:

Traceback (most recent call last):
  File "C:\Users\pc\AppData\Local\Programs\Python\Python35-32\lib\site-packages\django\template\base.py", line 893, in _resolve_lookup
    current = getattr(current, bit)
AttributeError: 'RegexURLResolver' object has no attribute 'name'

During handling of the above exception, another exception occurred:

Traceback (most recent call last):
  File "C:\Users\pc\AppData\Local\Programs\Python\Python35-32\lib\site-packages\django\template\base.py", line 900, in _resolve_lookup
    current = current[int(bit)]
ValueError: invalid literal for int() with base 10: 'name'

During handling of the above exception, another exception occurred:

Traceback (most recent call last):
  File "C:\Users\pc\AppData\Local\Programs\Python\Python35-32\lib\site-packages\django\template\base.py", line 907, in _resolve_lookup
    (bit, current))  # missing attribute
django.template.base.VariableDoesNotExist: Failed lookup for key [name] in '<RegexURLResolver <RegexURLPattern list> (admin:admin) ^admin/>'
[2016-11-16 15:25:26] DEBUG [django.template:929] Exception while resolving variable 'name' in template 'unknown'.
Traceback (most recent call last):
  File "C:\Users\pc\AppData\Local\Programs\Python\Python35-32\lib\site-packages\django\core\handlers\exception.py", line 39, in inner
    response = get_response(request)
  File "C:\Users\pc\AppData\Local\Programs\Python\Python35-32\lib\site-packages\django\core\handlers\base.py", line 172, in _get_response
    resolver_match = resolver.resolve(request.path_info)
  File "C:\Users\pc\AppData\Local\Programs\Python\Python35-32\lib\site-packages\django\urls\resolvers.py", line 300, in resolve
    raise Resolver404({'tried': tried, 'path': new_path})
django.urls.exceptions.Resolver404: {'path': 'favicon.ico', 'tried': [[<RegexURLResolver <RegexURLPattern list> (admin:admin) ^admin/>], [<RegexURLResolver <module 'django.contrib.admindocs.urls' from 'C:\\Users\\pc\\AppData\\Local\\Programs\\Python\\Python35-32\\lib\\site-packages\\django\\contrib\\admindocs\\urls.py'> (None:None) ^admin/doc/>], [<RegexURLResolver <module 'rest_framework.urls' from 'C:\\Users\\pc\\AppData\\Local\\Programs\\Python\\Python35-32\\lib\\site-packages\\rest_framework\\urls.py'> (rest_framework:rest_framework) ^api-auth/>], [<RegexURLResolver <module 'oauth2_provider.urls' from 'C:\\Users\\pc\\AppData\\Local\\Programs\\Python\\Python35-32\\lib\\site-packages\\oauth2_provider\\urls.py'> (None:oauth2_provider) ^o/>], [<RegexURLResolver <module 'vemo_service_apps.auths_api.urls' from 'D:\\Nueva carpeta (2)\\vemo\\vemo_service\\vemo_service_apps\\auths_api\\urls.py'> (None:None) ^api/auths/>], [<RegexURLResolver <module 'vemo_service_apps.catalogo_api.urls' from 'D:\\Nueva carpeta (2)\\vemo\\vemo_service\\vemo_service_apps\\catalogo_api\\urls.py'> (None:None) ^api/catalogo/>]]}

During handling of the above exception, another exception occurred:

Traceback (most recent call last):
  File "C:\Users\pc\AppData\Local\Programs\Python\Python35-32\lib\site-packages\django\template\base.py", line 885, in _resolve_lookup
    current = current[bit]
TypeError: 'RegexURLResolver' object is not subscriptable

During handling of the above exception, another exception occurred:

Traceback (most recent call last):
  File "C:\Users\pc\AppData\Local\Programs\Python\Python35-32\lib\site-packages\django\template\base.py", line 893, in _resolve_lookup
    current = getattr(current, bit)
AttributeError: 'RegexURLResolver' object has no attribute 'name'

During handling of the above exception, another exception occurred:

Traceback (most recent call last):
  File "C:\Users\pc\AppData\Local\Programs\Python\Python35-32\lib\site-packages\django\template\base.py", line 900, in _resolve_lookup
    current = current[int(bit)]
ValueError: invalid literal for int() with base 10: 'name'

During handling of the above exception, another exception occurred:

Traceback (most recent call last):
  File "C:\Users\pc\AppData\Local\Programs\Python\Python35-32\lib\site-packages\django\template\base.py", line 907, in _resolve_lookup
    (bit, current))  # missing attribute
django.template.base.VariableDoesNotExist: Failed lookup for key [name] in "<RegexURLResolver <module 'django.contrib.admindocs.urls' from 'C:\\\\Users\\\\pc\\\\AppData\\\\Local\\\\Programs\\\\Python\\\\Python35-32\\\\lib\\\\site-packages\\\\django\\\\contrib\\\\admindocs\\\\urls.py'> (None:None) ^admin/doc/>"
[2016-11-16 15:25:26] DEBUG [django.template:929] Exception while resolving variable 'name' in template 'unknown'.
Traceback (most recent call last):
  File "C:\Users\pc\AppData\Local\Programs\Python\Python35-32\lib\site-packages\django\core\handlers\exception.py", line 39, in inner
    response = get_response(request)
  File "C:\Users\pc\AppData\Local\Programs\Python\Python35-32\lib\site-packages\django\core\handlers\base.py", line 172, in _get_response
    resolver_match = resolver.resolve(request.path_info)
  File "C:\Users\pc\AppData\Local\Programs\Python\Python35-32\lib\site-packages\django\urls\resolvers.py", line 300, in resolve
    raise Resolver404({'tried': tried, 'path': new_path})
django.urls.exceptions.Resolver404: {'path': 'favicon.ico', 'tried': [[<RegexURLResolver <RegexURLPattern list> (admin:admin) ^admin/>], [<RegexURLResolver <module 'django.contrib.admindocs.urls' from 'C:\\Users\\pc\\AppData\\Local\\Programs\\Python\\Python35-32\\lib\\site-packages\\django\\contrib\\admindocs\\urls.py'> (None:None) ^admin/doc/>], [<RegexURLResolver <module 'rest_framework.urls' from 'C:\\Users\\pc\\AppData\\Local\\Programs\\Python\\Python35-32\\lib\\site-packages\\rest_framework\\urls.py'> (rest_framework:rest_framework) ^api-auth/>], [<RegexURLResolver <module 'oauth2_provider.urls' from 'C:\\Users\\pc\\AppData\\Local\\Programs\\Python\\Python35-32\\lib\\site-packages\\oauth2_provider\\urls.py'> (None:oauth2_provider) ^o/>], [<RegexURLResolver <module 'vemo_service_apps.auths_api.urls' from 'D:\\Nueva carpeta (2)\\vemo\\vemo_service\\vemo_service_apps\\auths_api\\urls.py'> (None:None) ^api/auths/>], [<RegexURLResolver <module 'vemo_service_apps.catalogo_api.urls' from 'D:\\Nueva carpeta (2)\\vemo\\vemo_service\\vemo_service_apps\\catalogo_api\\urls.py'> (None:None) ^api/catalogo/>]]}

During handling of the above exception, another exception occurred:

Traceback (most recent call last):
  File "C:\Users\pc\AppData\Local\Programs\Python\Python35-32\lib\site-packages\django\template\base.py", line 885, in _resolve_lookup
    current = current[bit]
TypeError: 'RegexURLResolver' object is not subscriptable

During handling of the above exception, another exception occurred:

Traceback (most recent call last):
  File "C:\Users\pc\AppData\Local\Programs\Python\Python35-32\lib\site-packages\django\template\base.py", line 893, in _resolve_lookup
    current = getattr(current, bit)
AttributeError: 'RegexURLResolver' object has no attribute 'name'

During handling of the above exception, another exception occurred:

Traceback (most recent call last):
  File "C:\Users\pc\AppData\Local\Programs\Python\Python35-32\lib\site-packages\django\template\base.py", line 900, in _resolve_lookup
    current = current[int(bit)]
ValueError: invalid literal for int() with base 10: 'name'

During handling of the above exception, another exception occurred:

Traceback (most recent call last):
  File "C:\Users\pc\AppData\Local\Programs\Python\Python35-32\lib\site-packages\django\template\base.py", line 907, in _resolve_lookup
    (bit, current))  # missing attribute
django.template.base.VariableDoesNotExist: Failed lookup for key [name] in "<RegexURLResolver <module 'rest_framework.urls' from 'C:\\\\Users\\\\pc\\\\AppData\\\\Local\\\\Programs\\\\Python\\\\Python35-32\\\\lib\\\\site-packages\\\\rest_framework\\\\urls.py'> (rest_framework:rest_framework) ^api-auth/>"
[2016-11-16 15:25:26] DEBUG [django.template:929] Exception while resolving variable 'name' in template 'unknown'.
Traceback (most recent call last):
  File "C:\Users\pc\AppData\Local\Programs\Python\Python35-32\lib\site-packages\django\core\handlers\exception.py", line 39, in inner
    response = get_response(request)
  File "C:\Users\pc\AppData\Local\Programs\Python\Python35-32\lib\site-packages\django\core\handlers\base.py", line 172, in _get_response
    resolver_match = resolver.resolve(request.path_info)
  File "C:\Users\pc\AppData\Local\Programs\Python\Python35-32\lib\site-packages\django\urls\resolvers.py", line 300, in resolve
    raise Resolver404({'tried': tried, 'path': new_path})
django.urls.exceptions.Resolver404: {'path': 'favicon.ico', 'tried': [[<RegexURLResolver <RegexURLPattern list> (admin:admin) ^admin/>], [<RegexURLResolver <module 'django.contrib.admindocs.urls' from 'C:\\Users\\pc\\AppData\\Local\\Programs\\Python\\Python35-32\\lib\\site-packages\\django\\contrib\\admindocs\\urls.py'> (None:None) ^admin/doc/>], [<RegexURLResolver <module 'rest_framework.urls' from 'C:\\Users\\pc\\AppData\\Local\\Programs\\Python\\Python35-32\\lib\\site-packages\\rest_framework\\urls.py'> (rest_framework:rest_framework) ^api-auth/>], [<RegexURLResolver <module 'oauth2_provider.urls' from 'C:\\Users\\pc\\AppData\\Local\\Programs\\Python\\Python35-32\\lib\\site-packages\\oauth2_provider\\urls.py'> (None:oauth2_provider) ^o/>], [<RegexURLResolver <module 'vemo_service_apps.auths_api.urls' from 'D:\\Nueva carpeta (2)\\vemo\\vemo_service\\vemo_service_apps\\auths_api\\urls.py'> (None:None) ^api/auths/>], [<RegexURLResolver <module 'vemo_service_apps.catalogo_api.urls' from 'D:\\Nueva carpeta (2)\\vemo\\vemo_service\\vemo_service_apps\\catalogo_api\\urls.py'> (None:None) ^api/catalogo/>]]}

During handling of the above exception, another exception occurred:

Traceback (most recent call last):
  File "C:\Users\pc\AppData\Local\Programs\Python\Python35-32\lib\site-packages\django\template\base.py", line 885, in _resolve_lookup
    current = current[bit]
TypeError: 'RegexURLResolver' object is not subscriptable

During handling of the above exception, another exception occurred:

Traceback (most recent call last):
  File "C:\Users\pc\AppData\Local\Programs\Python\Python35-32\lib\site-packages\django\template\base.py", line 893, in _resolve_lookup
    current = getattr(current, bit)
AttributeError: 'RegexURLResolver' object has no attribute 'name'

During handling of the above exception, another exception occurred:

Traceback (most recent call last):
  File "C:\Users\pc\AppData\Local\Programs\Python\Python35-32\lib\site-packages\django\template\base.py", line 900, in _resolve_lookup
    current = current[int(bit)]
ValueError: invalid literal for int() with base 10: 'name'

During handling of the above exception, another exception occurred:

Traceback (most recent call last):
  File "C:\Users\pc\AppData\Local\Programs\Python\Python35-32\lib\site-packages\django\template\base.py", line 907, in _resolve_lookup
    (bit, current))  # missing attribute
django.template.base.VariableDoesNotExist: Failed lookup for key [name] in "<RegexURLResolver <module 'oauth2_provider.urls' from 'C:\\\\Users\\\\pc\\\\AppData\\\\Local\\\\Programs\\\\Python\\\\Python35-32\\\\lib\\\\site-packages\\\\oauth2_provider\\\\urls.py'> (None:oauth2_provider) ^o/>"
[2016-11-16 15:25:26] DEBUG [django.template:929] Exception while resolving variable 'name' in template 'unknown'.
Traceback (most recent call last):
  File "C:\Users\pc\AppData\Local\Programs\Python\Python35-32\lib\site-packages\django\core\handlers\exception.py", line 39, in inner
    response = get_response(request)
  File "C:\Users\pc\AppData\Local\Programs\Python\Python35-32\lib\site-packages\django\core\handlers\base.py", line 172, in _get_response
    resolver_match = resolver.resolve(request.path_info)
  File "C:\Users\pc\AppData\Local\Programs\Python\Python35-32\lib\site-packages\django\urls\resolvers.py", line 300, in resolve
    raise Resolver404({'tried': tried, 'path': new_path})
django.urls.exceptions.Resolver404: {'path': 'favicon.ico', 'tried': [[<RegexURLResolver <RegexURLPattern list> (admin:admin) ^admin/>], [<RegexURLResolver <module 'django.contrib.admindocs.urls' from 'C:\\Users\\pc\\AppData\\Local\\Programs\\Python\\Python35-32\\lib\\site-packages\\django\\contrib\\admindocs\\urls.py'> (None:None) ^admin/doc/>], [<RegexURLResolver <module 'rest_framework.urls' from 'C:\\Users\\pc\\AppData\\Local\\Programs\\Python\\Python35-32\\lib\\site-packages\\rest_framework\\urls.py'> (rest_framework:rest_framework) ^api-auth/>], [<RegexURLResolver <module 'oauth2_provider.urls' from 'C:\\Users\\pc\\AppData\\Local\\Programs\\Python\\Python35-32\\lib\\site-packages\\oauth2_provider\\urls.py'> (None:oauth2_provider) ^o/>], [<RegexURLResolver <module 'vemo_service_apps.auths_api.urls' from 'D:\\Nueva carpeta (2)\\vemo\\vemo_service\\vemo_service_apps\\auths_api\\urls.py'> (None:None) ^api/auths/>], [<RegexURLResolver <module 'vemo_service_apps.catalogo_api.urls' from 'D:\\Nueva carpeta (2)\\vemo\\vemo_service\\vemo_service_apps\\catalogo_api\\urls.py'> (None:None) ^api/catalogo/>]]}

During handling of the above exception, another exception occurred:

Traceback (most recent call last):
  File "C:\Users\pc\AppData\Local\Programs\Python\Python35-32\lib\site-packages\django\template\base.py", line 885, in _resolve_lookup
    current = current[bit]
TypeError: 'RegexURLResolver' object is not subscriptable

During handling of the above exception, another exception occurred:

Traceback (most recent call last):
  File "C:\Users\pc\AppData\Local\Programs\Python\Python35-32\lib\site-packages\django\template\base.py", line 893, in _resolve_lookup
    current = getattr(current, bit)
AttributeError: 'RegexURLResolver' object has no attribute 'name'

During handling of the above exception, another exception occurred:

Traceback (most recent call last):
  File "C:\Users\pc\AppData\Local\Programs\Python\Python35-32\lib\site-packages\django\template\base.py", line 900, in _resolve_lookup
    current = current[int(bit)]
ValueError: invalid literal for int() with base 10: 'name'

During handling of the above exception, another exception occurred:

Traceback (most recent call last):
  File "C:\Users\pc\AppData\Local\Programs\Python\Python35-32\lib\site-packages\django\template\base.py", line 907, in _resolve_lookup
    (bit, current))  # missing attribute
django.template.base.VariableDoesNotExist: Failed lookup for key [name] in "<RegexURLResolver <module 'vemo_service_apps.auths_api.urls' from 'D:\\\\Nueva carpeta (2)\\\\vemo\\\\vemo_service\\\\vemo_service_apps\\\\auths_api\\\\urls.py'> (None:None) ^api/auths/>"
[2016-11-16 15:25:26] DEBUG [django.template:929] Exception while resolving variable 'name' in template 'unknown'.
Traceback (most recent call last):
  File "C:\Users\pc\AppData\Local\Programs\Python\Python35-32\lib\site-packages\django\core\handlers\exception.py", line 39, in inner
    response = get_response(request)
  File "C:\Users\pc\AppData\Local\Programs\Python\Python35-32\lib\site-packages\django\core\handlers\base.py", line 172, in _get_response
    resolver_match = resolver.resolve(request.path_info)
  File "C:\Users\pc\AppData\Local\Programs\Python\Python35-32\lib\site-packages\django\urls\resolvers.py", line 300, in resolve
    raise Resolver404({'tried': tried, 'path': new_path})
django.urls.exceptions.Resolver404: {'path': 'favicon.ico', 'tried': [[<RegexURLResolver <RegexURLPattern list> (admin:admin) ^admin/>], [<RegexURLResolver <module 'django.contrib.admindocs.urls' from 'C:\\Users\\pc\\AppData\\Local\\Programs\\Python\\Python35-32\\lib\\site-packages\\django\\contrib\\admindocs\\urls.py'> (None:None) ^admin/doc/>], [<RegexURLResolver <module 'rest_framework.urls' from 'C:\\Users\\pc\\AppData\\Local\\Programs\\Python\\Python35-32\\lib\\site-packages\\rest_framework\\urls.py'> (rest_framework:rest_framework) ^api-auth/>], [<RegexURLResolver <module 'oauth2_provider.urls' from 'C:\\Users\\pc\\AppData\\Local\\Programs\\Python\\Python35-32\\lib\\site-packages\\oauth2_provider\\urls.py'> (None:oauth2_provider) ^o/>], [<RegexURLResolver <module 'vemo_service_apps.auths_api.urls' from 'D:\\Nueva carpeta (2)\\vemo\\vemo_service\\vemo_service_apps\\auths_api\\urls.py'> (None:None) ^api/auths/>], [<RegexURLResolver <module 'vemo_service_apps.catalogo_api.urls' from 'D:\\Nueva carpeta (2)\\vemo\\vemo_service\\vemo_service_apps\\catalogo_api\\urls.py'> (None:None) ^api/catalogo/>]]}

During handling of the above exception, another exception occurred:

Traceback (most recent call last):
  File "C:\Users\pc\AppData\Local\Programs\Python\Python35-32\lib\site-packages\django\template\base.py", line 885, in _resolve_lookup
    current = current[bit]
TypeError: 'RegexURLResolver' object is not subscriptable

During handling of the above exception, another exception occurred:

Traceback (most recent call last):
  File "C:\Users\pc\AppData\Local\Programs\Python\Python35-32\lib\site-packages\django\template\base.py", line 893, in _resolve_lookup
    current = getattr(current, bit)
AttributeError: 'RegexURLResolver' object has no attribute 'name'

During handling of the above exception, another exception occurred:

Traceback (most recent call last):
  File "C:\Users\pc\AppData\Local\Programs\Python\Python35-32\lib\site-packages\django\template\base.py", line 900, in _resolve_lookup
    current = current[int(bit)]
ValueError: invalid literal for int() with base 10: 'name'

During handling of the above exception, another exception occurred:

Traceback (most recent call last):
  File "C:\Users\pc\AppData\Local\Programs\Python\Python35-32\lib\site-packages\django\template\base.py", line 907, in _resolve_lookup
    (bit, current))  # missing attribute
django.template.base.VariableDoesNotExist: Failed lookup for key [name] in "<RegexURLResolver <module 'vemo_service_apps.catalogo_api.urls' from 'D:\\\\Nueva carpeta (2)\\\\vemo\\\\vemo_service\\\\vemo_service_apps\\\\catalogo_api\\\\urls.py'> (None:None) ^api/catalogo/>"
[2016-11-16 15:25:26] WARNING [django.request:152] Not Found: /favicon.ico
[2016-11-16 15:25:26] WARNING [django.server:131] "GET /favicon.ico HTTP/1.1" 404 2488
[2016-11-16 15:25:28] INFO [django.server:131] "OPTIONS /api/auths/usermenu/ HTTP/1.1" 200 0
[2016-11-16 15:25:28] INFO [django.server:131] "OPTIONS /api/auths/localuserinfo/ HTTP/1.1" 200 0
[2016-11-16 15:25:28] DEBUG [django.db.backends:90] (0.027) SELECT "oauth2_provider_accesstoken"."id", "oauth2_provider_accesstoken"."user_id", "oauth2_provider_accesstoken"."token", "oauth2_provider_accesstoken"."application_id", "oauth2_provider_accesstoken"."expires", "oauth2_provider_accesstoken"."scope", "auths_user"."password", "auths_user"."last_login", "auths_user"."is_superuser", "auths_user"."username", "auths_user"."first_name", "auths_user"."last_name", "auths_user"."email", "auths_user"."is_staff", "auths_user"."is_active", "auths_user"."date_joined", "auths_user"."id", "auths_user"."last_hierarchy_id", "auths_user"."last_module_id", "auths_user"."person_id", "auths_user"."updated_at", "auths_user"."registered_by", "oauth2_provider_application"."id", "oauth2_provider_application"."client_id", "oauth2_provider_application"."user_id", "oauth2_provider_application"."redirect_uris", "oauth2_provider_application"."client_type", "oauth2_provider_application"."authorization_grant_type", "oauth2_provider_application"."client_secret", "oauth2_provider_application"."name", "oauth2_provider_application"."skip_authorization" FROM "oauth2_provider_accesstoken" LEFT OUTER JOIN "auths_user" ON ("oauth2_provider_accesstoken"."user_id" = "auths_user"."id") INNER JOIN "oauth2_provider_application" ON ("oauth2_provider_accesstoken"."application_id" = "oauth2_provider_application"."id") WHERE "oauth2_provider_accesstoken"."token" = 'pbonUfwDdVWqNXL836FceAznDaeFi5'; args=('pbonUfwDdVWqNXL836FceAznDaeFi5',)
[2016-11-16 15:25:28] WARNING [django.server:131] "GET /api/auths/usermenu/ HTTP/1.1" 401 58
[2016-11-16 15:25:28] DEBUG [django.db.backends:90] (0.047) SELECT "oauth2_provider_accesstoken"."id", "oauth2_provider_accesstoken"."user_id", "oauth2_provider_accesstoken"."token", "oauth2_provider_accesstoken"."application_id", "oauth2_provider_accesstoken"."expires", "oauth2_provider_accesstoken"."scope", "auths_user"."password", "auths_user"."last_login", "auths_user"."is_superuser", "auths_user"."username", "auths_user"."first_name", "auths_user"."last_name", "auths_user"."email", "auths_user"."is_staff", "auths_user"."is_active", "auths_user"."date_joined", "auths_user"."id", "auths_user"."last_hierarchy_id", "auths_user"."last_module_id", "auths_user"."person_id", "auths_user"."updated_at", "auths_user"."registered_by", "oauth2_provider_application"."id", "oauth2_provider_application"."client_id", "oauth2_provider_application"."user_id", "oauth2_provider_application"."redirect_uris", "oauth2_provider_application"."client_type", "oauth2_provider_application"."authorization_grant_type", "oauth2_provider_application"."client_secret", "oauth2_provider_application"."name", "oauth2_provider_application"."skip_authorization" FROM "oauth2_provider_accesstoken" LEFT OUTER JOIN "auths_user" ON ("oauth2_provider_accesstoken"."user_id" = "auths_user"."id") INNER JOIN "oauth2_provider_application" ON ("oauth2_provider_accesstoken"."application_id" = "oauth2_provider_application"."id") WHERE "oauth2_provider_accesstoken"."token" = 'pbonUfwDdVWqNXL836FceAznDaeFi5'; args=('pbonUfwDdVWqNXL836FceAznDaeFi5',)
[2016-11-16 15:25:28] WARNING [django.server:131] "GET /api/auths/localuserinfo/ HTTP/1.1" 401 58
[2016-11-16 15:25:30] DEBUG [django.db.backends:90] (0.002) SELECT "auths_menu"."router_json" FROM "auths_menu" ORDER BY "auths_menu"."pos" ASC; args=()
[2016-11-16 15:25:30] INFO [django.server:131] "GET /api/auths/routers/ HTTP/1.1" 200 2
[2016-11-16 15:25:36] DEBUG [django.db.backends:90] (0.004) SELECT "oauth2_provider_application"."id", "oauth2_provider_application"."client_id", "oauth2_provider_application"."user_id", "oauth2_provider_application"."redirect_uris", "oauth2_provider_application"."client_type", "oauth2_provider_application"."authorization_grant_type", "oauth2_provider_application"."client_secret", "oauth2_provider_application"."name", "oauth2_provider_application"."skip_authorization" FROM "oauth2_provider_application" WHERE "oauth2_provider_application"."client_id" = 'gyEJ310NDKMKrYvOMbwSnu9UFkJkXE5E48dCLRZK'; args=('gyEJ310NDKMKrYvOMbwSnu9UFkJkXE5E48dCLRZK',)
[2016-11-16 15:25:36] DEBUG [django.db.backends:90] (0.001) SELECT "auths_user"."password", "auths_user"."last_login", "auths_user"."is_superuser", "auths_user"."username", "auths_user"."first_name", "auths_user"."last_name", "auths_user"."email", "auths_user"."is_staff", "auths_user"."is_active", "auths_user"."date_joined", "auths_user"."id", "auths_user"."last_hierarchy_id", "auths_user"."last_module_id", "auths_user"."person_id", "auths_user"."updated_at", "auths_user"."registered_by" FROM "auths_user" WHERE "auths_user"."username" = 'admin'; args=('admin',)
[2016-11-16 15:25:37] DEBUG [django.db.backends:90] (0.000) BEGIN; args=None
[2016-11-16 15:25:37] DEBUG [django.db.backends:90] (0.020) INSERT INTO "oauth2_provider_accesstoken" ("user_id", "token", "application_id", "expires", "scope") VALUES ('3651942c1384420da02bbf9e5eca3faa', 'MPAbusN6LfH2ZfL37brKEpT0lU89rc', 1, '2016-11-17 06:25:37.058953', 'write read'); args=['3651942c1384420da02bbf9e5eca3faa', 'MPAbusN6LfH2ZfL37brKEpT0lU89rc', 1, '2016-11-17 06:25:37.058953', 'write read']
[2016-11-16 15:25:37] DEBUG [django.db.backends:90] (0.000) BEGIN; args=None
[2016-11-16 15:25:37] DEBUG [django.db.backends:90] (0.014) INSERT INTO "oauth2_provider_refreshtoken" ("user_id", "token", "application_id", "access_token_id") VALUES ('3651942c1384420da02bbf9e5eca3faa', 'J0oYtpH3krhi5gQL25RErmfpwcsdFQ', 1, 19); args=['3651942c1384420da02bbf9e5eca3faa', 'J0oYtpH3krhi5gQL25RErmfpwcsdFQ', 1, 19]
[2016-11-16 15:25:37] INFO [django.server:131] "POST /o/token/ HTTP/1.1" 200 169
[2016-11-16 15:25:38] DEBUG [django.db.backends:90] (0.003) SELECT "oauth2_provider_accesstoken"."id", "oauth2_provider_accesstoken"."user_id", "oauth2_provider_accesstoken"."token", "oauth2_provider_accesstoken"."application_id", "oauth2_provider_accesstoken"."expires", "oauth2_provider_accesstoken"."scope", "auths_user"."password", "auths_user"."last_login", "auths_user"."is_superuser", "auths_user"."username", "auths_user"."first_name", "auths_user"."last_name", "auths_user"."email", "auths_user"."is_staff", "auths_user"."is_active", "auths_user"."date_joined", "auths_user"."id", "auths_user"."last_hierarchy_id", "auths_user"."last_module_id", "auths_user"."person_id", "auths_user"."updated_at", "auths_user"."registered_by", "oauth2_provider_application"."id", "oauth2_provider_application"."client_id", "oauth2_provider_application"."user_id", "oauth2_provider_application"."redirect_uris", "oauth2_provider_application"."client_type", "oauth2_provider_application"."authorization_grant_type", "oauth2_provider_application"."client_secret", "oauth2_provider_application"."name", "oauth2_provider_application"."skip_authorization" FROM "oauth2_provider_accesstoken" LEFT OUTER JOIN "auths_user" ON ("oauth2_provider_accesstoken"."user_id" = "auths_user"."id") INNER JOIN "oauth2_provider_application" ON ("oauth2_provider_accesstoken"."application_id" = "oauth2_provider_application"."id") WHERE "oauth2_provider_accesstoken"."token" = 'MPAbusN6LfH2ZfL37brKEpT0lU89rc'; args=('MPAbusN6LfH2ZfL37brKEpT0lU89rc',)
[2016-11-16 15:25:38] DEBUG [django.db.backends:90] (0.001) SELECT "auths_menu"."id" FROM "auths_menu" WHERE ("auths_menu"."id" IS NOT NULL AND "auths_menu"."module" = 'BACKEND' AND "auths_menu"."is_active" = 1) ORDER BY "auths_menu"."pos" ASC; args=('BACKEND', True)
[2016-11-16 15:25:38] DEBUG [django.db.backends:90] (0.003) SELECT (1) AS "a" FROM "django_session" WHERE "django_session"."session_key" = 's4loz0bzhy3q35ajmn0z5v3i3pdml8p3' LIMIT 1; args=('s4loz0bzhy3q35ajmn0z5v3i3pdml8p3',)
[2016-11-16 15:25:38] DEBUG [django.db.backends:90] (0.000) BEGIN; args=None
[2016-11-16 15:25:38] DEBUG [django.db.backends:90] (0.001) INSERT INTO "django_session" ("session_key", "session_data", "expire_date") SELECT 's4loz0bzhy3q35ajmn0z5v3i3pdml8p3', 'NmE3M2Q3NmYwOTU3YjJmZDBjYmQxYTVjODc5MTExNzM3NjY1YzYzNzp7Il9zZXNzaW9uX2V4cGlyeSI6MzB9', '2016-11-16 20:26:08.619137'; args=('s4loz0bzhy3q35ajmn0z5v3i3pdml8p3', 'NmE3M2Q3NmYwOTU3YjJmZDBjYmQxYTVjODc5MTExNzM3NjY1YzYzNzp7Il9zZXNzaW9uX2V4cGlyeSI6MzB9', '2016-11-16 20:26:08.619137')
[2016-11-16 15:25:38] INFO [django.server:131] "OPTIONS /api/auths/localuserinfo/ HTTP/1.1" 200 0
[2016-11-16 15:25:38] INFO [django.server:131] "GET /api/auths/usermenu/ HTTP/1.1" 200 11
[2016-11-16 15:25:38] DEBUG [django.db.backends:90] (0.051) SELECT "oauth2_provider_accesstoken"."id", "oauth2_provider_accesstoken"."user_id", "oauth2_provider_accesstoken"."token", "oauth2_provider_accesstoken"."application_id", "oauth2_provider_accesstoken"."expires", "oauth2_provider_accesstoken"."scope", "auths_user"."password", "auths_user"."last_login", "auths_user"."is_superuser", "auths_user"."username", "auths_user"."first_name", "auths_user"."last_name", "auths_user"."email", "auths_user"."is_staff", "auths_user"."is_active", "auths_user"."date_joined", "auths_user"."id", "auths_user"."last_hierarchy_id", "auths_user"."last_module_id", "auths_user"."person_id", "auths_user"."updated_at", "auths_user"."registered_by", "oauth2_provider_application"."id", "oauth2_provider_application"."client_id", "oauth2_provider_application"."user_id", "oauth2_provider_application"."redirect_uris", "oauth2_provider_application"."client_type", "oauth2_provider_application"."authorization_grant_type", "oauth2_provider_application"."client_secret", "oauth2_provider_application"."name", "oauth2_provider_application"."skip_authorization" FROM "oauth2_provider_accesstoken" LEFT OUTER JOIN "auths_user" ON ("oauth2_provider_accesstoken"."user_id" = "auths_user"."id") INNER JOIN "oauth2_provider_application" ON ("oauth2_provider_accesstoken"."application_id" = "oauth2_provider_application"."id") WHERE "oauth2_provider_accesstoken"."token" = 'MPAbusN6LfH2ZfL37brKEpT0lU89rc'; args=('MPAbusN6LfH2ZfL37brKEpT0lU89rc',)
[2016-11-16 15:25:38] DEBUG [django.db.backends:90] (0.000) SELECT "auth_group"."id", "auth_group"."name" FROM "auth_group" INNER JOIN "auths_user_groups" ON ("auth_group"."id" = "auths_user_groups"."group_id") WHERE "auths_user_groups"."user_id" = '3651942c1384420da02bbf9e5eca3faa'; args=('3651942c1384420da02bbf9e5eca3faa',)
[2016-11-16 15:25:38] DEBUG [django.db.backends:90] (0.001) SELECT "auth_permission"."id", "auth_permission"."name", "auth_permission"."content_type_id", "auth_permission"."codename" FROM "auth_permission" INNER JOIN "auths_user_user_permissions" ON ("auth_permission"."id" = "auths_user_user_permissions"."permission_id") INNER JOIN "django_content_type" ON ("auth_permission"."content_type_id" = "django_content_type"."id") WHERE "auths_user_user_permissions"."user_id" = '3651942c1384420da02bbf9e5eca3faa' ORDER BY "django_content_type"."app_label" ASC, "django_content_type"."model" ASC, "auth_permission"."codename" ASC; args=('3651942c1384420da02bbf9e5eca3faa',)
[2016-11-16 15:25:38] INFO [django.server:131] "GET /api/auths/localuserinfo/ HTTP/1.1" 200 496
[2016-11-16 15:25:44] INFO [django.server:131] "OPTIONS /api/catalogo/categorias/ HTTP/1.1" 200 0
[2016-11-16 15:25:44] DEBUG [django.db.backends:90] (0.003) SELECT "oauth2_provider_accesstoken"."id", "oauth2_provider_accesstoken"."user_id", "oauth2_provider_accesstoken"."token", "oauth2_provider_accesstoken"."application_id", "oauth2_provider_accesstoken"."expires", "oauth2_provider_accesstoken"."scope", "auths_user"."password", "auths_user"."last_login", "auths_user"."is_superuser", "auths_user"."username", "auths_user"."first_name", "auths_user"."last_name", "auths_user"."email", "auths_user"."is_staff", "auths_user"."is_active", "auths_user"."date_joined", "auths_user"."id", "auths_user"."last_hierarchy_id", "auths_user"."last_module_id", "auths_user"."person_id", "auths_user"."updated_at", "auths_user"."registered_by", "oauth2_provider_application"."id", "oauth2_provider_application"."client_id", "oauth2_provider_application"."user_id", "oauth2_provider_application"."redirect_uris", "oauth2_provider_application"."client_type", "oauth2_provider_application"."authorization_grant_type", "oauth2_provider_application"."client_secret", "oauth2_provider_application"."name", "oauth2_provider_application"."skip_authorization" FROM "oauth2_provider_accesstoken" LEFT OUTER JOIN "auths_user" ON ("oauth2_provider_accesstoken"."user_id" = "auths_user"."id") INNER JOIN "oauth2_provider_application" ON ("oauth2_provider_accesstoken"."application_id" = "oauth2_provider_application"."id") WHERE "oauth2_provider_accesstoken"."token" = 'MPAbusN6LfH2ZfL37brKEpT0lU89rc'; args=('MPAbusN6LfH2ZfL37brKEpT0lU89rc',)
[2016-11-16 15:25:44] DEBUG [django.db.backends:90] (0.001) SELECT "catalogo_categoria"."id", "catalogo_categoria"."nombre", "catalogo_categoria"."codigo", "catalogo_categoria"."estado" FROM "catalogo_categoria" WHERE ("catalogo_categoria"."codigo" LIKE '%%' ESCAPE '\' OR "catalogo_categoria"."nombre" LIKE '%%' ESCAPE '\'); args=('%%', '%%')
[2016-11-16 15:25:44] INFO [django.server:131] "GET /api/catalogo/categorias/ HTTP/1.1" 200 199
[2016-11-16 15:31:26] DEBUG [django.db.backends:90] (0.016) 
            SELECT name, type FROM sqlite_master
            WHERE type in ('table', 'view') AND NOT name='sqlite_sequence'
            ORDER BY name; args=None
[2016-11-16 15:31:26] DEBUG [django.db.backends:90] (0.000) SELECT "django_migrations"."app", "django_migrations"."name" FROM "django_migrations"; args=()
[2016-11-16 15:31:29] DEBUG [django.db.backends:90] (0.005) SELECT "oauth2_provider_accesstoken"."id", "oauth2_provider_accesstoken"."user_id", "oauth2_provider_accesstoken"."token", "oauth2_provider_accesstoken"."application_id", "oauth2_provider_accesstoken"."expires", "oauth2_provider_accesstoken"."scope", "auths_user"."password", "auths_user"."last_login", "auths_user"."is_superuser", "auths_user"."username", "auths_user"."first_name", "auths_user"."last_name", "auths_user"."email", "auths_user"."is_staff", "auths_user"."is_active", "auths_user"."date_joined", "auths_user"."id", "auths_user"."last_hierarchy_id", "auths_user"."last_module_id", "auths_user"."person_id", "auths_user"."updated_at", "auths_user"."registered_by", "oauth2_provider_application"."id", "oauth2_provider_application"."client_id", "oauth2_provider_application"."user_id", "oauth2_provider_application"."redirect_uris", "oauth2_provider_application"."client_type", "oauth2_provider_application"."authorization_grant_type", "oauth2_provider_application"."client_secret", "oauth2_provider_application"."name", "oauth2_provider_application"."skip_authorization" FROM "oauth2_provider_accesstoken" LEFT OUTER JOIN "auths_user" ON ("oauth2_provider_accesstoken"."user_id" = "auths_user"."id") INNER JOIN "oauth2_provider_application" ON ("oauth2_provider_accesstoken"."application_id" = "oauth2_provider_application"."id") WHERE "oauth2_provider_accesstoken"."token" = 'MPAbusN6LfH2ZfL37brKEpT0lU89rc'; args=('MPAbusN6LfH2ZfL37brKEpT0lU89rc',)
[2016-11-16 15:31:29] DEBUG [django.db.backends:90] (0.005) SELECT "oauth2_provider_accesstoken"."id", "oauth2_provider_accesstoken"."user_id", "oauth2_provider_accesstoken"."token", "oauth2_provider_accesstoken"."application_id", "oauth2_provider_accesstoken"."expires", "oauth2_provider_accesstoken"."scope", "auths_user"."password", "auths_user"."last_login", "auths_user"."is_superuser", "auths_user"."username", "auths_user"."first_name", "auths_user"."last_name", "auths_user"."email", "auths_user"."is_staff", "auths_user"."is_active", "auths_user"."date_joined", "auths_user"."id", "auths_user"."last_hierarchy_id", "auths_user"."last_module_id", "auths_user"."person_id", "auths_user"."updated_at", "auths_user"."registered_by", "oauth2_provider_application"."id", "oauth2_provider_application"."client_id", "oauth2_provider_application"."user_id", "oauth2_provider_application"."redirect_uris", "oauth2_provider_application"."client_type", "oauth2_provider_application"."authorization_grant_type", "oauth2_provider_application"."client_secret", "oauth2_provider_application"."name", "oauth2_provider_application"."skip_authorization" FROM "oauth2_provider_accesstoken" LEFT OUTER JOIN "auths_user" ON ("oauth2_provider_accesstoken"."user_id" = "auths_user"."id") INNER JOIN "oauth2_provider_application" ON ("oauth2_provider_accesstoken"."application_id" = "oauth2_provider_application"."id") WHERE "oauth2_provider_accesstoken"."token" = 'MPAbusN6LfH2ZfL37brKEpT0lU89rc'; args=('MPAbusN6LfH2ZfL37brKEpT0lU89rc',)
[2016-11-16 15:31:29] DEBUG [django.db.backends:90] (0.000) SELECT "auths_menu"."id" FROM "auths_menu" WHERE ("auths_menu"."id" IS NOT NULL AND "auths_menu"."is_active" = 1 AND "auths_menu"."module" = 'BACKEND') ORDER BY "auths_menu"."pos" ASC; args=(True, 'BACKEND')
[2016-11-16 15:31:29] DEBUG [django.db.backends:90] (0.001) SELECT (1) AS "a" FROM "django_session" WHERE "django_session"."session_key" = 'fp5uv3m4cg4dx3msd64fldrrbfce1yrg' LIMIT 1; args=('fp5uv3m4cg4dx3msd64fldrrbfce1yrg',)
[2016-11-16 15:31:29] DEBUG [django.db.backends:90] (0.000) BEGIN; args=None
[2016-11-16 15:31:29] DEBUG [django.db.backends:90] (0.004) INSERT INTO "django_session" ("session_key", "session_data", "expire_date") SELECT 'fp5uv3m4cg4dx3msd64fldrrbfce1yrg', 'NmE3M2Q3NmYwOTU3YjJmZDBjYmQxYTVjODc5MTExNzM3NjY1YzYzNzp7Il9zZXNzaW9uX2V4cGlyeSI6MzB9', '2016-11-16 20:31:59.249080'; args=('fp5uv3m4cg4dx3msd64fldrrbfce1yrg', 'NmE3M2Q3NmYwOTU3YjJmZDBjYmQxYTVjODc5MTExNzM3NjY1YzYzNzp7Il9zZXNzaW9uX2V4cGlyeSI6MzB9', '2016-11-16 20:31:59.249080')
[2016-11-16 15:31:29] INFO [django.server:131] "GET /api/auths/usermenu/ HTTP/1.1" 200 11
[2016-11-16 15:31:29] DEBUG [django.db.backends:90] (0.131) SELECT "auth_group"."id", "auth_group"."name" FROM "auth_group" INNER JOIN "auths_user_groups" ON ("auth_group"."id" = "auths_user_groups"."group_id") WHERE "auths_user_groups"."user_id" = '3651942c1384420da02bbf9e5eca3faa'; args=('3651942c1384420da02bbf9e5eca3faa',)
[2016-11-16 15:31:29] DEBUG [django.db.backends:90] (0.000) SELECT "auth_permission"."id", "auth_permission"."name", "auth_permission"."content_type_id", "auth_permission"."codename" FROM "auth_permission" INNER JOIN "auths_user_user_permissions" ON ("auth_permission"."id" = "auths_user_user_permissions"."permission_id") INNER JOIN "django_content_type" ON ("auth_permission"."content_type_id" = "django_content_type"."id") WHERE "auths_user_user_permissions"."user_id" = '3651942c1384420da02bbf9e5eca3faa' ORDER BY "django_content_type"."app_label" ASC, "django_content_type"."model" ASC, "auth_permission"."codename" ASC; args=('3651942c1384420da02bbf9e5eca3faa',)
[2016-11-16 15:31:29] INFO [django.server:131] "GET /api/auths/localuserinfo/ HTTP/1.1" 200 496
[2016-11-16 15:31:29] DEBUG [django.db.backends:90] (0.005) SELECT "oauth2_provider_accesstoken"."id", "oauth2_provider_accesstoken"."user_id", "oauth2_provider_accesstoken"."token", "oauth2_provider_accesstoken"."application_id", "oauth2_provider_accesstoken"."expires", "oauth2_provider_accesstoken"."scope", "auths_user"."password", "auths_user"."last_login", "auths_user"."is_superuser", "auths_user"."username", "auths_user"."first_name", "auths_user"."last_name", "auths_user"."email", "auths_user"."is_staff", "auths_user"."is_active", "auths_user"."date_joined", "auths_user"."id", "auths_user"."last_hierarchy_id", "auths_user"."last_module_id", "auths_user"."person_id", "auths_user"."updated_at", "auths_user"."registered_by", "oauth2_provider_application"."id", "oauth2_provider_application"."client_id", "oauth2_provider_application"."user_id", "oauth2_provider_application"."redirect_uris", "oauth2_provider_application"."client_type", "oauth2_provider_application"."authorization_grant_type", "oauth2_provider_application"."client_secret", "oauth2_provider_application"."name", "oauth2_provider_application"."skip_authorization" FROM "oauth2_provider_accesstoken" LEFT OUTER JOIN "auths_user" ON ("oauth2_provider_accesstoken"."user_id" = "auths_user"."id") INNER JOIN "oauth2_provider_application" ON ("oauth2_provider_accesstoken"."application_id" = "oauth2_provider_application"."id") WHERE "oauth2_provider_accesstoken"."token" = 'MPAbusN6LfH2ZfL37brKEpT0lU89rc'; args=('MPAbusN6LfH2ZfL37brKEpT0lU89rc',)
[2016-11-16 15:31:29] DEBUG [django.db.backends:90] (0.000) SELECT "catalogo_categoria"."id", "catalogo_categoria"."nombre", "catalogo_categoria"."codigo", "catalogo_categoria"."estado" FROM "catalogo_categoria" WHERE ("catalogo_categoria"."codigo" LIKE '%%' ESCAPE '\' OR "catalogo_categoria"."nombre" LIKE '%%' ESCAPE '\'); args=('%%', '%%')
[2016-11-16 15:31:29] INFO [django.server:131] "GET /api/catalogo/categorias/ HTTP/1.1" 200 199
[2016-11-16 15:31:50] DEBUG [django.db.backends:90] (0.004) 
            SELECT name, type FROM sqlite_master
            WHERE type in ('table', 'view') AND NOT name='sqlite_sequence'
            ORDER BY name; args=None
[2016-11-16 15:31:50] DEBUG [django.db.backends:90] (0.001) SELECT "django_migrations"."app", "django_migrations"."name" FROM "django_migrations"; args=()
[2016-11-16 21:35:05] DEBUG [django.db.backends:90] (0.005) 
            SELECT name, type FROM sqlite_master
            WHERE type in ('table', 'view') AND NOT name='sqlite_sequence'
            ORDER BY name; args=None
[2016-11-16 21:35:05] DEBUG [django.db.backends:90] (0.000) SELECT "django_migrations"."app", "django_migrations"."name" FROM "django_migrations"; args=()
[2016-11-16 21:35:05] INFO [django.server:131] "OPTIONS /api/auths/localuserinfo/ HTTP/1.1" 200 0
[2016-11-16 21:35:05] INFO [django.server:131] "OPTIONS /api/catalogo/categorias/ HTTP/1.1" 200 0
[2016-11-16 21:35:05] INFO [django.server:131] "OPTIONS /api/auths/usermenu/ HTTP/1.1" 200 0
[2016-11-16 21:35:05] DEBUG [django.db.backends:90] (0.013) SELECT "oauth2_provider_accesstoken"."id", "oauth2_provider_accesstoken"."user_id", "oauth2_provider_accesstoken"."token", "oauth2_provider_accesstoken"."application_id", "oauth2_provider_accesstoken"."expires", "oauth2_provider_accesstoken"."scope", "auths_user"."password", "auths_user"."last_login", "auths_user"."is_superuser", "auths_user"."username", "auths_user"."first_name", "auths_user"."last_name", "auths_user"."email", "auths_user"."is_staff", "auths_user"."is_active", "auths_user"."date_joined", "auths_user"."id", "auths_user"."last_hierarchy_id", "auths_user"."last_module_id", "auths_user"."person_id", "auths_user"."updated_at", "auths_user"."registered_by", "oauth2_provider_application"."id", "oauth2_provider_application"."client_id", "oauth2_provider_application"."user_id", "oauth2_provider_application"."redirect_uris", "oauth2_provider_application"."client_type", "oauth2_provider_application"."authorization_grant_type", "oauth2_provider_application"."client_secret", "oauth2_provider_application"."name", "oauth2_provider_application"."skip_authorization" FROM "oauth2_provider_accesstoken" LEFT OUTER JOIN "auths_user" ON ("oauth2_provider_accesstoken"."user_id" = "auths_user"."id") INNER JOIN "oauth2_provider_application" ON ("oauth2_provider_accesstoken"."application_id" = "oauth2_provider_application"."id") WHERE "oauth2_provider_accesstoken"."token" = 'MPAbusN6LfH2ZfL37brKEpT0lU89rc'; args=('MPAbusN6LfH2ZfL37brKEpT0lU89rc',)
[2016-11-16 21:35:05] DEBUG [django.db.backends:90] (0.006) SELECT "oauth2_provider_accesstoken"."id", "oauth2_provider_accesstoken"."user_id", "oauth2_provider_accesstoken"."token", "oauth2_provider_accesstoken"."application_id", "oauth2_provider_accesstoken"."expires", "oauth2_provider_accesstoken"."scope", "auths_user"."password", "auths_user"."last_login", "auths_user"."is_superuser", "auths_user"."username", "auths_user"."first_name", "auths_user"."last_name", "auths_user"."email", "auths_user"."is_staff", "auths_user"."is_active", "auths_user"."date_joined", "auths_user"."id", "auths_user"."last_hierarchy_id", "auths_user"."last_module_id", "auths_user"."person_id", "auths_user"."updated_at", "auths_user"."registered_by", "oauth2_provider_application"."id", "oauth2_provider_application"."client_id", "oauth2_provider_application"."user_id", "oauth2_provider_application"."redirect_uris", "oauth2_provider_application"."client_type", "oauth2_provider_application"."authorization_grant_type", "oauth2_provider_application"."client_secret", "oauth2_provider_application"."name", "oauth2_provider_application"."skip_authorization" FROM "oauth2_provider_accesstoken" LEFT OUTER JOIN "auths_user" ON ("oauth2_provider_accesstoken"."user_id" = "auths_user"."id") INNER JOIN "oauth2_provider_application" ON ("oauth2_provider_accesstoken"."application_id" = "oauth2_provider_application"."id") WHERE "oauth2_provider_accesstoken"."token" = 'MPAbusN6LfH2ZfL37brKEpT0lU89rc'; args=('MPAbusN6LfH2ZfL37brKEpT0lU89rc',)
[2016-11-16 21:35:05] DEBUG [django.db.backends:90] (0.000) SELECT "catalogo_categoria"."id", "catalogo_categoria"."nombre", "catalogo_categoria"."codigo", "catalogo_categoria"."estado" FROM "catalogo_categoria" WHERE ("catalogo_categoria"."codigo" LIKE '%%' ESCAPE '\' OR "catalogo_categoria"."nombre" LIKE '%%' ESCAPE '\'); args=('%%', '%%')
[2016-11-16 21:35:05] DEBUG [django.db.backends:90] (0.019) SELECT "oauth2_provider_accesstoken"."id", "oauth2_provider_accesstoken"."user_id", "oauth2_provider_accesstoken"."token", "oauth2_provider_accesstoken"."application_id", "oauth2_provider_accesstoken"."expires", "oauth2_provider_accesstoken"."scope", "auths_user"."password", "auths_user"."last_login", "auths_user"."is_superuser", "auths_user"."username", "auths_user"."first_name", "auths_user"."last_name", "auths_user"."email", "auths_user"."is_staff", "auths_user"."is_active", "auths_user"."date_joined", "auths_user"."id", "auths_user"."last_hierarchy_id", "auths_user"."last_module_id", "auths_user"."person_id", "auths_user"."updated_at", "auths_user"."registered_by", "oauth2_provider_application"."id", "oauth2_provider_application"."client_id", "oauth2_provider_application"."user_id", "oauth2_provider_application"."redirect_uris", "oauth2_provider_application"."client_type", "oauth2_provider_application"."authorization_grant_type", "oauth2_provider_application"."client_secret", "oauth2_provider_application"."name", "oauth2_provider_application"."skip_authorization" FROM "oauth2_provider_accesstoken" LEFT OUTER JOIN "auths_user" ON ("oauth2_provider_accesstoken"."user_id" = "auths_user"."id") INNER JOIN "oauth2_provider_application" ON ("oauth2_provider_accesstoken"."application_id" = "oauth2_provider_application"."id") WHERE "oauth2_provider_accesstoken"."token" = 'MPAbusN6LfH2ZfL37brKEpT0lU89rc'; args=('MPAbusN6LfH2ZfL37brKEpT0lU89rc',)
[2016-11-16 21:35:05] INFO [django.server:131] "GET /api/catalogo/categorias/ HTTP/1.1" 200 199
[2016-11-16 21:35:05] DEBUG [django.db.backends:90] (0.001) SELECT "auth_group"."id", "auth_group"."name" FROM "auth_group" INNER JOIN "auths_user_groups" ON ("auth_group"."id" = "auths_user_groups"."group_id") WHERE "auths_user_groups"."user_id" = '3651942c1384420da02bbf9e5eca3faa'; args=('3651942c1384420da02bbf9e5eca3faa',)
[2016-11-16 21:35:05] DEBUG [django.db.backends:90] (0.001) SELECT "auths_menu"."id" FROM "auths_menu" WHERE ("auths_menu"."id" IS NOT NULL AND "auths_menu"."module" = 'BACKEND' AND "auths_menu"."is_active" = 1) ORDER BY "auths_menu"."pos" ASC; args=('BACKEND', True)
[2016-11-16 21:35:05] DEBUG [django.db.backends:90] (0.011) SELECT "auth_permission"."id", "auth_permission"."name", "auth_permission"."content_type_id", "auth_permission"."codename" FROM "auth_permission" INNER JOIN "auths_user_user_permissions" ON ("auth_permission"."id" = "auths_user_user_permissions"."permission_id") INNER JOIN "django_content_type" ON ("auth_permission"."content_type_id" = "django_content_type"."id") WHERE "auths_user_user_permissions"."user_id" = '3651942c1384420da02bbf9e5eca3faa' ORDER BY "django_content_type"."app_label" ASC, "django_content_type"."model" ASC, "auth_permission"."codename" ASC; args=('3651942c1384420da02bbf9e5eca3faa',)
[2016-11-16 21:35:05] INFO [django.server:131] "GET /api/auths/localuserinfo/ HTTP/1.1" 200 496
[2016-11-16 21:35:05] DEBUG [django.db.backends:90] (0.001) SELECT (1) AS "a" FROM "django_session" WHERE "django_session"."session_key" = 'k06n4kzb9js1ll0ah8ljxeadbpdrv2kh' LIMIT 1; args=('k06n4kzb9js1ll0ah8ljxeadbpdrv2kh',)
[2016-11-16 21:35:05] DEBUG [django.db.backends:90] (0.000) BEGIN; args=None
[2016-11-16 21:35:05] DEBUG [django.db.backends:90] (0.002) INSERT INTO "django_session" ("session_key", "session_data", "expire_date") SELECT 'k06n4kzb9js1ll0ah8ljxeadbpdrv2kh', 'NmE3M2Q3NmYwOTU3YjJmZDBjYmQxYTVjODc5MTExNzM3NjY1YzYzNzp7Il9zZXNzaW9uX2V4cGlyeSI6MzB9', '2016-11-17 02:35:35.545572'; args=('k06n4kzb9js1ll0ah8ljxeadbpdrv2kh', 'NmE3M2Q3NmYwOTU3YjJmZDBjYmQxYTVjODc5MTExNzM3NjY1YzYzNzp7Il9zZXNzaW9uX2V4cGlyeSI6MzB9', '2016-11-17 02:35:35.545572')
[2016-11-16 21:35:05] INFO [django.server:131] "GET /api/auths/usermenu/ HTTP/1.1" 200 11
[2016-11-16 22:21:42] DEBUG [django.db.backends:90] (0.005) SELECT "oauth2_provider_accesstoken"."id", "oauth2_provider_accesstoken"."user_id", "oauth2_provider_accesstoken"."token", "oauth2_provider_accesstoken"."application_id", "oauth2_provider_accesstoken"."expires", "oauth2_provider_accesstoken"."scope", "auths_user"."password", "auths_user"."last_login", "auths_user"."is_superuser", "auths_user"."username", "auths_user"."first_name", "auths_user"."last_name", "auths_user"."email", "auths_user"."is_staff", "auths_user"."is_active", "auths_user"."date_joined", "auths_user"."id", "auths_user"."last_hierarchy_id", "auths_user"."last_module_id", "auths_user"."person_id", "auths_user"."updated_at", "auths_user"."registered_by", "oauth2_provider_application"."id", "oauth2_provider_application"."client_id", "oauth2_provider_application"."user_id", "oauth2_provider_application"."redirect_uris", "oauth2_provider_application"."client_type", "oauth2_provider_application"."authorization_grant_type", "oauth2_provider_application"."client_secret", "oauth2_provider_application"."name", "oauth2_provider_application"."skip_authorization" FROM "oauth2_provider_accesstoken" LEFT OUTER JOIN "auths_user" ON ("oauth2_provider_accesstoken"."user_id" = "auths_user"."id") INNER JOIN "oauth2_provider_application" ON ("oauth2_provider_accesstoken"."application_id" = "oauth2_provider_application"."id") WHERE "oauth2_provider_accesstoken"."token" = 'MPAbusN6LfH2ZfL37brKEpT0lU89rc'; args=('MPAbusN6LfH2ZfL37brKEpT0lU89rc',)
[2016-11-16 22:21:42] DEBUG [django.db.backends:90] (0.004) SELECT "oauth2_provider_accesstoken"."id", "oauth2_provider_accesstoken"."user_id", "oauth2_provider_accesstoken"."token", "oauth2_provider_accesstoken"."application_id", "oauth2_provider_accesstoken"."expires", "oauth2_provider_accesstoken"."scope", "auths_user"."password", "auths_user"."last_login", "auths_user"."is_superuser", "auths_user"."username", "auths_user"."first_name", "auths_user"."last_name", "auths_user"."email", "auths_user"."is_staff", "auths_user"."is_active", "auths_user"."date_joined", "auths_user"."id", "auths_user"."last_hierarchy_id", "auths_user"."last_module_id", "auths_user"."person_id", "auths_user"."updated_at", "auths_user"."registered_by", "oauth2_provider_application"."id", "oauth2_provider_application"."client_id", "oauth2_provider_application"."user_id", "oauth2_provider_application"."redirect_uris", "oauth2_provider_application"."client_type", "oauth2_provider_application"."authorization_grant_type", "oauth2_provider_application"."client_secret", "oauth2_provider_application"."name", "oauth2_provider_application"."skip_authorization" FROM "oauth2_provider_accesstoken" LEFT OUTER JOIN "auths_user" ON ("oauth2_provider_accesstoken"."user_id" = "auths_user"."id") INNER JOIN "oauth2_provider_application" ON ("oauth2_provider_accesstoken"."application_id" = "oauth2_provider_application"."id") WHERE "oauth2_provider_accesstoken"."token" = 'MPAbusN6LfH2ZfL37brKEpT0lU89rc'; args=('MPAbusN6LfH2ZfL37brKEpT0lU89rc',)
[2016-11-16 22:21:42] DEBUG [django.db.backends:90] (0.001) SELECT "auths_menu"."id" FROM "auths_menu" WHERE ("auths_menu"."id" IS NOT NULL AND "auths_menu"."module" = 'BACKEND' AND "auths_menu"."is_active" = 1) ORDER BY "auths_menu"."pos" ASC; args=('BACKEND', True)
[2016-11-16 22:21:42] DEBUG [django.db.backends:90] (0.000) SELECT (1) AS "a" FROM "django_session" WHERE "django_session"."session_key" = 'r0ppfszpd93xxm6od907wgotyxlwy25z' LIMIT 1; args=('r0ppfszpd93xxm6od907wgotyxlwy25z',)
[2016-11-16 22:21:42] DEBUG [django.db.backends:90] (0.000) BEGIN; args=None
[2016-11-16 22:21:42] DEBUG [django.db.backends:90] (0.003) INSERT INTO "django_session" ("session_key", "session_data", "expire_date") SELECT 'r0ppfszpd93xxm6od907wgotyxlwy25z', 'NmE3M2Q3NmYwOTU3YjJmZDBjYmQxYTVjODc5MTExNzM3NjY1YzYzNzp7Il9zZXNzaW9uX2V4cGlyeSI6MzB9', '2016-11-17 03:22:12.294413'; args=('r0ppfszpd93xxm6od907wgotyxlwy25z', 'NmE3M2Q3NmYwOTU3YjJmZDBjYmQxYTVjODc5MTExNzM3NjY1YzYzNzp7Il9zZXNzaW9uX2V4cGlyeSI6MzB9', '2016-11-17 03:22:12.294413')
[2016-11-16 22:21:42] INFO [django.server:131] "GET /api/auths/usermenu/ HTTP/1.1" 200 11
[2016-11-16 22:21:42] DEBUG [django.db.backends:90] (0.122) SELECT "auth_group"."id", "auth_group"."name" FROM "auth_group" INNER JOIN "auths_user_groups" ON ("auth_group"."id" = "auths_user_groups"."group_id") WHERE "auths_user_groups"."user_id" = '3651942c1384420da02bbf9e5eca3faa'; args=('3651942c1384420da02bbf9e5eca3faa',)
[2016-11-16 22:21:42] DEBUG [django.db.backends:90] (0.001) SELECT "auth_permission"."id", "auth_permission"."name", "auth_permission"."content_type_id", "auth_permission"."codename" FROM "auth_permission" INNER JOIN "auths_user_user_permissions" ON ("auth_permission"."id" = "auths_user_user_permissions"."permission_id") INNER JOIN "django_content_type" ON ("auth_permission"."content_type_id" = "django_content_type"."id") WHERE "auths_user_user_permissions"."user_id" = '3651942c1384420da02bbf9e5eca3faa' ORDER BY "django_content_type"."app_label" ASC, "django_content_type"."model" ASC, "auth_permission"."codename" ASC; args=('3651942c1384420da02bbf9e5eca3faa',)
[2016-11-16 22:21:42] INFO [django.server:131] "GET /api/auths/localuserinfo/ HTTP/1.1" 200 496
[2016-11-16 22:21:42] DEBUG [django.db.backends:90] (0.004) SELECT "oauth2_provider_accesstoken"."id", "oauth2_provider_accesstoken"."user_id", "oauth2_provider_accesstoken"."token", "oauth2_provider_accesstoken"."application_id", "oauth2_provider_accesstoken"."expires", "oauth2_provider_accesstoken"."scope", "auths_user"."password", "auths_user"."last_login", "auths_user"."is_superuser", "auths_user"."username", "auths_user"."first_name", "auths_user"."last_name", "auths_user"."email", "auths_user"."is_staff", "auths_user"."is_active", "auths_user"."date_joined", "auths_user"."id", "auths_user"."last_hierarchy_id", "auths_user"."last_module_id", "auths_user"."person_id", "auths_user"."updated_at", "auths_user"."registered_by", "oauth2_provider_application"."id", "oauth2_provider_application"."client_id", "oauth2_provider_application"."user_id", "oauth2_provider_application"."redirect_uris", "oauth2_provider_application"."client_type", "oauth2_provider_application"."authorization_grant_type", "oauth2_provider_application"."client_secret", "oauth2_provider_application"."name", "oauth2_provider_application"."skip_authorization" FROM "oauth2_provider_accesstoken" LEFT OUTER JOIN "auths_user" ON ("oauth2_provider_accesstoken"."user_id" = "auths_user"."id") INNER JOIN "oauth2_provider_application" ON ("oauth2_provider_accesstoken"."application_id" = "oauth2_provider_application"."id") WHERE "oauth2_provider_accesstoken"."token" = 'MPAbusN6LfH2ZfL37brKEpT0lU89rc'; args=('MPAbusN6LfH2ZfL37brKEpT0lU89rc',)
[2016-11-16 22:21:42] DEBUG [django.db.backends:90] (0.000) SELECT "catalogo_categoria"."id", "catalogo_categoria"."nombre", "catalogo_categoria"."codigo", "catalogo_categoria"."estado" FROM "catalogo_categoria" WHERE ("catalogo_categoria"."codigo" LIKE '%%' ESCAPE '\' OR "catalogo_categoria"."nombre" LIKE '%%' ESCAPE '\'); args=('%%', '%%')
[2016-11-16 22:21:42] INFO [django.server:131] "GET /api/catalogo/categorias/ HTTP/1.1" 200 199
