[2016-11-15 16:37:59] DEBUG [django.db.backends:90] (0.000) 
            SELECT name, type FROM sqlite_master
            WHERE type in ('table', 'view') AND NOT name='sqlite_sequence'
            ORDER BY name; args=None
[2016-11-15 16:37:59] DEBUG [django.db.backends:90] (0.000) SELECT "django_migrations"."app", "django_migrations"."name" FROM "django_migrations"; args=()
[2016-11-15 16:39:00] DEBUG [django.db.backends:90] (0.233) SELECT "django_session"."session_key", "django_session"."session_data", "django_session"."expire_date" FROM "django_session" WHERE ("django_session"."session_key" = '4w7mksqqsrmucukumcpvs4jbtn8vd4qw' AND "django_session"."expire_date" > '2016-11-15 21:38:59.932204'); args=('4w7mksqqsrmucukumcpvs4jbtn8vd4qw', '2016-11-15 21:38:59.932204')
[2016-11-15 16:39:00] DEBUG [django.db.backends:90] (0.001) SELECT "auths_user"."password", "auths_user"."last_login", "auths_user"."is_superuser", "auths_user"."username", "auths_user"."first_name", "auths_user"."last_name", "auths_user"."email", "auths_user"."is_staff", "auths_user"."is_active", "auths_user"."date_joined", "auths_user"."id", "auths_user"."last_hierarchy_id", "auths_user"."last_module_id", "auths_user"."person_id", "auths_user"."updated_at", "auths_user"."registered_by" FROM "auths_user" WHERE "auths_user"."id" = '3651942c1384420da02bbf9e5eca3faa'; args=('3651942c1384420da02bbf9e5eca3faa',)
[2016-11-15 16:39:01] DEBUG [django.template:929] Exception while resolving variable 'is_popup' in template 'admin/index.html'.
Traceback (most recent call last):
  File "C:\Users\pc\AppData\Local\Programs\Python\Python35-32\lib\site-packages\django\template\base.py", line 885, in _resolve_lookup
    current = current[bit]
  File "C:\Users\pc\AppData\Local\Programs\Python\Python35-32\lib\site-packages\django\template\context.py", line 75, in __getitem__
    raise KeyError(key)
KeyError: 'is_popup'

During handling of the above exception, another exception occurred:

Traceback (most recent call last):
  File "C:\Users\pc\AppData\Local\Programs\Python\Python35-32\lib\site-packages\django\template\base.py", line 891, in _resolve_lookup
    if isinstance(current, BaseContext) and getattr(type(current), bit):
AttributeError: type object 'RequestContext' has no attribute 'is_popup'

During handling of the above exception, another exception occurred:

Traceback (most recent call last):
  File "C:\Users\pc\AppData\Local\Programs\Python\Python35-32\lib\site-packages\django\template\base.py", line 900, in _resolve_lookup
    current = current[int(bit)]
ValueError: invalid literal for int() with base 10: 'is_popup'

During handling of the above exception, another exception occurred:

Traceback (most recent call last):
  File "C:\Users\pc\AppData\Local\Programs\Python\Python35-32\lib\site-packages\django\template\base.py", line 907, in _resolve_lookup
    (bit, current))  # missing attribute
django.template.base.VariableDoesNotExist: Failed lookup for key [is_popup] in "[{'True': True, 'None': None, 'False': False}, {'messages': <django.contrib.messages.storage.fallback.FallbackStorage object at 0x0411EEF0>, 'user': <SimpleLazyObject: <User: admin>>, 'perms': <django.contrib.auth.context_processors.PermWrapper object at 0x00C5B5D0>, 'csrf_token': <SimpleLazyObject: <function csrf.<locals>._get_val at 0x042108A0>>, 'DEFAULT_MESSAGE_LEVELS': {'WARNING': 30, 'ERROR': 40, 'SUCCESS': 25, 'INFO': 20, 'DEBUG': 10}, 'request': <WSGIRequest: GET '/admin/'>}, {}, {'LANGUAGE_BIDI': False, 'LANGUAGE_CODE': 'en-us', 'title': <django.utils.functional.lazy.<locals>.__proxy__ object at 0x034F2A30>, 'app_list': [{'models': [{'admin_url': '/admin/auth/group/', 'object_name': 'Group', 'perms': {'delete': True, 'add': True, 'change': True}, 'add_url': '/admin/auth/group/add/', 'name': <django.utils.functional.lazy.<locals>.__proxy__ object at 0x001C18F0>}, {'admin_url': '/admin/auth/permission/', 'object_name': 'Permission', 'perms': {'delete': True, 'add': True, 'change': True}, 'add_url': '/admin/auth/permission/add/', 'name': <django.utils.functional.lazy.<locals>.__proxy__ object at 0x001E9DD0>}], 'has_module_perms': True, 'app_label': 'auth', 'app_url': '/admin/auth/', 'name': <django.utils.functional.lazy.<locals>.__proxy__ object at 0x0350D610>}, {'models': [{'admin_url': '/admin/auths/hierarchytype/', 'object_name': 'HierarchyType', 'perms': {'delete': True, 'add': True, 'change': True}, 'add_url': '/admin/auths/hierarchytype/add/', 'name': <django.utils.functional.lazy.<locals>.__proxy__ object at 0x001E9F10>}, {'admin_url': '/admin/auths/hierarchy/', 'object_name': 'Hierarchy', 'perms': {'delete': True, 'add': True, 'change': True}, 'add_url': '/admin/auths/hierarchy/add/', 'name': <django.utils.functional.lazy.<locals>.__proxy__ object at 0x001C1590>}, {'admin_url': '/admin/auths/menu/', 'object_name': 'Menu', 'perms': {'delete': True, 'add': True, 'change': True}, 'add_url': '/admin/auths/menu/add/', 'name': <django.utils.functional.lazy.<locals>.__proxy__ object at 0x001C1F70>}, {'admin_url': '/admin/auths/person/', 'object_name': 'Person', 'perms': {'delete': True, 'add': True, 'change': True}, 'add_url': '/admin/auths/person/add/', 'name': <django.utils.functional.lazy.<locals>.__proxy__ object at 0x001E9FF0>}, {'admin_url': '/admin/auths/userhierarchygroup/', 'object_name': 'UserHierarchyGroup', 'perms': {'delete': True, 'add': True, 'change': True}, 'add_url': '/admin/auths/userhierarchygroup/add/', 'name': <django.utils.functional.lazy.<locals>.__proxy__ object at 0x001E9F30>}, {'admin_url': '/admin/auths/userhierarchypermission/', 'object_name': 'UserHierarchyPermission', 'perms': {'delete': True, 'add': True, 'change': True}, 'add_url': '/admin/auths/userhierarchypermission/add/', 'name': <django.utils.functional.lazy.<locals>.__proxy__ object at 0x001E9850>}, {'admin_url': '/admin/auths/user/', 'object_name': 'User', 'perms': {'delete': True, 'add': True, 'change': True}, 'add_url': '/admin/auths/user/add/', 'name': <django.utils.functional.lazy.<locals>.__proxy__ object at 0x001E9BF0>}], 'has_module_perms': True, 'app_label': 'auths', 'app_url': '/admin/auths/', 'name': 'Auths'}, {'models': [{'admin_url': '/admin/catalogo/autor/', 'object_name': 'Autor', 'perms': {'delete': True, 'add': True, 'change': True}, 'add_url': '/admin/catalogo/autor/add/', 'name': 'Autores'}, {'admin_url': '/admin/catalogo/categoria/', 'object_name': 'Categoria', 'perms': {'delete': True, 'add': True, 'change': True}, 'add_url': '/admin/catalogo/categoria/add/', 'name': 'Categorias'}, {'admin_url': '/admin/catalogo/libro/', 'object_name': 'Libro', 'perms': {'delete': True, 'add': True, 'change': True}, 'add_url': '/admin/catalogo/libro/add/', 'name': 'Libros'}], 'has_module_perms': True, 'app_label': 'catalogo', 'app_url': '/admin/catalogo/', 'name': 'Catalogo'}, {'models': [{'admin_url': '/admin/contenttypes/contenttype/', 'object_name': 'ContentType', 'perms': {'delete': True, 'add': True, 'change': True}, 'add_url': '/admin/contenttypes/contenttype/add/', 'name': <django.utils.functional.lazy.<locals>.__proxy__ object at 0x001E99D0>}], 'has_module_perms': True, 'app_label': 'contenttypes', 'app_url': '/admin/contenttypes/', 'name': <django.utils.functional.lazy.<locals>.__proxy__ object at 0x0350D550>}, {'models': [{'admin_url': '/admin/oauth2_provider/accesstoken/', 'object_name': 'AccessToken', 'perms': {'delete': True, 'add': True, 'change': True}, 'add_url': '/admin/oauth2_provider/accesstoken/add/', 'name': <django.utils.functional.lazy.<locals>.__proxy__ object at 0x001E9B30>}, {'admin_url': '/admin/oauth2_provider/application/', 'object_name': 'Application', 'perms': {'delete': True, 'add': True, 'change': True}, 'add_url': '/admin/oauth2_provider/application/add/', 'name': <django.utils.functional.lazy.<locals>.__proxy__ object at 0x001E9E10>}, {'admin_url': '/admin/oauth2_provider/grant/', 'object_name': 'Grant', 'perms': {'delete': True, 'add': True, 'change': True}, 'add_url': '/admin/oauth2_provider/grant/add/', 'name': <django.utils.functional.lazy.<locals>.__proxy__ object at 0x001E9EF0>}, {'admin_url': '/admin/oauth2_provider/refreshtoken/', 'object_name': 'RefreshToken', 'perms': {'delete': True, 'add': True, 'change': True}, 'add_url': '/admin/oauth2_provider/refreshtoken/add/', 'name': <django.utils.functional.lazy.<locals>.__proxy__ object at 0x001C1ED0>}], 'has_module_perms': True, 'app_label': 'oauth2_provider', 'app_url': '/admin/oauth2_provider/', 'name': 'Django OAuth Toolkit'}], 'site_title': <django.utils.functional.lazy.<locals>.__proxy__ object at 0x03480F10>, 'site_url': '/', 'has_permission': True, 'site_header': <django.utils.functional.lazy.<locals>.__proxy__ object at 0x034F29D0>, 'available_apps': [{'models': [{'admin_url': '/admin/auth/group/', 'object_name': 'Group', 'perms': {'delete': True, 'add': True, 'change': True}, 'add_url': '/admin/auth/group/add/', 'name': <django.utils.functional.lazy.<locals>.__proxy__ object at 0x001E97B0>}, {'admin_url': '/admin/auth/permission/', 'object_name': 'Permission', 'perms': {'delete': True, 'add': True, 'change': True}, 'add_url': '/admin/auth/permission/add/', 'name': <django.utils.functional.lazy.<locals>.__proxy__ object at 0x00C080F0>}], 'has_module_perms': True, 'app_label': 'auth', 'app_url': '/admin/auth/', 'name': <django.utils.functional.lazy.<locals>.__proxy__ object at 0x0350D610>}, {'models': [{'admin_url': '/admin/auths/hierarchytype/', 'object_name': 'HierarchyType', 'perms': {'delete': True, 'add': True, 'change': True}, 'add_url': '/admin/auths/hierarchytype/add/', 'name': <django.utils.functional.lazy.<locals>.__proxy__ object at 0x001E9D90>}, {'admin_url': '/admin/auths/hierarchy/', 'object_name': 'Hierarchy', 'perms': {'delete': True, 'add': True, 'change': True}, 'add_url': '/admin/auths/hierarchy/add/', 'name': <django.utils.functional.lazy.<locals>.__proxy__ object at 0x001E9D50>}, {'admin_url': '/admin/auths/menu/', 'object_name': 'Menu', 'perms': {'delete': True, 'add': True, 'change': True}, 'add_url': '/admin/auths/menu/add/', 'name': <django.utils.functional.lazy.<locals>.__proxy__ object at 0x001E9F50>}, {'admin_url': '/admin/auths/person/', 'object_name': 'Person', 'perms': {'delete': True, 'add': True, 'change': True}, 'add_url': '/admin/auths/person/add/', 'name': <django.utils.functional.lazy.<locals>.__proxy__ object at 0x00C08310>}, {'admin_url': '/admin/auths/userhierarchygroup/', 'object_name': 'UserHierarchyGroup', 'perms': {'delete': True, 'add': True, 'change': True}, 'add_url': '/admin/auths/userhierarchygroup/add/', 'name': <django.utils.functional.lazy.<locals>.__proxy__ object at 0x00C08250>}, {'admin_url': '/admin/auths/userhierarchypermission/', 'object_name': 'UserHierarchyPermission', 'perms': {'delete': True, 'add': True, 'change': True}, 'add_url': '/admin/auths/userhierarchypermission/add/', 'name': <django.utils.functional.lazy.<locals>.__proxy__ object at 0x001E9D70>}, {'admin_url': '/admin/auths/user/', 'object_name': 'User', 'perms': {'delete': True, 'add': True, 'change': True}, 'add_url': '/admin/auths/user/add/', 'name': <django.utils.functional.lazy.<locals>.__proxy__ object at 0x00C08170>}], 'has_module_perms': True, 'app_label': 'auths', 'app_url': '/admin/auths/', 'name': 'Auths'}, {'models': [{'admin_url': '/admin/catalogo/autor/', 'object_name': 'Autor', 'perms': {'delete': True, 'add': True, 'change': True}, 'add_url': '/admin/catalogo/autor/add/', 'name': 'Autores'}, {'admin_url': '/admin/catalogo/categoria/', 'object_name': 'Categoria', 'perms': {'delete': True, 'add': True, 'change': True}, 'add_url': '/admin/catalogo/categoria/add/', 'name': 'Categorias'}, {'admin_url': '/admin/catalogo/libro/', 'object_name': 'Libro', 'perms': {'delete': True, 'add': True, 'change': True}, 'add_url': '/admin/catalogo/libro/add/', 'name': 'Libros'}], 'has_module_perms': True, 'app_label': 'catalogo', 'app_url': '/admin/catalogo/', 'name': 'Catalogo'}, {'models': [{'admin_url': '/admin/contenttypes/contenttype/', 'object_name': 'ContentType', 'perms': {'delete': True, 'add': True, 'change': True}, 'add_url': '/admin/contenttypes/contenttype/add/', 'name': <django.utils.functional.lazy.<locals>.__proxy__ object at 0x00C08AD0>}], 'has_module_perms': True, 'app_label': 'contenttypes', 'app_url': '/admin/contenttypes/', 'name': <django.utils.functional.lazy.<locals>.__proxy__ object at 0x0350D550>}, {'models': [{'admin_url': '/admin/oauth2_provider/accesstoken/', 'object_name': 'AccessToken', 'perms': {'delete': True, 'add': True, 'change': True}, 'add_url': '/admin/oauth2_provider/accesstoken/add/', 'name': <django.utils.functional.lazy.<locals>.__proxy__ object at 0x00C084B0>}, {'admin_url': '/admin/oauth2_provider/application/', 'object_name': 'Application', 'perms': {'delete': True, 'add': True, 'change': True}, 'add_url': '/admin/oauth2_provider/application/add/', 'name': <django.utils.functional.lazy.<locals>.__proxy__ object at 0x001E9B50>}, {'admin_url': '/admin/oauth2_provider/grant/', 'object_name': 'Grant', 'perms': {'delete': True, 'add': True, 'change': True}, 'add_url': '/admin/oauth2_provider/grant/add/', 'name': <django.utils.functional.lazy.<locals>.__proxy__ object at 0x00C082D0>}, {'admin_url': '/admin/oauth2_provider/refreshtoken/', 'object_name': 'RefreshToken', 'perms': {'delete': True, 'add': True, 'change': True}, 'add_url': '/admin/oauth2_provider/refreshtoken/add/', 'name': <django.utils.functional.lazy.<locals>.__proxy__ object at 0x001E9ED0>}], 'has_module_perms': True, 'app_label': 'oauth2_provider', 'app_url': '/admin/oauth2_provider/', 'name': 'Django OAuth Toolkit'}]}]"
[2016-11-15 16:39:01] DEBUG [django.template:929] Exception while resolving variable 'is_popup' in template 'admin/index.html'.
Traceback (most recent call last):
  File "C:\Users\pc\AppData\Local\Programs\Python\Python35-32\lib\site-packages\django\template\base.py", line 885, in _resolve_lookup
    current = current[bit]
  File "C:\Users\pc\AppData\Local\Programs\Python\Python35-32\lib\site-packages\django\template\context.py", line 75, in __getitem__
    raise KeyError(key)
KeyError: 'is_popup'

During handling of the above exception, another exception occurred:

Traceback (most recent call last):
  File "C:\Users\pc\AppData\Local\Programs\Python\Python35-32\lib\site-packages\django\template\base.py", line 891, in _resolve_lookup
    if isinstance(current, BaseContext) and getattr(type(current), bit):
AttributeError: type object 'RequestContext' has no attribute 'is_popup'

During handling of the above exception, another exception occurred:

Traceback (most recent call last):
  File "C:\Users\pc\AppData\Local\Programs\Python\Python35-32\lib\site-packages\django\template\base.py", line 900, in _resolve_lookup
    current = current[int(bit)]
ValueError: invalid literal for int() with base 10: 'is_popup'

During handling of the above exception, another exception occurred:

Traceback (most recent call last):
  File "C:\Users\pc\AppData\Local\Programs\Python\Python35-32\lib\site-packages\django\template\base.py", line 907, in _resolve_lookup
    (bit, current))  # missing attribute
django.template.base.VariableDoesNotExist: Failed lookup for key [is_popup] in "[{'True': True, 'None': None, 'False': False}, {'messages': <django.contrib.messages.storage.fallback.FallbackStorage object at 0x0411EEF0>, 'user': <SimpleLazyObject: <User: admin>>, 'perms': <django.contrib.auth.context_processors.PermWrapper object at 0x00C5B5D0>, 'csrf_token': <SimpleLazyObject: <function csrf.<locals>._get_val at 0x042108A0>>, 'DEFAULT_MESSAGE_LEVELS': {'WARNING': 30, 'ERROR': 40, 'SUCCESS': 25, 'INFO': 20, 'DEBUG': 10}, 'request': <WSGIRequest: GET '/admin/'>}, {}, {'LANGUAGE_BIDI': False, 'LANGUAGE_CODE': 'en-us', 'title': <django.utils.functional.lazy.<locals>.__proxy__ object at 0x034F2A30>, 'app_list': [{'models': [{'admin_url': '/admin/auth/group/', 'object_name': 'Group', 'perms': {'delete': True, 'add': True, 'change': True}, 'add_url': '/admin/auth/group/add/', 'name': <django.utils.functional.lazy.<locals>.__proxy__ object at 0x001C18F0>}, {'admin_url': '/admin/auth/permission/', 'object_name': 'Permission', 'perms': {'delete': True, 'add': True, 'change': True}, 'add_url': '/admin/auth/permission/add/', 'name': <django.utils.functional.lazy.<locals>.__proxy__ object at 0x001E9DD0>}], 'has_module_perms': True, 'app_label': 'auth', 'app_url': '/admin/auth/', 'name': <django.utils.functional.lazy.<locals>.__proxy__ object at 0x0350D610>}, {'models': [{'admin_url': '/admin/auths/hierarchytype/', 'object_name': 'HierarchyType', 'perms': {'delete': True, 'add': True, 'change': True}, 'add_url': '/admin/auths/hierarchytype/add/', 'name': <django.utils.functional.lazy.<locals>.__proxy__ object at 0x001E9F10>}, {'admin_url': '/admin/auths/hierarchy/', 'object_name': 'Hierarchy', 'perms': {'delete': True, 'add': True, 'change': True}, 'add_url': '/admin/auths/hierarchy/add/', 'name': <django.utils.functional.lazy.<locals>.__proxy__ object at 0x001C1590>}, {'admin_url': '/admin/auths/menu/', 'object_name': 'Menu', 'perms': {'delete': True, 'add': True, 'change': True}, 'add_url': '/admin/auths/menu/add/', 'name': <django.utils.functional.lazy.<locals>.__proxy__ object at 0x001C1F70>}, {'admin_url': '/admin/auths/person/', 'object_name': 'Person', 'perms': {'delete': True, 'add': True, 'change': True}, 'add_url': '/admin/auths/person/add/', 'name': <django.utils.functional.lazy.<locals>.__proxy__ object at 0x001E9FF0>}, {'admin_url': '/admin/auths/userhierarchygroup/', 'object_name': 'UserHierarchyGroup', 'perms': {'delete': True, 'add': True, 'change': True}, 'add_url': '/admin/auths/userhierarchygroup/add/', 'name': <django.utils.functional.lazy.<locals>.__proxy__ object at 0x001E9F30>}, {'admin_url': '/admin/auths/userhierarchypermission/', 'object_name': 'UserHierarchyPermission', 'perms': {'delete': True, 'add': True, 'change': True}, 'add_url': '/admin/auths/userhierarchypermission/add/', 'name': <django.utils.functional.lazy.<locals>.__proxy__ object at 0x001E9850>}, {'admin_url': '/admin/auths/user/', 'object_name': 'User', 'perms': {'delete': True, 'add': True, 'change': True}, 'add_url': '/admin/auths/user/add/', 'name': <django.utils.functional.lazy.<locals>.__proxy__ object at 0x001E9BF0>}], 'has_module_perms': True, 'app_label': 'auths', 'app_url': '/admin/auths/', 'name': 'Auths'}, {'models': [{'admin_url': '/admin/catalogo/autor/', 'object_name': 'Autor', 'perms': {'delete': True, 'add': True, 'change': True}, 'add_url': '/admin/catalogo/autor/add/', 'name': 'Autores'}, {'admin_url': '/admin/catalogo/categoria/', 'object_name': 'Categoria', 'perms': {'delete': True, 'add': True, 'change': True}, 'add_url': '/admin/catalogo/categoria/add/', 'name': 'Categorias'}, {'admin_url': '/admin/catalogo/libro/', 'object_name': 'Libro', 'perms': {'delete': True, 'add': True, 'change': True}, 'add_url': '/admin/catalogo/libro/add/', 'name': 'Libros'}], 'has_module_perms': True, 'app_label': 'catalogo', 'app_url': '/admin/catalogo/', 'name': 'Catalogo'}, {'models': [{'admin_url': '/admin/contenttypes/contenttype/', 'object_name': 'ContentType', 'perms': {'delete': True, 'add': True, 'change': True}, 'add_url': '/admin/contenttypes/contenttype/add/', 'name': <django.utils.functional.lazy.<locals>.__proxy__ object at 0x001E99D0>}], 'has_module_perms': True, 'app_label': 'contenttypes', 'app_url': '/admin/contenttypes/', 'name': <django.utils.functional.lazy.<locals>.__proxy__ object at 0x0350D550>}, {'models': [{'admin_url': '/admin/oauth2_provider/accesstoken/', 'object_name': 'AccessToken', 'perms': {'delete': True, 'add': True, 'change': True}, 'add_url': '/admin/oauth2_provider/accesstoken/add/', 'name': <django.utils.functional.lazy.<locals>.__proxy__ object at 0x001E9B30>}, {'admin_url': '/admin/oauth2_provider/application/', 'object_name': 'Application', 'perms': {'delete': True, 'add': True, 'change': True}, 'add_url': '/admin/oauth2_provider/application/add/', 'name': <django.utils.functional.lazy.<locals>.__proxy__ object at 0x001E9E10>}, {'admin_url': '/admin/oauth2_provider/grant/', 'object_name': 'Grant', 'perms': {'delete': True, 'add': True, 'change': True}, 'add_url': '/admin/oauth2_provider/grant/add/', 'name': <django.utils.functional.lazy.<locals>.__proxy__ object at 0x001E9EF0>}, {'admin_url': '/admin/oauth2_provider/refreshtoken/', 'object_name': 'RefreshToken', 'perms': {'delete': True, 'add': True, 'change': True}, 'add_url': '/admin/oauth2_provider/refreshtoken/add/', 'name': <django.utils.functional.lazy.<locals>.__proxy__ object at 0x001C1ED0>}], 'has_module_perms': True, 'app_label': 'oauth2_provider', 'app_url': '/admin/oauth2_provider/', 'name': 'Django OAuth Toolkit'}], 'site_title': <django.utils.functional.lazy.<locals>.__proxy__ object at 0x03480F10>, 'site_url': '/', 'has_permission': True, 'site_header': <django.utils.functional.lazy.<locals>.__proxy__ object at 0x034F29D0>, 'available_apps': [{'models': [{'admin_url': '/admin/auth/group/', 'object_name': 'Group', 'perms': {'delete': True, 'add': True, 'change': True}, 'add_url': '/admin/auth/group/add/', 'name': <django.utils.functional.lazy.<locals>.__proxy__ object at 0x001E97B0>}, {'admin_url': '/admin/auth/permission/', 'object_name': 'Permission', 'perms': {'delete': True, 'add': True, 'change': True}, 'add_url': '/admin/auth/permission/add/', 'name': <django.utils.functional.lazy.<locals>.__proxy__ object at 0x00C080F0>}], 'has_module_perms': True, 'app_label': 'auth', 'app_url': '/admin/auth/', 'name': <django.utils.functional.lazy.<locals>.__proxy__ object at 0x0350D610>}, {'models': [{'admin_url': '/admin/auths/hierarchytype/', 'object_name': 'HierarchyType', 'perms': {'delete': True, 'add': True, 'change': True}, 'add_url': '/admin/auths/hierarchytype/add/', 'name': <django.utils.functional.lazy.<locals>.__proxy__ object at 0x001E9D90>}, {'admin_url': '/admin/auths/hierarchy/', 'object_name': 'Hierarchy', 'perms': {'delete': True, 'add': True, 'change': True}, 'add_url': '/admin/auths/hierarchy/add/', 'name': <django.utils.functional.lazy.<locals>.__proxy__ object at 0x001E9D50>}, {'admin_url': '/admin/auths/menu/', 'object_name': 'Menu', 'perms': {'delete': True, 'add': True, 'change': True}, 'add_url': '/admin/auths/menu/add/', 'name': <django.utils.functional.lazy.<locals>.__proxy__ object at 0x001E9F50>}, {'admin_url': '/admin/auths/person/', 'object_name': 'Person', 'perms': {'delete': True, 'add': True, 'change': True}, 'add_url': '/admin/auths/person/add/', 'name': <django.utils.functional.lazy.<locals>.__proxy__ object at 0x00C08310>}, {'admin_url': '/admin/auths/userhierarchygroup/', 'object_name': 'UserHierarchyGroup', 'perms': {'delete': True, 'add': True, 'change': True}, 'add_url': '/admin/auths/userhierarchygroup/add/', 'name': <django.utils.functional.lazy.<locals>.__proxy__ object at 0x00C08250>}, {'admin_url': '/admin/auths/userhierarchypermission/', 'object_name': 'UserHierarchyPermission', 'perms': {'delete': True, 'add': True, 'change': True}, 'add_url': '/admin/auths/userhierarchypermission/add/', 'name': <django.utils.functional.lazy.<locals>.__proxy__ object at 0x001E9D70>}, {'admin_url': '/admin/auths/user/', 'object_name': 'User', 'perms': {'delete': True, 'add': True, 'change': True}, 'add_url': '/admin/auths/user/add/', 'name': <django.utils.functional.lazy.<locals>.__proxy__ object at 0x00C08170>}], 'has_module_perms': True, 'app_label': 'auths', 'app_url': '/admin/auths/', 'name': 'Auths'}, {'models': [{'admin_url': '/admin/catalogo/autor/', 'object_name': 'Autor', 'perms': {'delete': True, 'add': True, 'change': True}, 'add_url': '/admin/catalogo/autor/add/', 'name': 'Autores'}, {'admin_url': '/admin/catalogo/categoria/', 'object_name': 'Categoria', 'perms': {'delete': True, 'add': True, 'change': True}, 'add_url': '/admin/catalogo/categoria/add/', 'name': 'Categorias'}, {'admin_url': '/admin/catalogo/libro/', 'object_name': 'Libro', 'perms': {'delete': True, 'add': True, 'change': True}, 'add_url': '/admin/catalogo/libro/add/', 'name': 'Libros'}], 'has_module_perms': True, 'app_label': 'catalogo', 'app_url': '/admin/catalogo/', 'name': 'Catalogo'}, {'models': [{'admin_url': '/admin/contenttypes/contenttype/', 'object_name': 'ContentType', 'perms': {'delete': True, 'add': True, 'change': True}, 'add_url': '/admin/contenttypes/contenttype/add/', 'name': <django.utils.functional.lazy.<locals>.__proxy__ object at 0x00C08AD0>}], 'has_module_perms': True, 'app_label': 'contenttypes', 'app_url': '/admin/contenttypes/', 'name': <django.utils.functional.lazy.<locals>.__proxy__ object at 0x0350D550>}, {'models': [{'admin_url': '/admin/oauth2_provider/accesstoken/', 'object_name': 'AccessToken', 'perms': {'delete': True, 'add': True, 'change': True}, 'add_url': '/admin/oauth2_provider/accesstoken/add/', 'name': <django.utils.functional.lazy.<locals>.__proxy__ object at 0x00C084B0>}, {'admin_url': '/admin/oauth2_provider/application/', 'object_name': 'Application', 'perms': {'delete': True, 'add': True, 'change': True}, 'add_url': '/admin/oauth2_provider/application/add/', 'name': <django.utils.functional.lazy.<locals>.__proxy__ object at 0x001E9B50>}, {'admin_url': '/admin/oauth2_provider/grant/', 'object_name': 'Grant', 'perms': {'delete': True, 'add': True, 'change': True}, 'add_url': '/admin/oauth2_provider/grant/add/', 'name': <django.utils.functional.lazy.<locals>.__proxy__ object at 0x00C082D0>}, {'admin_url': '/admin/oauth2_provider/refreshtoken/', 'object_name': 'RefreshToken', 'perms': {'delete': True, 'add': True, 'change': True}, 'add_url': '/admin/oauth2_provider/refreshtoken/add/', 'name': <django.utils.functional.lazy.<locals>.__proxy__ object at 0x001E9ED0>}], 'has_module_perms': True, 'app_label': 'oauth2_provider', 'app_url': '/admin/oauth2_provider/', 'name': 'Django OAuth Toolkit'}]}]"
[2016-11-15 16:39:02] DEBUG [django.db.backends:90] (0.015) SELECT "django_admin_log"."id", "django_admin_log"."action_time", "django_admin_log"."user_id", "django_admin_log"."content_type_id", "django_admin_log"."object_id", "django_admin_log"."object_repr", "django_admin_log"."action_flag", "django_admin_log"."change_message", "auths_user"."password", "auths_user"."last_login", "auths_user"."is_superuser", "auths_user"."username", "auths_user"."first_name", "auths_user"."last_name", "auths_user"."email", "auths_user"."is_staff", "auths_user"."is_active", "auths_user"."date_joined", "auths_user"."id", "auths_user"."last_hierarchy_id", "auths_user"."last_module_id", "auths_user"."person_id", "auths_user"."updated_at", "auths_user"."registered_by", "django_content_type"."id", "django_content_type"."app_label", "django_content_type"."model" FROM "django_admin_log" INNER JOIN "auths_user" ON ("django_admin_log"."user_id" = "auths_user"."id") LEFT OUTER JOIN "django_content_type" ON ("django_admin_log"."content_type_id" = "django_content_type"."id") WHERE "django_admin_log"."user_id" = '3651942c1384420da02bbf9e5eca3faa' ORDER BY "django_admin_log"."action_time" DESC LIMIT 10; args=('3651942c1384420da02bbf9e5eca3faa',)
[2016-11-15 16:39:02] INFO [django.server:131] "GET /admin/ HTTP/1.1" 200 10333
[2016-11-15 16:39:02] INFO [django.server:131] "OPTIONS /api/auths/localuserinfo/ HTTP/1.1" 200 0
[2016-11-15 16:39:02] INFO [django.server:131] "OPTIONS /api/auths/usermenu/ HTTP/1.1" 200 0
[2016-11-15 16:39:03] INFO [django.server:131] "GET /static/admin/css/base.css HTTP/1.1" 304 0
[2016-11-15 16:39:03] DEBUG [django.db.backends:90] (0.026) SELECT "oauth2_provider_accesstoken"."id", "oauth2_provider_accesstoken"."user_id", "oauth2_provider_accesstoken"."token", "oauth2_provider_accesstoken"."application_id", "oauth2_provider_accesstoken"."expires", "oauth2_provider_accesstoken"."scope", "auths_user"."password", "auths_user"."last_login", "auths_user"."is_superuser", "auths_user"."username", "auths_user"."first_name", "auths_user"."last_name", "auths_user"."email", "auths_user"."is_staff", "auths_user"."is_active", "auths_user"."date_joined", "auths_user"."id", "auths_user"."last_hierarchy_id", "auths_user"."last_module_id", "auths_user"."person_id", "auths_user"."updated_at", "auths_user"."registered_by", "oauth2_provider_application"."id", "oauth2_provider_application"."client_id", "oauth2_provider_application"."user_id", "oauth2_provider_application"."redirect_uris", "oauth2_provider_application"."client_type", "oauth2_provider_application"."authorization_grant_type", "oauth2_provider_application"."client_secret", "oauth2_provider_application"."name", "oauth2_provider_application"."skip_authorization" FROM "oauth2_provider_accesstoken" LEFT OUTER JOIN "auths_user" ON ("oauth2_provider_accesstoken"."user_id" = "auths_user"."id") INNER JOIN "oauth2_provider_application" ON ("oauth2_provider_accesstoken"."application_id" = "oauth2_provider_application"."id") WHERE "oauth2_provider_accesstoken"."token" = 'Fbx5Y6uC4VBujcRlninwfby0OI1UqM'; args=('Fbx5Y6uC4VBujcRlninwfby0OI1UqM',)
[2016-11-15 16:39:03] WARNING [django.server:131] "GET /api/auths/localuserinfo/ HTTP/1.1" 401 58
[2016-11-15 16:39:03] INFO [django.server:131] "GET /static/admin/css/dashboard.css HTTP/1.1" 304 0
[2016-11-15 16:39:03] DEBUG [django.db.backends:90] (0.005) SELECT "oauth2_provider_accesstoken"."id", "oauth2_provider_accesstoken"."user_id", "oauth2_provider_accesstoken"."token", "oauth2_provider_accesstoken"."application_id", "oauth2_provider_accesstoken"."expires", "oauth2_provider_accesstoken"."scope", "auths_user"."password", "auths_user"."last_login", "auths_user"."is_superuser", "auths_user"."username", "auths_user"."first_name", "auths_user"."last_name", "auths_user"."email", "auths_user"."is_staff", "auths_user"."is_active", "auths_user"."date_joined", "auths_user"."id", "auths_user"."last_hierarchy_id", "auths_user"."last_module_id", "auths_user"."person_id", "auths_user"."updated_at", "auths_user"."registered_by", "oauth2_provider_application"."id", "oauth2_provider_application"."client_id", "oauth2_provider_application"."user_id", "oauth2_provider_application"."redirect_uris", "oauth2_provider_application"."client_type", "oauth2_provider_application"."authorization_grant_type", "oauth2_provider_application"."client_secret", "oauth2_provider_application"."name", "oauth2_provider_application"."skip_authorization" FROM "oauth2_provider_accesstoken" LEFT OUTER JOIN "auths_user" ON ("oauth2_provider_accesstoken"."user_id" = "auths_user"."id") INNER JOIN "oauth2_provider_application" ON ("oauth2_provider_accesstoken"."application_id" = "oauth2_provider_application"."id") WHERE "oauth2_provider_accesstoken"."token" = 'Fbx5Y6uC4VBujcRlninwfby0OI1UqM'; args=('Fbx5Y6uC4VBujcRlninwfby0OI1UqM',)
[2016-11-15 16:39:03] WARNING [django.server:131] "GET /api/auths/usermenu/ HTTP/1.1" 401 58
[2016-11-15 16:39:03] INFO [django.server:131] "GET /static/admin/css/fonts.css HTTP/1.1" 304 0
[2016-11-15 16:39:03] ERROR [django.server:131] "GET /api/auths/usermenu/ HTTP/1.1" 500 59
[2016-11-15 16:39:05] INFO [django.server:131] "GET /static/admin/img/icon-addlink.svg HTTP/1.1" 304 0
[2016-11-15 16:39:05] INFO [django.server:131] "GET /static/admin/img/icon-changelink.svg HTTP/1.1" 304 0
[2016-11-15 16:39:07] DEBUG [django.db.backends:90] (0.005) SELECT "auths_menu"."router_json" FROM "auths_menu" ORDER BY "auths_menu"."pos" ASC; args=()
[2016-11-15 16:39:07] INFO [django.server:131] "GET /api/auths/routers/ HTTP/1.1" 200 2
[2016-11-15 16:39:07] INFO [django.server:131] "GET /static/admin/fonts/Roboto-Bold-webfont.woff HTTP/1.1" 304 0
[2016-11-15 16:39:07] INFO [django.server:131] "GET /static/admin/fonts/Roboto-Regular-webfont.woff HTTP/1.1" 304 0
[2016-11-15 16:39:07] INFO [django.server:131] "GET /static/admin/fonts/Roboto-Light-webfont.woff HTTP/1.1" 304 0
[2016-11-15 16:39:08] DEBUG [django.template:929] Exception while resolving variable 'name' in template 'unknown'.
Traceback (most recent call last):
  File "C:\Users\pc\AppData\Local\Programs\Python\Python35-32\lib\site-packages\django\core\handlers\exception.py", line 39, in inner
    response = get_response(request)
  File "C:\Users\pc\AppData\Local\Programs\Python\Python35-32\lib\site-packages\django\core\handlers\base.py", line 172, in _get_response
    resolver_match = resolver.resolve(request.path_info)
  File "C:\Users\pc\AppData\Local\Programs\Python\Python35-32\lib\site-packages\django\urls\resolvers.py", line 300, in resolve
    raise Resolver404({'tried': tried, 'path': new_path})
django.urls.exceptions.Resolver404: {'tried': [[<RegexURLResolver <RegexURLPattern list> (admin:admin) ^admin/>], [<RegexURLResolver <module 'django.contrib.admindocs.urls' from 'C:\\Users\\pc\\AppData\\Local\\Programs\\Python\\Python35-32\\lib\\site-packages\\django\\contrib\\admindocs\\urls.py'> (None:None) ^admin/doc/>], [<RegexURLResolver <module 'rest_framework.urls' from 'C:\\Users\\pc\\AppData\\Local\\Programs\\Python\\Python35-32\\lib\\site-packages\\rest_framework\\urls.py'> (rest_framework:rest_framework) ^api-auth/>], [<RegexURLResolver <module 'oauth2_provider.urls' from 'C:\\Users\\pc\\AppData\\Local\\Programs\\Python\\Python35-32\\lib\\site-packages\\oauth2_provider\\urls.py'> (None:oauth2_provider) ^o/>], [<RegexURLResolver <module 'vemo_service_apps.auths_api.urls' from 'D:\\Nueva carpeta (2)\\vemo\\vemo_service\\vemo_service_apps\\auths_api\\urls.py'> (None:None) ^api/auths/>], [<RegexURLResolver <module 'vemo_service_apps.catalogo_api.urls' from 'D:\\Nueva carpeta (2)\\vemo\\vemo_service\\vemo_service_apps\\catalogo_api\\urls.py'> (None:None) ^api/catalogo/>]], 'path': 'favicon.ico'}

During handling of the above exception, another exception occurred:

Traceback (most recent call last):
  File "C:\Users\pc\AppData\Local\Programs\Python\Python35-32\lib\site-packages\django\template\base.py", line 885, in _resolve_lookup
    current = current[bit]
TypeError: 'RegexURLResolver' object is not subscriptable

During handling of the above exception, another exception occurred:

Traceback (most recent call last):
  File "C:\Users\pc\AppData\Local\Programs\Python\Python35-32\lib\site-packages\django\template\base.py", line 893, in _resolve_lookup
    current = getattr(current, bit)
AttributeError: 'RegexURLResolver' object has no attribute 'name'

During handling of the above exception, another exception occurred:

Traceback (most recent call last):
  File "C:\Users\pc\AppData\Local\Programs\Python\Python35-32\lib\site-packages\django\template\base.py", line 900, in _resolve_lookup
    current = current[int(bit)]
ValueError: invalid literal for int() with base 10: 'name'

During handling of the above exception, another exception occurred:

Traceback (most recent call last):
  File "C:\Users\pc\AppData\Local\Programs\Python\Python35-32\lib\site-packages\django\template\base.py", line 907, in _resolve_lookup
    (bit, current))  # missing attribute
django.template.base.VariableDoesNotExist: Failed lookup for key [name] in '<RegexURLResolver <RegexURLPattern list> (admin:admin) ^admin/>'
[2016-11-15 16:39:08] DEBUG [django.template:929] Exception while resolving variable 'name' in template 'unknown'.
Traceback (most recent call last):
  File "C:\Users\pc\AppData\Local\Programs\Python\Python35-32\lib\site-packages\django\core\handlers\exception.py", line 39, in inner
    response = get_response(request)
  File "C:\Users\pc\AppData\Local\Programs\Python\Python35-32\lib\site-packages\django\core\handlers\base.py", line 172, in _get_response
    resolver_match = resolver.resolve(request.path_info)
  File "C:\Users\pc\AppData\Local\Programs\Python\Python35-32\lib\site-packages\django\urls\resolvers.py", line 300, in resolve
    raise Resolver404({'tried': tried, 'path': new_path})
django.urls.exceptions.Resolver404: {'tried': [[<RegexURLResolver <RegexURLPattern list> (admin:admin) ^admin/>], [<RegexURLResolver <module 'django.contrib.admindocs.urls' from 'C:\\Users\\pc\\AppData\\Local\\Programs\\Python\\Python35-32\\lib\\site-packages\\django\\contrib\\admindocs\\urls.py'> (None:None) ^admin/doc/>], [<RegexURLResolver <module 'rest_framework.urls' from 'C:\\Users\\pc\\AppData\\Local\\Programs\\Python\\Python35-32\\lib\\site-packages\\rest_framework\\urls.py'> (rest_framework:rest_framework) ^api-auth/>], [<RegexURLResolver <module 'oauth2_provider.urls' from 'C:\\Users\\pc\\AppData\\Local\\Programs\\Python\\Python35-32\\lib\\site-packages\\oauth2_provider\\urls.py'> (None:oauth2_provider) ^o/>], [<RegexURLResolver <module 'vemo_service_apps.auths_api.urls' from 'D:\\Nueva carpeta (2)\\vemo\\vemo_service\\vemo_service_apps\\auths_api\\urls.py'> (None:None) ^api/auths/>], [<RegexURLResolver <module 'vemo_service_apps.catalogo_api.urls' from 'D:\\Nueva carpeta (2)\\vemo\\vemo_service\\vemo_service_apps\\catalogo_api\\urls.py'> (None:None) ^api/catalogo/>]], 'path': 'favicon.ico'}

During handling of the above exception, another exception occurred:

Traceback (most recent call last):
  File "C:\Users\pc\AppData\Local\Programs\Python\Python35-32\lib\site-packages\django\template\base.py", line 885, in _resolve_lookup
    current = current[bit]
TypeError: 'RegexURLResolver' object is not subscriptable

During handling of the above exception, another exception occurred:

Traceback (most recent call last):
  File "C:\Users\pc\AppData\Local\Programs\Python\Python35-32\lib\site-packages\django\template\base.py", line 893, in _resolve_lookup
    current = getattr(current, bit)
AttributeError: 'RegexURLResolver' object has no attribute 'name'

During handling of the above exception, another exception occurred:

Traceback (most recent call last):
  File "C:\Users\pc\AppData\Local\Programs\Python\Python35-32\lib\site-packages\django\template\base.py", line 900, in _resolve_lookup
    current = current[int(bit)]
ValueError: invalid literal for int() with base 10: 'name'

During handling of the above exception, another exception occurred:

Traceback (most recent call last):
  File "C:\Users\pc\AppData\Local\Programs\Python\Python35-32\lib\site-packages\django\template\base.py", line 907, in _resolve_lookup
    (bit, current))  # missing attribute
django.template.base.VariableDoesNotExist: Failed lookup for key [name] in "<RegexURLResolver <module 'django.contrib.admindocs.urls' from 'C:\\\\Users\\\\pc\\\\AppData\\\\Local\\\\Programs\\\\Python\\\\Python35-32\\\\lib\\\\site-packages\\\\django\\\\contrib\\\\admindocs\\\\urls.py'> (None:None) ^admin/doc/>"
[2016-11-15 16:39:08] DEBUG [django.template:929] Exception while resolving variable 'name' in template 'unknown'.
Traceback (most recent call last):
  File "C:\Users\pc\AppData\Local\Programs\Python\Python35-32\lib\site-packages\django\core\handlers\exception.py", line 39, in inner
    response = get_response(request)
  File "C:\Users\pc\AppData\Local\Programs\Python\Python35-32\lib\site-packages\django\core\handlers\base.py", line 172, in _get_response
    resolver_match = resolver.resolve(request.path_info)
  File "C:\Users\pc\AppData\Local\Programs\Python\Python35-32\lib\site-packages\django\urls\resolvers.py", line 300, in resolve
    raise Resolver404({'tried': tried, 'path': new_path})
django.urls.exceptions.Resolver404: {'tried': [[<RegexURLResolver <RegexURLPattern list> (admin:admin) ^admin/>], [<RegexURLResolver <module 'django.contrib.admindocs.urls' from 'C:\\Users\\pc\\AppData\\Local\\Programs\\Python\\Python35-32\\lib\\site-packages\\django\\contrib\\admindocs\\urls.py'> (None:None) ^admin/doc/>], [<RegexURLResolver <module 'rest_framework.urls' from 'C:\\Users\\pc\\AppData\\Local\\Programs\\Python\\Python35-32\\lib\\site-packages\\rest_framework\\urls.py'> (rest_framework:rest_framework) ^api-auth/>], [<RegexURLResolver <module 'oauth2_provider.urls' from 'C:\\Users\\pc\\AppData\\Local\\Programs\\Python\\Python35-32\\lib\\site-packages\\oauth2_provider\\urls.py'> (None:oauth2_provider) ^o/>], [<RegexURLResolver <module 'vemo_service_apps.auths_api.urls' from 'D:\\Nueva carpeta (2)\\vemo\\vemo_service\\vemo_service_apps\\auths_api\\urls.py'> (None:None) ^api/auths/>], [<RegexURLResolver <module 'vemo_service_apps.catalogo_api.urls' from 'D:\\Nueva carpeta (2)\\vemo\\vemo_service\\vemo_service_apps\\catalogo_api\\urls.py'> (None:None) ^api/catalogo/>]], 'path': 'favicon.ico'}

During handling of the above exception, another exception occurred:

Traceback (most recent call last):
  File "C:\Users\pc\AppData\Local\Programs\Python\Python35-32\lib\site-packages\django\template\base.py", line 885, in _resolve_lookup
    current = current[bit]
TypeError: 'RegexURLResolver' object is not subscriptable

During handling of the above exception, another exception occurred:

Traceback (most recent call last):
  File "C:\Users\pc\AppData\Local\Programs\Python\Python35-32\lib\site-packages\django\template\base.py", line 893, in _resolve_lookup
    current = getattr(current, bit)
AttributeError: 'RegexURLResolver' object has no attribute 'name'

During handling of the above exception, another exception occurred:

Traceback (most recent call last):
  File "C:\Users\pc\AppData\Local\Programs\Python\Python35-32\lib\site-packages\django\template\base.py", line 900, in _resolve_lookup
    current = current[int(bit)]
ValueError: invalid literal for int() with base 10: 'name'

During handling of the above exception, another exception occurred:

Traceback (most recent call last):
  File "C:\Users\pc\AppData\Local\Programs\Python\Python35-32\lib\site-packages\django\template\base.py", line 907, in _resolve_lookup
    (bit, current))  # missing attribute
django.template.base.VariableDoesNotExist: Failed lookup for key [name] in "<RegexURLResolver <module 'rest_framework.urls' from 'C:\\\\Users\\\\pc\\\\AppData\\\\Local\\\\Programs\\\\Python\\\\Python35-32\\\\lib\\\\site-packages\\\\rest_framework\\\\urls.py'> (rest_framework:rest_framework) ^api-auth/>"
[2016-11-15 16:39:08] DEBUG [django.template:929] Exception while resolving variable 'name' in template 'unknown'.
Traceback (most recent call last):
  File "C:\Users\pc\AppData\Local\Programs\Python\Python35-32\lib\site-packages\django\core\handlers\exception.py", line 39, in inner
    response = get_response(request)
  File "C:\Users\pc\AppData\Local\Programs\Python\Python35-32\lib\site-packages\django\core\handlers\base.py", line 172, in _get_response
    resolver_match = resolver.resolve(request.path_info)
  File "C:\Users\pc\AppData\Local\Programs\Python\Python35-32\lib\site-packages\django\urls\resolvers.py", line 300, in resolve
    raise Resolver404({'tried': tried, 'path': new_path})
django.urls.exceptions.Resolver404: {'tried': [[<RegexURLResolver <RegexURLPattern list> (admin:admin) ^admin/>], [<RegexURLResolver <module 'django.contrib.admindocs.urls' from 'C:\\Users\\pc\\AppData\\Local\\Programs\\Python\\Python35-32\\lib\\site-packages\\django\\contrib\\admindocs\\urls.py'> (None:None) ^admin/doc/>], [<RegexURLResolver <module 'rest_framework.urls' from 'C:\\Users\\pc\\AppData\\Local\\Programs\\Python\\Python35-32\\lib\\site-packages\\rest_framework\\urls.py'> (rest_framework:rest_framework) ^api-auth/>], [<RegexURLResolver <module 'oauth2_provider.urls' from 'C:\\Users\\pc\\AppData\\Local\\Programs\\Python\\Python35-32\\lib\\site-packages\\oauth2_provider\\urls.py'> (None:oauth2_provider) ^o/>], [<RegexURLResolver <module 'vemo_service_apps.auths_api.urls' from 'D:\\Nueva carpeta (2)\\vemo\\vemo_service\\vemo_service_apps\\auths_api\\urls.py'> (None:None) ^api/auths/>], [<RegexURLResolver <module 'vemo_service_apps.catalogo_api.urls' from 'D:\\Nueva carpeta (2)\\vemo\\vemo_service\\vemo_service_apps\\catalogo_api\\urls.py'> (None:None) ^api/catalogo/>]], 'path': 'favicon.ico'}

During handling of the above exception, another exception occurred:

Traceback (most recent call last):
  File "C:\Users\pc\AppData\Local\Programs\Python\Python35-32\lib\site-packages\django\template\base.py", line 885, in _resolve_lookup
    current = current[bit]
TypeError: 'RegexURLResolver' object is not subscriptable

During handling of the above exception, another exception occurred:

Traceback (most recent call last):
  File "C:\Users\pc\AppData\Local\Programs\Python\Python35-32\lib\site-packages\django\template\base.py", line 893, in _resolve_lookup
    current = getattr(current, bit)
AttributeError: 'RegexURLResolver' object has no attribute 'name'

During handling of the above exception, another exception occurred:

Traceback (most recent call last):
  File "C:\Users\pc\AppData\Local\Programs\Python\Python35-32\lib\site-packages\django\template\base.py", line 900, in _resolve_lookup
    current = current[int(bit)]
ValueError: invalid literal for int() with base 10: 'name'

During handling of the above exception, another exception occurred:

Traceback (most recent call last):
  File "C:\Users\pc\AppData\Local\Programs\Python\Python35-32\lib\site-packages\django\template\base.py", line 907, in _resolve_lookup
    (bit, current))  # missing attribute
django.template.base.VariableDoesNotExist: Failed lookup for key [name] in "<RegexURLResolver <module 'oauth2_provider.urls' from 'C:\\\\Users\\\\pc\\\\AppData\\\\Local\\\\Programs\\\\Python\\\\Python35-32\\\\lib\\\\site-packages\\\\oauth2_provider\\\\urls.py'> (None:oauth2_provider) ^o/>"
[2016-11-15 16:39:08] DEBUG [django.template:929] Exception while resolving variable 'name' in template 'unknown'.
Traceback (most recent call last):
  File "C:\Users\pc\AppData\Local\Programs\Python\Python35-32\lib\site-packages\django\core\handlers\exception.py", line 39, in inner
    response = get_response(request)
  File "C:\Users\pc\AppData\Local\Programs\Python\Python35-32\lib\site-packages\django\core\handlers\base.py", line 172, in _get_response
    resolver_match = resolver.resolve(request.path_info)
  File "C:\Users\pc\AppData\Local\Programs\Python\Python35-32\lib\site-packages\django\urls\resolvers.py", line 300, in resolve
    raise Resolver404({'tried': tried, 'path': new_path})
django.urls.exceptions.Resolver404: {'tried': [[<RegexURLResolver <RegexURLPattern list> (admin:admin) ^admin/>], [<RegexURLResolver <module 'django.contrib.admindocs.urls' from 'C:\\Users\\pc\\AppData\\Local\\Programs\\Python\\Python35-32\\lib\\site-packages\\django\\contrib\\admindocs\\urls.py'> (None:None) ^admin/doc/>], [<RegexURLResolver <module 'rest_framework.urls' from 'C:\\Users\\pc\\AppData\\Local\\Programs\\Python\\Python35-32\\lib\\site-packages\\rest_framework\\urls.py'> (rest_framework:rest_framework) ^api-auth/>], [<RegexURLResolver <module 'oauth2_provider.urls' from 'C:\\Users\\pc\\AppData\\Local\\Programs\\Python\\Python35-32\\lib\\site-packages\\oauth2_provider\\urls.py'> (None:oauth2_provider) ^o/>], [<RegexURLResolver <module 'vemo_service_apps.auths_api.urls' from 'D:\\Nueva carpeta (2)\\vemo\\vemo_service\\vemo_service_apps\\auths_api\\urls.py'> (None:None) ^api/auths/>], [<RegexURLResolver <module 'vemo_service_apps.catalogo_api.urls' from 'D:\\Nueva carpeta (2)\\vemo\\vemo_service\\vemo_service_apps\\catalogo_api\\urls.py'> (None:None) ^api/catalogo/>]], 'path': 'favicon.ico'}

During handling of the above exception, another exception occurred:

Traceback (most recent call last):
  File "C:\Users\pc\AppData\Local\Programs\Python\Python35-32\lib\site-packages\django\template\base.py", line 885, in _resolve_lookup
    current = current[bit]
TypeError: 'RegexURLResolver' object is not subscriptable

During handling of the above exception, another exception occurred:

Traceback (most recent call last):
  File "C:\Users\pc\AppData\Local\Programs\Python\Python35-32\lib\site-packages\django\template\base.py", line 893, in _resolve_lookup
    current = getattr(current, bit)
AttributeError: 'RegexURLResolver' object has no attribute 'name'

During handling of the above exception, another exception occurred:

Traceback (most recent call last):
  File "C:\Users\pc\AppData\Local\Programs\Python\Python35-32\lib\site-packages\django\template\base.py", line 900, in _resolve_lookup
    current = current[int(bit)]
ValueError: invalid literal for int() with base 10: 'name'

During handling of the above exception, another exception occurred:

Traceback (most recent call last):
  File "C:\Users\pc\AppData\Local\Programs\Python\Python35-32\lib\site-packages\django\template\base.py", line 907, in _resolve_lookup
    (bit, current))  # missing attribute
django.template.base.VariableDoesNotExist: Failed lookup for key [name] in "<RegexURLResolver <module 'vemo_service_apps.auths_api.urls' from 'D:\\\\Nueva carpeta (2)\\\\vemo\\\\vemo_service\\\\vemo_service_apps\\\\auths_api\\\\urls.py'> (None:None) ^api/auths/>"
[2016-11-15 16:39:08] DEBUG [django.template:929] Exception while resolving variable 'name' in template 'unknown'.
Traceback (most recent call last):
  File "C:\Users\pc\AppData\Local\Programs\Python\Python35-32\lib\site-packages\django\core\handlers\exception.py", line 39, in inner
    response = get_response(request)
  File "C:\Users\pc\AppData\Local\Programs\Python\Python35-32\lib\site-packages\django\core\handlers\base.py", line 172, in _get_response
    resolver_match = resolver.resolve(request.path_info)
  File "C:\Users\pc\AppData\Local\Programs\Python\Python35-32\lib\site-packages\django\urls\resolvers.py", line 300, in resolve
    raise Resolver404({'tried': tried, 'path': new_path})
django.urls.exceptions.Resolver404: {'tried': [[<RegexURLResolver <RegexURLPattern list> (admin:admin) ^admin/>], [<RegexURLResolver <module 'django.contrib.admindocs.urls' from 'C:\\Users\\pc\\AppData\\Local\\Programs\\Python\\Python35-32\\lib\\site-packages\\django\\contrib\\admindocs\\urls.py'> (None:None) ^admin/doc/>], [<RegexURLResolver <module 'rest_framework.urls' from 'C:\\Users\\pc\\AppData\\Local\\Programs\\Python\\Python35-32\\lib\\site-packages\\rest_framework\\urls.py'> (rest_framework:rest_framework) ^api-auth/>], [<RegexURLResolver <module 'oauth2_provider.urls' from 'C:\\Users\\pc\\AppData\\Local\\Programs\\Python\\Python35-32\\lib\\site-packages\\oauth2_provider\\urls.py'> (None:oauth2_provider) ^o/>], [<RegexURLResolver <module 'vemo_service_apps.auths_api.urls' from 'D:\\Nueva carpeta (2)\\vemo\\vemo_service\\vemo_service_apps\\auths_api\\urls.py'> (None:None) ^api/auths/>], [<RegexURLResolver <module 'vemo_service_apps.catalogo_api.urls' from 'D:\\Nueva carpeta (2)\\vemo\\vemo_service\\vemo_service_apps\\catalogo_api\\urls.py'> (None:None) ^api/catalogo/>]], 'path': 'favicon.ico'}

During handling of the above exception, another exception occurred:

Traceback (most recent call last):
  File "C:\Users\pc\AppData\Local\Programs\Python\Python35-32\lib\site-packages\django\template\base.py", line 885, in _resolve_lookup
    current = current[bit]
TypeError: 'RegexURLResolver' object is not subscriptable

During handling of the above exception, another exception occurred:

Traceback (most recent call last):
  File "C:\Users\pc\AppData\Local\Programs\Python\Python35-32\lib\site-packages\django\template\base.py", line 893, in _resolve_lookup
    current = getattr(current, bit)
AttributeError: 'RegexURLResolver' object has no attribute 'name'

During handling of the above exception, another exception occurred:

Traceback (most recent call last):
  File "C:\Users\pc\AppData\Local\Programs\Python\Python35-32\lib\site-packages\django\template\base.py", line 900, in _resolve_lookup
    current = current[int(bit)]
ValueError: invalid literal for int() with base 10: 'name'

During handling of the above exception, another exception occurred:

Traceback (most recent call last):
  File "C:\Users\pc\AppData\Local\Programs\Python\Python35-32\lib\site-packages\django\template\base.py", line 907, in _resolve_lookup
    (bit, current))  # missing attribute
django.template.base.VariableDoesNotExist: Failed lookup for key [name] in "<RegexURLResolver <module 'vemo_service_apps.catalogo_api.urls' from 'D:\\\\Nueva carpeta (2)\\\\vemo\\\\vemo_service\\\\vemo_service_apps\\\\catalogo_api\\\\urls.py'> (None:None) ^api/catalogo/>"
[2016-11-15 16:39:08] WARNING [django.request:152] Not Found: /favicon.ico
[2016-11-15 16:39:08] WARNING [django.server:131] "GET /favicon.ico HTTP/1.1" 404 2488
[2016-11-15 16:39:08] DEBUG [django.template:929] Exception while resolving variable 'name' in template 'unknown'.
Traceback (most recent call last):
  File "C:\Users\pc\AppData\Local\Programs\Python\Python35-32\lib\site-packages\django\core\handlers\exception.py", line 39, in inner
    response = get_response(request)
  File "C:\Users\pc\AppData\Local\Programs\Python\Python35-32\lib\site-packages\django\core\handlers\base.py", line 172, in _get_response
    resolver_match = resolver.resolve(request.path_info)
  File "C:\Users\pc\AppData\Local\Programs\Python\Python35-32\lib\site-packages\django\urls\resolvers.py", line 300, in resolve
    raise Resolver404({'tried': tried, 'path': new_path})
django.urls.exceptions.Resolver404: {'tried': [[<RegexURLResolver <RegexURLPattern list> (admin:admin) ^admin/>], [<RegexURLResolver <module 'django.contrib.admindocs.urls' from 'C:\\Users\\pc\\AppData\\Local\\Programs\\Python\\Python35-32\\lib\\site-packages\\django\\contrib\\admindocs\\urls.py'> (None:None) ^admin/doc/>], [<RegexURLResolver <module 'rest_framework.urls' from 'C:\\Users\\pc\\AppData\\Local\\Programs\\Python\\Python35-32\\lib\\site-packages\\rest_framework\\urls.py'> (rest_framework:rest_framework) ^api-auth/>], [<RegexURLResolver <module 'oauth2_provider.urls' from 'C:\\Users\\pc\\AppData\\Local\\Programs\\Python\\Python35-32\\lib\\site-packages\\oauth2_provider\\urls.py'> (None:oauth2_provider) ^o/>], [<RegexURLResolver <module 'vemo_service_apps.auths_api.urls' from 'D:\\Nueva carpeta (2)\\vemo\\vemo_service\\vemo_service_apps\\auths_api\\urls.py'> (None:None) ^api/auths/>], [<RegexURLResolver <module 'vemo_service_apps.catalogo_api.urls' from 'D:\\Nueva carpeta (2)\\vemo\\vemo_service\\vemo_service_apps\\catalogo_api\\urls.py'> (None:None) ^api/catalogo/>]], 'path': 'favicon.ico'}

During handling of the above exception, another exception occurred:

Traceback (most recent call last):
  File "C:\Users\pc\AppData\Local\Programs\Python\Python35-32\lib\site-packages\django\template\base.py", line 885, in _resolve_lookup
    current = current[bit]
TypeError: 'RegexURLResolver' object is not subscriptable

During handling of the above exception, another exception occurred:

Traceback (most recent call last):
  File "C:\Users\pc\AppData\Local\Programs\Python\Python35-32\lib\site-packages\django\template\base.py", line 893, in _resolve_lookup
    current = getattr(current, bit)
AttributeError: 'RegexURLResolver' object has no attribute 'name'

During handling of the above exception, another exception occurred:

Traceback (most recent call last):
  File "C:\Users\pc\AppData\Local\Programs\Python\Python35-32\lib\site-packages\django\template\base.py", line 900, in _resolve_lookup
    current = current[int(bit)]
ValueError: invalid literal for int() with base 10: 'name'

During handling of the above exception, another exception occurred:

Traceback (most recent call last):
  File "C:\Users\pc\AppData\Local\Programs\Python\Python35-32\lib\site-packages\django\template\base.py", line 907, in _resolve_lookup
    (bit, current))  # missing attribute
django.template.base.VariableDoesNotExist: Failed lookup for key [name] in '<RegexURLResolver <RegexURLPattern list> (admin:admin) ^admin/>'
[2016-11-15 16:39:08] DEBUG [django.template:929] Exception while resolving variable 'name' in template 'unknown'.
Traceback (most recent call last):
  File "C:\Users\pc\AppData\Local\Programs\Python\Python35-32\lib\site-packages\django\core\handlers\exception.py", line 39, in inner
    response = get_response(request)
  File "C:\Users\pc\AppData\Local\Programs\Python\Python35-32\lib\site-packages\django\core\handlers\base.py", line 172, in _get_response
    resolver_match = resolver.resolve(request.path_info)
  File "C:\Users\pc\AppData\Local\Programs\Python\Python35-32\lib\site-packages\django\urls\resolvers.py", line 300, in resolve
    raise Resolver404({'tried': tried, 'path': new_path})
django.urls.exceptions.Resolver404: {'tried': [[<RegexURLResolver <RegexURLPattern list> (admin:admin) ^admin/>], [<RegexURLResolver <module 'django.contrib.admindocs.urls' from 'C:\\Users\\pc\\AppData\\Local\\Programs\\Python\\Python35-32\\lib\\site-packages\\django\\contrib\\admindocs\\urls.py'> (None:None) ^admin/doc/>], [<RegexURLResolver <module 'rest_framework.urls' from 'C:\\Users\\pc\\AppData\\Local\\Programs\\Python\\Python35-32\\lib\\site-packages\\rest_framework\\urls.py'> (rest_framework:rest_framework) ^api-auth/>], [<RegexURLResolver <module 'oauth2_provider.urls' from 'C:\\Users\\pc\\AppData\\Local\\Programs\\Python\\Python35-32\\lib\\site-packages\\oauth2_provider\\urls.py'> (None:oauth2_provider) ^o/>], [<RegexURLResolver <module 'vemo_service_apps.auths_api.urls' from 'D:\\Nueva carpeta (2)\\vemo\\vemo_service\\vemo_service_apps\\auths_api\\urls.py'> (None:None) ^api/auths/>], [<RegexURLResolver <module 'vemo_service_apps.catalogo_api.urls' from 'D:\\Nueva carpeta (2)\\vemo\\vemo_service\\vemo_service_apps\\catalogo_api\\urls.py'> (None:None) ^api/catalogo/>]], 'path': 'favicon.ico'}

During handling of the above exception, another exception occurred:

Traceback (most recent call last):
  File "C:\Users\pc\AppData\Local\Programs\Python\Python35-32\lib\site-packages\django\template\base.py", line 885, in _resolve_lookup
    current = current[bit]
TypeError: 'RegexURLResolver' object is not subscriptable

During handling of the above exception, another exception occurred:

Traceback (most recent call last):
  File "C:\Users\pc\AppData\Local\Programs\Python\Python35-32\lib\site-packages\django\template\base.py", line 893, in _resolve_lookup
    current = getattr(current, bit)
AttributeError: 'RegexURLResolver' object has no attribute 'name'

During handling of the above exception, another exception occurred:

Traceback (most recent call last):
  File "C:\Users\pc\AppData\Local\Programs\Python\Python35-32\lib\site-packages\django\template\base.py", line 900, in _resolve_lookup
    current = current[int(bit)]
ValueError: invalid literal for int() with base 10: 'name'

During handling of the above exception, another exception occurred:

Traceback (most recent call last):
  File "C:\Users\pc\AppData\Local\Programs\Python\Python35-32\lib\site-packages\django\template\base.py", line 907, in _resolve_lookup
    (bit, current))  # missing attribute
django.template.base.VariableDoesNotExist: Failed lookup for key [name] in "<RegexURLResolver <module 'django.contrib.admindocs.urls' from 'C:\\\\Users\\\\pc\\\\AppData\\\\Local\\\\Programs\\\\Python\\\\Python35-32\\\\lib\\\\site-packages\\\\django\\\\contrib\\\\admindocs\\\\urls.py'> (None:None) ^admin/doc/>"
[2016-11-15 16:39:08] DEBUG [django.template:929] Exception while resolving variable 'name' in template 'unknown'.
Traceback (most recent call last):
  File "C:\Users\pc\AppData\Local\Programs\Python\Python35-32\lib\site-packages\django\core\handlers\exception.py", line 39, in inner
    response = get_response(request)
  File "C:\Users\pc\AppData\Local\Programs\Python\Python35-32\lib\site-packages\django\core\handlers\base.py", line 172, in _get_response
    resolver_match = resolver.resolve(request.path_info)
  File "C:\Users\pc\AppData\Local\Programs\Python\Python35-32\lib\site-packages\django\urls\resolvers.py", line 300, in resolve
    raise Resolver404({'tried': tried, 'path': new_path})
django.urls.exceptions.Resolver404: {'tried': [[<RegexURLResolver <RegexURLPattern list> (admin:admin) ^admin/>], [<RegexURLResolver <module 'django.contrib.admindocs.urls' from 'C:\\Users\\pc\\AppData\\Local\\Programs\\Python\\Python35-32\\lib\\site-packages\\django\\contrib\\admindocs\\urls.py'> (None:None) ^admin/doc/>], [<RegexURLResolver <module 'rest_framework.urls' from 'C:\\Users\\pc\\AppData\\Local\\Programs\\Python\\Python35-32\\lib\\site-packages\\rest_framework\\urls.py'> (rest_framework:rest_framework) ^api-auth/>], [<RegexURLResolver <module 'oauth2_provider.urls' from 'C:\\Users\\pc\\AppData\\Local\\Programs\\Python\\Python35-32\\lib\\site-packages\\oauth2_provider\\urls.py'> (None:oauth2_provider) ^o/>], [<RegexURLResolver <module 'vemo_service_apps.auths_api.urls' from 'D:\\Nueva carpeta (2)\\vemo\\vemo_service\\vemo_service_apps\\auths_api\\urls.py'> (None:None) ^api/auths/>], [<RegexURLResolver <module 'vemo_service_apps.catalogo_api.urls' from 'D:\\Nueva carpeta (2)\\vemo\\vemo_service\\vemo_service_apps\\catalogo_api\\urls.py'> (None:None) ^api/catalogo/>]], 'path': 'favicon.ico'}

During handling of the above exception, another exception occurred:

Traceback (most recent call last):
  File "C:\Users\pc\AppData\Local\Programs\Python\Python35-32\lib\site-packages\django\template\base.py", line 885, in _resolve_lookup
    current = current[bit]
TypeError: 'RegexURLResolver' object is not subscriptable

During handling of the above exception, another exception occurred:

Traceback (most recent call last):
  File "C:\Users\pc\AppData\Local\Programs\Python\Python35-32\lib\site-packages\django\template\base.py", line 893, in _resolve_lookup
    current = getattr(current, bit)
AttributeError: 'RegexURLResolver' object has no attribute 'name'

During handling of the above exception, another exception occurred:

Traceback (most recent call last):
  File "C:\Users\pc\AppData\Local\Programs\Python\Python35-32\lib\site-packages\django\template\base.py", line 900, in _resolve_lookup
    current = current[int(bit)]
ValueError: invalid literal for int() with base 10: 'name'

During handling of the above exception, another exception occurred:

Traceback (most recent call last):
  File "C:\Users\pc\AppData\Local\Programs\Python\Python35-32\lib\site-packages\django\template\base.py", line 907, in _resolve_lookup
    (bit, current))  # missing attribute
django.template.base.VariableDoesNotExist: Failed lookup for key [name] in "<RegexURLResolver <module 'rest_framework.urls' from 'C:\\\\Users\\\\pc\\\\AppData\\\\Local\\\\Programs\\\\Python\\\\Python35-32\\\\lib\\\\site-packages\\\\rest_framework\\\\urls.py'> (rest_framework:rest_framework) ^api-auth/>"
[2016-11-15 16:39:08] DEBUG [django.template:929] Exception while resolving variable 'name' in template 'unknown'.
Traceback (most recent call last):
  File "C:\Users\pc\AppData\Local\Programs\Python\Python35-32\lib\site-packages\django\core\handlers\exception.py", line 39, in inner
    response = get_response(request)
  File "C:\Users\pc\AppData\Local\Programs\Python\Python35-32\lib\site-packages\django\core\handlers\base.py", line 172, in _get_response
    resolver_match = resolver.resolve(request.path_info)
  File "C:\Users\pc\AppData\Local\Programs\Python\Python35-32\lib\site-packages\django\urls\resolvers.py", line 300, in resolve
    raise Resolver404({'tried': tried, 'path': new_path})
django.urls.exceptions.Resolver404: {'tried': [[<RegexURLResolver <RegexURLPattern list> (admin:admin) ^admin/>], [<RegexURLResolver <module 'django.contrib.admindocs.urls' from 'C:\\Users\\pc\\AppData\\Local\\Programs\\Python\\Python35-32\\lib\\site-packages\\django\\contrib\\admindocs\\urls.py'> (None:None) ^admin/doc/>], [<RegexURLResolver <module 'rest_framework.urls' from 'C:\\Users\\pc\\AppData\\Local\\Programs\\Python\\Python35-32\\lib\\site-packages\\rest_framework\\urls.py'> (rest_framework:rest_framework) ^api-auth/>], [<RegexURLResolver <module 'oauth2_provider.urls' from 'C:\\Users\\pc\\AppData\\Local\\Programs\\Python\\Python35-32\\lib\\site-packages\\oauth2_provider\\urls.py'> (None:oauth2_provider) ^o/>], [<RegexURLResolver <module 'vemo_service_apps.auths_api.urls' from 'D:\\Nueva carpeta (2)\\vemo\\vemo_service\\vemo_service_apps\\auths_api\\urls.py'> (None:None) ^api/auths/>], [<RegexURLResolver <module 'vemo_service_apps.catalogo_api.urls' from 'D:\\Nueva carpeta (2)\\vemo\\vemo_service\\vemo_service_apps\\catalogo_api\\urls.py'> (None:None) ^api/catalogo/>]], 'path': 'favicon.ico'}

During handling of the above exception, another exception occurred:

Traceback (most recent call last):
  File "C:\Users\pc\AppData\Local\Programs\Python\Python35-32\lib\site-packages\django\template\base.py", line 885, in _resolve_lookup
    current = current[bit]
TypeError: 'RegexURLResolver' object is not subscriptable

During handling of the above exception, another exception occurred:

Traceback (most recent call last):
  File "C:\Users\pc\AppData\Local\Programs\Python\Python35-32\lib\site-packages\django\template\base.py", line 893, in _resolve_lookup
    current = getattr(current, bit)
AttributeError: 'RegexURLResolver' object has no attribute 'name'

During handling of the above exception, another exception occurred:

Traceback (most recent call last):
  File "C:\Users\pc\AppData\Local\Programs\Python\Python35-32\lib\site-packages\django\template\base.py", line 900, in _resolve_lookup
    current = current[int(bit)]
ValueError: invalid literal for int() with base 10: 'name'

During handling of the above exception, another exception occurred:

Traceback (most recent call last):
  File "C:\Users\pc\AppData\Local\Programs\Python\Python35-32\lib\site-packages\django\template\base.py", line 907, in _resolve_lookup
    (bit, current))  # missing attribute
django.template.base.VariableDoesNotExist: Failed lookup for key [name] in "<RegexURLResolver <module 'oauth2_provider.urls' from 'C:\\\\Users\\\\pc\\\\AppData\\\\Local\\\\Programs\\\\Python\\\\Python35-32\\\\lib\\\\site-packages\\\\oauth2_provider\\\\urls.py'> (None:oauth2_provider) ^o/>"
[2016-11-15 16:39:08] DEBUG [django.template:929] Exception while resolving variable 'name' in template 'unknown'.
Traceback (most recent call last):
  File "C:\Users\pc\AppData\Local\Programs\Python\Python35-32\lib\site-packages\django\core\handlers\exception.py", line 39, in inner
    response = get_response(request)
  File "C:\Users\pc\AppData\Local\Programs\Python\Python35-32\lib\site-packages\django\core\handlers\base.py", line 172, in _get_response
    resolver_match = resolver.resolve(request.path_info)
  File "C:\Users\pc\AppData\Local\Programs\Python\Python35-32\lib\site-packages\django\urls\resolvers.py", line 300, in resolve
    raise Resolver404({'tried': tried, 'path': new_path})
django.urls.exceptions.Resolver404: {'tried': [[<RegexURLResolver <RegexURLPattern list> (admin:admin) ^admin/>], [<RegexURLResolver <module 'django.contrib.admindocs.urls' from 'C:\\Users\\pc\\AppData\\Local\\Programs\\Python\\Python35-32\\lib\\site-packages\\django\\contrib\\admindocs\\urls.py'> (None:None) ^admin/doc/>], [<RegexURLResolver <module 'rest_framework.urls' from 'C:\\Users\\pc\\AppData\\Local\\Programs\\Python\\Python35-32\\lib\\site-packages\\rest_framework\\urls.py'> (rest_framework:rest_framework) ^api-auth/>], [<RegexURLResolver <module 'oauth2_provider.urls' from 'C:\\Users\\pc\\AppData\\Local\\Programs\\Python\\Python35-32\\lib\\site-packages\\oauth2_provider\\urls.py'> (None:oauth2_provider) ^o/>], [<RegexURLResolver <module 'vemo_service_apps.auths_api.urls' from 'D:\\Nueva carpeta (2)\\vemo\\vemo_service\\vemo_service_apps\\auths_api\\urls.py'> (None:None) ^api/auths/>], [<RegexURLResolver <module 'vemo_service_apps.catalogo_api.urls' from 'D:\\Nueva carpeta (2)\\vemo\\vemo_service\\vemo_service_apps\\catalogo_api\\urls.py'> (None:None) ^api/catalogo/>]], 'path': 'favicon.ico'}

During handling of the above exception, another exception occurred:

Traceback (most recent call last):
  File "C:\Users\pc\AppData\Local\Programs\Python\Python35-32\lib\site-packages\django\template\base.py", line 885, in _resolve_lookup
    current = current[bit]
TypeError: 'RegexURLResolver' object is not subscriptable

During handling of the above exception, another exception occurred:

Traceback (most recent call last):
  File "C:\Users\pc\AppData\Local\Programs\Python\Python35-32\lib\site-packages\django\template\base.py", line 893, in _resolve_lookup
    current = getattr(current, bit)
AttributeError: 'RegexURLResolver' object has no attribute 'name'

During handling of the above exception, another exception occurred:

Traceback (most recent call last):
  File "C:\Users\pc\AppData\Local\Programs\Python\Python35-32\lib\site-packages\django\template\base.py", line 900, in _resolve_lookup
    current = current[int(bit)]
ValueError: invalid literal for int() with base 10: 'name'

During handling of the above exception, another exception occurred:

Traceback (most recent call last):
  File "C:\Users\pc\AppData\Local\Programs\Python\Python35-32\lib\site-packages\django\template\base.py", line 907, in _resolve_lookup
    (bit, current))  # missing attribute
django.template.base.VariableDoesNotExist: Failed lookup for key [name] in "<RegexURLResolver <module 'vemo_service_apps.auths_api.urls' from 'D:\\\\Nueva carpeta (2)\\\\vemo\\\\vemo_service\\\\vemo_service_apps\\\\auths_api\\\\urls.py'> (None:None) ^api/auths/>"
[2016-11-15 16:39:08] DEBUG [django.template:929] Exception while resolving variable 'name' in template 'unknown'.
Traceback (most recent call last):
  File "C:\Users\pc\AppData\Local\Programs\Python\Python35-32\lib\site-packages\django\core\handlers\exception.py", line 39, in inner
    response = get_response(request)
  File "C:\Users\pc\AppData\Local\Programs\Python\Python35-32\lib\site-packages\django\core\handlers\base.py", line 172, in _get_response
    resolver_match = resolver.resolve(request.path_info)
  File "C:\Users\pc\AppData\Local\Programs\Python\Python35-32\lib\site-packages\django\urls\resolvers.py", line 300, in resolve
    raise Resolver404({'tried': tried, 'path': new_path})
django.urls.exceptions.Resolver404: {'tried': [[<RegexURLResolver <RegexURLPattern list> (admin:admin) ^admin/>], [<RegexURLResolver <module 'django.contrib.admindocs.urls' from 'C:\\Users\\pc\\AppData\\Local\\Programs\\Python\\Python35-32\\lib\\site-packages\\django\\contrib\\admindocs\\urls.py'> (None:None) ^admin/doc/>], [<RegexURLResolver <module 'rest_framework.urls' from 'C:\\Users\\pc\\AppData\\Local\\Programs\\Python\\Python35-32\\lib\\site-packages\\rest_framework\\urls.py'> (rest_framework:rest_framework) ^api-auth/>], [<RegexURLResolver <module 'oauth2_provider.urls' from 'C:\\Users\\pc\\AppData\\Local\\Programs\\Python\\Python35-32\\lib\\site-packages\\oauth2_provider\\urls.py'> (None:oauth2_provider) ^o/>], [<RegexURLResolver <module 'vemo_service_apps.auths_api.urls' from 'D:\\Nueva carpeta (2)\\vemo\\vemo_service\\vemo_service_apps\\auths_api\\urls.py'> (None:None) ^api/auths/>], [<RegexURLResolver <module 'vemo_service_apps.catalogo_api.urls' from 'D:\\Nueva carpeta (2)\\vemo\\vemo_service\\vemo_service_apps\\catalogo_api\\urls.py'> (None:None) ^api/catalogo/>]], 'path': 'favicon.ico'}

During handling of the above exception, another exception occurred:

Traceback (most recent call last):
  File "C:\Users\pc\AppData\Local\Programs\Python\Python35-32\lib\site-packages\django\template\base.py", line 885, in _resolve_lookup
    current = current[bit]
TypeError: 'RegexURLResolver' object is not subscriptable

During handling of the above exception, another exception occurred:

Traceback (most recent call last):
  File "C:\Users\pc\AppData\Local\Programs\Python\Python35-32\lib\site-packages\django\template\base.py", line 893, in _resolve_lookup
    current = getattr(current, bit)
AttributeError: 'RegexURLResolver' object has no attribute 'name'

During handling of the above exception, another exception occurred:

Traceback (most recent call last):
  File "C:\Users\pc\AppData\Local\Programs\Python\Python35-32\lib\site-packages\django\template\base.py", line 900, in _resolve_lookup
    current = current[int(bit)]
ValueError: invalid literal for int() with base 10: 'name'

During handling of the above exception, another exception occurred:

Traceback (most recent call last):
  File "C:\Users\pc\AppData\Local\Programs\Python\Python35-32\lib\site-packages\django\template\base.py", line 907, in _resolve_lookup
    (bit, current))  # missing attribute
django.template.base.VariableDoesNotExist: Failed lookup for key [name] in "<RegexURLResolver <module 'vemo_service_apps.catalogo_api.urls' from 'D:\\\\Nueva carpeta (2)\\\\vemo\\\\vemo_service\\\\vemo_service_apps\\\\catalogo_api\\\\urls.py'> (None:None) ^api/catalogo/>"
[2016-11-15 16:39:08] WARNING [django.request:152] Not Found: /favicon.ico
[2016-11-15 16:39:08] WARNING [django.server:131] "GET /favicon.ico HTTP/1.1" 404 2488
[2016-11-15 16:39:26] DEBUG [django.db.backends:90] (0.003) SELECT "oauth2_provider_application"."id", "oauth2_provider_application"."client_id", "oauth2_provider_application"."user_id", "oauth2_provider_application"."redirect_uris", "oauth2_provider_application"."client_type", "oauth2_provider_application"."authorization_grant_type", "oauth2_provider_application"."client_secret", "oauth2_provider_application"."name", "oauth2_provider_application"."skip_authorization" FROM "oauth2_provider_application" WHERE "oauth2_provider_application"."client_id" = 'gyEJ310NDKMKrYvOMbwSnu9UFkJkXE5E48dCLRZK'; args=('gyEJ310NDKMKrYvOMbwSnu9UFkJkXE5E48dCLRZK',)
[2016-11-15 16:39:26] DEBUG [django.db.backends:90] (0.001) SELECT "auths_user"."password", "auths_user"."last_login", "auths_user"."is_superuser", "auths_user"."username", "auths_user"."first_name", "auths_user"."last_name", "auths_user"."email", "auths_user"."is_staff", "auths_user"."is_active", "auths_user"."date_joined", "auths_user"."id", "auths_user"."last_hierarchy_id", "auths_user"."last_module_id", "auths_user"."person_id", "auths_user"."updated_at", "auths_user"."registered_by" FROM "auths_user" WHERE "auths_user"."username" = 'admin'; args=('admin',)
[2016-11-15 16:39:26] DEBUG [django.db.backends:90] (0.000) BEGIN; args=None
[2016-11-15 16:39:27] DEBUG [django.db.backends:90] (0.092) INSERT INTO "oauth2_provider_accesstoken" ("user_id", "token", "application_id", "expires", "scope") VALUES ('3651942c1384420da02bbf9e5eca3faa', 'pbonUfwDdVWqNXL836FceAznDaeFi5', 1, '2016-11-16 07:39:26.931611', 'write read'); args=['3651942c1384420da02bbf9e5eca3faa', 'pbonUfwDdVWqNXL836FceAznDaeFi5', 1, '2016-11-16 07:39:26.931611', 'write read']
[2016-11-15 16:39:27] DEBUG [django.db.backends:90] (0.000) BEGIN; args=None
[2016-11-15 16:39:27] DEBUG [django.db.backends:90] (0.038) INSERT INTO "oauth2_provider_refreshtoken" ("user_id", "token", "application_id", "access_token_id") VALUES ('3651942c1384420da02bbf9e5eca3faa', 'aVK4B3Xvz9xCr3pGd8G4hZd9qFAPpy', 1, 18); args=['3651942c1384420da02bbf9e5eca3faa', 'aVK4B3Xvz9xCr3pGd8G4hZd9qFAPpy', 1, 18]
[2016-11-15 16:39:27] INFO [django.server:131] "POST /o/token/ HTTP/1.1" 200 169
[2016-11-15 16:39:28] DEBUG [django.db.backends:90] (0.005) SELECT "oauth2_provider_accesstoken"."id", "oauth2_provider_accesstoken"."user_id", "oauth2_provider_accesstoken"."token", "oauth2_provider_accesstoken"."application_id", "oauth2_provider_accesstoken"."expires", "oauth2_provider_accesstoken"."scope", "auths_user"."password", "auths_user"."last_login", "auths_user"."is_superuser", "auths_user"."username", "auths_user"."first_name", "auths_user"."last_name", "auths_user"."email", "auths_user"."is_staff", "auths_user"."is_active", "auths_user"."date_joined", "auths_user"."id", "auths_user"."last_hierarchy_id", "auths_user"."last_module_id", "auths_user"."person_id", "auths_user"."updated_at", "auths_user"."registered_by", "oauth2_provider_application"."id", "oauth2_provider_application"."client_id", "oauth2_provider_application"."user_id", "oauth2_provider_application"."redirect_uris", "oauth2_provider_application"."client_type", "oauth2_provider_application"."authorization_grant_type", "oauth2_provider_application"."client_secret", "oauth2_provider_application"."name", "oauth2_provider_application"."skip_authorization" FROM "oauth2_provider_accesstoken" LEFT OUTER JOIN "auths_user" ON ("oauth2_provider_accesstoken"."user_id" = "auths_user"."id") INNER JOIN "oauth2_provider_application" ON ("oauth2_provider_accesstoken"."application_id" = "oauth2_provider_application"."id") WHERE "oauth2_provider_accesstoken"."token" = 'pbonUfwDdVWqNXL836FceAznDaeFi5'; args=('pbonUfwDdVWqNXL836FceAznDaeFi5',)
[2016-11-15 16:39:28] INFO [django.server:131] "OPTIONS /api/auths/usermenu/ HTTP/1.1" 200 0
[2016-11-15 16:39:29] DEBUG [django.db.backends:90] (0.000) SELECT "auth_group"."id", "auth_group"."name" FROM "auth_group" INNER JOIN "auths_user_groups" ON ("auth_group"."id" = "auths_user_groups"."group_id") WHERE "auths_user_groups"."user_id" = '3651942c1384420da02bbf9e5eca3faa'; args=('3651942c1384420da02bbf9e5eca3faa',)
[2016-11-15 16:39:29] DEBUG [django.db.backends:90] (0.000) SELECT "auth_permission"."id", "auth_permission"."name", "auth_permission"."content_type_id", "auth_permission"."codename" FROM "auth_permission" INNER JOIN "auths_user_user_permissions" ON ("auth_permission"."id" = "auths_user_user_permissions"."permission_id") INNER JOIN "django_content_type" ON ("auth_permission"."content_type_id" = "django_content_type"."id") WHERE "auths_user_user_permissions"."user_id" = '3651942c1384420da02bbf9e5eca3faa' ORDER BY "django_content_type"."app_label" ASC, "django_content_type"."model" ASC, "auth_permission"."codename" ASC; args=('3651942c1384420da02bbf9e5eca3faa',)
[2016-11-15 16:39:29] INFO [django.server:131] "GET /api/auths/localuserinfo/ HTTP/1.1" 200 496
[2016-11-15 16:39:29] DEBUG [django.db.backends:90] (0.003) SELECT "oauth2_provider_accesstoken"."id", "oauth2_provider_accesstoken"."user_id", "oauth2_provider_accesstoken"."token", "oauth2_provider_accesstoken"."application_id", "oauth2_provider_accesstoken"."expires", "oauth2_provider_accesstoken"."scope", "auths_user"."password", "auths_user"."last_login", "auths_user"."is_superuser", "auths_user"."username", "auths_user"."first_name", "auths_user"."last_name", "auths_user"."email", "auths_user"."is_staff", "auths_user"."is_active", "auths_user"."date_joined", "auths_user"."id", "auths_user"."last_hierarchy_id", "auths_user"."last_module_id", "auths_user"."person_id", "auths_user"."updated_at", "auths_user"."registered_by", "oauth2_provider_application"."id", "oauth2_provider_application"."client_id", "oauth2_provider_application"."user_id", "oauth2_provider_application"."redirect_uris", "oauth2_provider_application"."client_type", "oauth2_provider_application"."authorization_grant_type", "oauth2_provider_application"."client_secret", "oauth2_provider_application"."name", "oauth2_provider_application"."skip_authorization" FROM "oauth2_provider_accesstoken" LEFT OUTER JOIN "auths_user" ON ("oauth2_provider_accesstoken"."user_id" = "auths_user"."id") INNER JOIN "oauth2_provider_application" ON ("oauth2_provider_accesstoken"."application_id" = "oauth2_provider_application"."id") WHERE "oauth2_provider_accesstoken"."token" = 'pbonUfwDdVWqNXL836FceAznDaeFi5'; args=('pbonUfwDdVWqNXL836FceAznDaeFi5',)
[2016-11-15 16:39:29] DEBUG [django.db.backends:90] (0.002) SELECT "auths_menu"."id" FROM "auths_menu" WHERE ("auths_menu"."id" IS NOT NULL AND "auths_menu"."is_active" = 1 AND "auths_menu"."module" = 'BACKEND') ORDER BY "auths_menu"."pos" ASC; args=(True, 'BACKEND')
[2016-11-15 16:39:29] DEBUG [django.db.backends:90] (0.134) SELECT (1) AS "a" FROM "django_session" WHERE "django_session"."session_key" = 'iseh396uo9i4y1vzn7esag595dol55l1' LIMIT 1; args=('iseh396uo9i4y1vzn7esag595dol55l1',)
[2016-11-15 16:39:29] DEBUG [django.db.backends:90] (0.000) BEGIN; args=None
[2016-11-15 16:39:29] DEBUG [django.db.backends:90] (0.248) INSERT INTO "django_session" ("session_key", "session_data", "expire_date") SELECT 'iseh396uo9i4y1vzn7esag595dol55l1', 'NmE3M2Q3NmYwOTU3YjJmZDBjYmQxYTVjODc5MTExNzM3NjY1YzYzNzp7Il9zZXNzaW9uX2V4cGlyeSI6MzB9', '2016-11-15 21:39:59.575998'; args=('iseh396uo9i4y1vzn7esag595dol55l1', 'NmE3M2Q3NmYwOTU3YjJmZDBjYmQxYTVjODc5MTExNzM3NjY1YzYzNzp7Il9zZXNzaW9uX2V4cGlyeSI6MzB9', '2016-11-15 21:39:59.575998')
[2016-11-15 16:39:30] INFO [django.server:131] "GET /api/auths/usermenu/ HTTP/1.1" 200 11
[2016-11-15 16:39:37] INFO [django.server:131] "OPTIONS /api/catalogo/categorias/ HTTP/1.1" 200 0
[2016-11-15 16:39:38] DEBUG [django.db.backends:90] (0.007) SELECT "oauth2_provider_accesstoken"."id", "oauth2_provider_accesstoken"."user_id", "oauth2_provider_accesstoken"."token", "oauth2_provider_accesstoken"."application_id", "oauth2_provider_accesstoken"."expires", "oauth2_provider_accesstoken"."scope", "auths_user"."password", "auths_user"."last_login", "auths_user"."is_superuser", "auths_user"."username", "auths_user"."first_name", "auths_user"."last_name", "auths_user"."email", "auths_user"."is_staff", "auths_user"."is_active", "auths_user"."date_joined", "auths_user"."id", "auths_user"."last_hierarchy_id", "auths_user"."last_module_id", "auths_user"."person_id", "auths_user"."updated_at", "auths_user"."registered_by", "oauth2_provider_application"."id", "oauth2_provider_application"."client_id", "oauth2_provider_application"."user_id", "oauth2_provider_application"."redirect_uris", "oauth2_provider_application"."client_type", "oauth2_provider_application"."authorization_grant_type", "oauth2_provider_application"."client_secret", "oauth2_provider_application"."name", "oauth2_provider_application"."skip_authorization" FROM "oauth2_provider_accesstoken" LEFT OUTER JOIN "auths_user" ON ("oauth2_provider_accesstoken"."user_id" = "auths_user"."id") INNER JOIN "oauth2_provider_application" ON ("oauth2_provider_accesstoken"."application_id" = "oauth2_provider_application"."id") WHERE "oauth2_provider_accesstoken"."token" = 'pbonUfwDdVWqNXL836FceAznDaeFi5'; args=('pbonUfwDdVWqNXL836FceAznDaeFi5',)
[2016-11-15 16:39:38] DEBUG [django.db.backends:90] (0.001) SELECT "catalogo_categoria"."id", "catalogo_categoria"."nombre", "catalogo_categoria"."codigo", "catalogo_categoria"."estado" FROM "catalogo_categoria" WHERE ("catalogo_categoria"."codigo" LIKE '%%' ESCAPE '\' OR "catalogo_categoria"."nombre" LIKE '%%' ESCAPE '\'); args=('%%', '%%')
[2016-11-15 16:39:38] INFO [django.server:131] "GET /api/catalogo/categorias/ HTTP/1.1" 200 199
[2016-11-15 17:31:01] INFO [django.server:131] "OPTIONS /api/catalogo/autors/ HTTP/1.1" 200 0
[2016-11-15 17:31:01] DEBUG [django.db.backends:90] (0.005) SELECT "oauth2_provider_accesstoken"."id", "oauth2_provider_accesstoken"."user_id", "oauth2_provider_accesstoken"."token", "oauth2_provider_accesstoken"."application_id", "oauth2_provider_accesstoken"."expires", "oauth2_provider_accesstoken"."scope", "auths_user"."password", "auths_user"."last_login", "auths_user"."is_superuser", "auths_user"."username", "auths_user"."first_name", "auths_user"."last_name", "auths_user"."email", "auths_user"."is_staff", "auths_user"."is_active", "auths_user"."date_joined", "auths_user"."id", "auths_user"."last_hierarchy_id", "auths_user"."last_module_id", "auths_user"."person_id", "auths_user"."updated_at", "auths_user"."registered_by", "oauth2_provider_application"."id", "oauth2_provider_application"."client_id", "oauth2_provider_application"."user_id", "oauth2_provider_application"."redirect_uris", "oauth2_provider_application"."client_type", "oauth2_provider_application"."authorization_grant_type", "oauth2_provider_application"."client_secret", "oauth2_provider_application"."name", "oauth2_provider_application"."skip_authorization" FROM "oauth2_provider_accesstoken" LEFT OUTER JOIN "auths_user" ON ("oauth2_provider_accesstoken"."user_id" = "auths_user"."id") INNER JOIN "oauth2_provider_application" ON ("oauth2_provider_accesstoken"."application_id" = "oauth2_provider_application"."id") WHERE "oauth2_provider_accesstoken"."token" = 'pbonUfwDdVWqNXL836FceAznDaeFi5'; args=('pbonUfwDdVWqNXL836FceAznDaeFi5',)
[2016-11-15 17:31:01] DEBUG [django.db.backends:90] (0.001) SELECT COUNT(*) AS "__count" FROM "catalogo_autor"; args=()
[2016-11-15 17:31:01] INFO [django.server:131] "GET /api/catalogo/autors/ HTTP/1.1" 200 124
[2016-11-15 17:31:08] DEBUG [django.db.backends:90] (0.004) SELECT "oauth2_provider_accesstoken"."id", "oauth2_provider_accesstoken"."user_id", "oauth2_provider_accesstoken"."token", "oauth2_provider_accesstoken"."application_id", "oauth2_provider_accesstoken"."expires", "oauth2_provider_accesstoken"."scope", "auths_user"."password", "auths_user"."last_login", "auths_user"."is_superuser", "auths_user"."username", "auths_user"."first_name", "auths_user"."last_name", "auths_user"."email", "auths_user"."is_staff", "auths_user"."is_active", "auths_user"."date_joined", "auths_user"."id", "auths_user"."last_hierarchy_id", "auths_user"."last_module_id", "auths_user"."person_id", "auths_user"."updated_at", "auths_user"."registered_by", "oauth2_provider_application"."id", "oauth2_provider_application"."client_id", "oauth2_provider_application"."user_id", "oauth2_provider_application"."redirect_uris", "oauth2_provider_application"."client_type", "oauth2_provider_application"."authorization_grant_type", "oauth2_provider_application"."client_secret", "oauth2_provider_application"."name", "oauth2_provider_application"."skip_authorization" FROM "oauth2_provider_accesstoken" LEFT OUTER JOIN "auths_user" ON ("oauth2_provider_accesstoken"."user_id" = "auths_user"."id") INNER JOIN "oauth2_provider_application" ON ("oauth2_provider_accesstoken"."application_id" = "oauth2_provider_application"."id") WHERE "oauth2_provider_accesstoken"."token" = 'pbonUfwDdVWqNXL836FceAznDaeFi5'; args=('pbonUfwDdVWqNXL836FceAznDaeFi5',)
[2016-11-15 17:31:08] DEBUG [django.db.backends:90] (0.001) SELECT "catalogo_categoria"."id", "catalogo_categoria"."nombre", "catalogo_categoria"."codigo", "catalogo_categoria"."estado" FROM "catalogo_categoria" WHERE ("catalogo_categoria"."codigo" LIKE '%%' ESCAPE '\' OR "catalogo_categoria"."nombre" LIKE '%%' ESCAPE '\'); args=('%%', '%%')
[2016-11-15 17:31:08] INFO [django.server:131] "GET /api/catalogo/categorias/ HTTP/1.1" 200 199
[2016-11-15 17:31:14] DEBUG [django.db.backends:90] (0.003) SELECT "oauth2_provider_accesstoken"."id", "oauth2_provider_accesstoken"."user_id", "oauth2_provider_accesstoken"."token", "oauth2_provider_accesstoken"."application_id", "oauth2_provider_accesstoken"."expires", "oauth2_provider_accesstoken"."scope", "auths_user"."password", "auths_user"."last_login", "auths_user"."is_superuser", "auths_user"."username", "auths_user"."first_name", "auths_user"."last_name", "auths_user"."email", "auths_user"."is_staff", "auths_user"."is_active", "auths_user"."date_joined", "auths_user"."id", "auths_user"."last_hierarchy_id", "auths_user"."last_module_id", "auths_user"."person_id", "auths_user"."updated_at", "auths_user"."registered_by", "oauth2_provider_application"."id", "oauth2_provider_application"."client_id", "oauth2_provider_application"."user_id", "oauth2_provider_application"."redirect_uris", "oauth2_provider_application"."client_type", "oauth2_provider_application"."authorization_grant_type", "oauth2_provider_application"."client_secret", "oauth2_provider_application"."name", "oauth2_provider_application"."skip_authorization" FROM "oauth2_provider_accesstoken" LEFT OUTER JOIN "auths_user" ON ("oauth2_provider_accesstoken"."user_id" = "auths_user"."id") INNER JOIN "oauth2_provider_application" ON ("oauth2_provider_accesstoken"."application_id" = "oauth2_provider_application"."id") WHERE "oauth2_provider_accesstoken"."token" = 'pbonUfwDdVWqNXL836FceAznDaeFi5'; args=('pbonUfwDdVWqNXL836FceAznDaeFi5',)
[2016-11-15 17:31:14] DEBUG [django.db.backends:90] (0.000) SELECT COUNT(*) AS "__count" FROM "catalogo_autor"; args=()
[2016-11-15 17:31:14] INFO [django.server:131] "GET /api/catalogo/autors/ HTTP/1.1" 200 124
[2016-11-15 17:31:20] DEBUG [django.db.backends:90] (0.003) SELECT "oauth2_provider_accesstoken"."id", "oauth2_provider_accesstoken"."user_id", "oauth2_provider_accesstoken"."token", "oauth2_provider_accesstoken"."application_id", "oauth2_provider_accesstoken"."expires", "oauth2_provider_accesstoken"."scope", "auths_user"."password", "auths_user"."last_login", "auths_user"."is_superuser", "auths_user"."username", "auths_user"."first_name", "auths_user"."last_name", "auths_user"."email", "auths_user"."is_staff", "auths_user"."is_active", "auths_user"."date_joined", "auths_user"."id", "auths_user"."last_hierarchy_id", "auths_user"."last_module_id", "auths_user"."person_id", "auths_user"."updated_at", "auths_user"."registered_by", "oauth2_provider_application"."id", "oauth2_provider_application"."client_id", "oauth2_provider_application"."user_id", "oauth2_provider_application"."redirect_uris", "oauth2_provider_application"."client_type", "oauth2_provider_application"."authorization_grant_type", "oauth2_provider_application"."client_secret", "oauth2_provider_application"."name", "oauth2_provider_application"."skip_authorization" FROM "oauth2_provider_accesstoken" LEFT OUTER JOIN "auths_user" ON ("oauth2_provider_accesstoken"."user_id" = "auths_user"."id") INNER JOIN "oauth2_provider_application" ON ("oauth2_provider_accesstoken"."application_id" = "oauth2_provider_application"."id") WHERE "oauth2_provider_accesstoken"."token" = 'pbonUfwDdVWqNXL836FceAznDaeFi5'; args=('pbonUfwDdVWqNXL836FceAznDaeFi5',)
[2016-11-15 17:31:20] DEBUG [django.db.backends:90] (0.000) SELECT "catalogo_categoria"."id", "catalogo_categoria"."nombre", "catalogo_categoria"."codigo", "catalogo_categoria"."estado" FROM "catalogo_categoria" WHERE ("catalogo_categoria"."codigo" LIKE '%%' ESCAPE '\' OR "catalogo_categoria"."nombre" LIKE '%%' ESCAPE '\'); args=('%%', '%%')
[2016-11-15 17:31:20] INFO [django.server:131] "GET /api/catalogo/categorias/ HTTP/1.1" 200 199
